Workbook

Sheet KAPAK SAYFASI
E1: B.T.S. ELEKTRİK TRAFO BAKIM
E3: MÜH. İNŞ. MAK. LAB. SAN. VE TİC. LTD. ŞTİ.
A7: TRAFO BAKIM RAPORU
A9: Müşterinin Adı | D9: Test Musteri AS
A10: Trafo Etiketi | D10: TRAFO-1
A11: ADRESİ | D11: Bursa OSB Test Cad. No:1
A12: RAPOR TARİHİ | D12: 46237
A13: REFERANS | D13: International Electrical Testing Association
A14: RAPOR KONUSU | D14: 46237 | E14: Tarihinde yapılan Trafo Bakım raporu.
B16: TRAFO BAKIMI VE KONTROLLERİ
A18: - | B18: Trafonun D.C. İzolasyon test değerleri uygun bulunmuştur.
A20: - | B20: Trafoda yapılan çevirme oranı (TTR) test sonuçları uygun bulmuştur, buna bağlı olarak kademe değiştirici ile sargılar arasındaki bağlantılarda herhangi bir sorun olmadığı gözlemlenmiştir.
A23: - | B23: Trafoda yapılan D.C. Sargı direnci test sonuçlarının uygun olduğu tespit edilmiştir, sargılar arasındaki direnç farklılıkları max. değerin (%5) altındadır. Bu sonuçlara göre; sargı bağlantı uçları, kademe değiştirici kontakları, tij bağlantılarında gevşeklik olmadığı gözlemlenmiştir.
A27: - | B27: Görsel olarak yapılan kontrollerde herhangi bir soruna rastlanmamıştır.
A29: SONUÇ
A31: Kontroller yapildiktan sonra trafoya enerji verildi. Olcumler UYGUN.
A54: Test Tarihi | C54: : | D54: =D14 | G54: ONAYLAYAN
A55: Rapor Tarihi | C55: : | D55: =D12 | G55: Ahmet YILMAZ
A56: Unvan | C56: : | D56: Elektrik Mühendisi
A57: Sicil No | C57: : | D57: 12345
A58: Ekipnet No | C58: : | D58: K202439698
A60: Bu belge 5070 sayılı elektronik imza kanununa göre güvenli elektronik imza ile imzalanmıştır.
A62: Üçevler Mahallesi Ak-Va Sanayi Sitesi 80. Sokak No:2/P Nilüfer-BURSA
A63: Telefon : 444 0 287 - 0224 441 94 33 Mail: www.btselektrik.com.tr
A64: Gsm : 0532 206 58 32 - 0538 035 35 94

Sheet ANA SAYFA
H2: ŞALT SAHASI | K2: ='KAPAK SAYFASI'!D9
H5: TRAFO ETİKETİ | K5: ='KAPAK SAYFASI'!D10
B6: Üçevler Mh. AK-VA Sanayi Sitesi 80. Sk. No:2/P Nilüfer / BURSA / TÜRKİYE
B9: TRAFO BİLGİLERİ
B11: Trafo Markası | F11: : | G11: BEST | K11: Kademe Bilgisi | N11: : | O11: 6 | P11: / | Q11: 4 | R11: / | S11: 3
B13: Trafo Gücü (kVA) | F13: : | G13: 2000 | K13: İmal Yılı | N13: : | O13: 2015
B15: Gerilim Seviyesi (V) | F15: : | G15: 34500/400 | K15: Seri Numarası | N15: : | O15: SN-TEST-001
B17: Bağlantı Grubu | F17: : | G17: Dyn11 | K17: Kısa Devre Emp.% | N17: : | O17: 6.42
B19: Kazan Tipi | F19: : | G19: Hermetik | I19: ü | K19: Genleşme Tanklı | P19: Kuru Tip | R19: ü | U19: ü
B23: KONTROLLER
I24: Evet | J24: ü | R24: Evet | S24: Hayır
J25: ü
B26: Trafo Sıcaklık Kontrolü | F26: : | G26: 35 | H26: °C | I26: ü | J26: ü | K26: Trafo Temizliği | O26: : | P26: YAPILDI | R26: ü
B28: Fan ON | F28: : | G28: UYGUN | I28: ü | K28: Bina Temizliği | O28: : | P28: UYGUN | R28: ü
B30: DC Redresör Kontrolü | F30: : | G30: 24 | H30: Vdc | I30: ü | K30: Kablo Sıkılık Kontrolü | O30: : | P30: UYGUN | R30: ü
B32: Termometre Alarm | F32: : | G32: UYGUN | I32: ü | K32: Epoksi Kontrolü | O32: : | P32: UYGUN | R32: ü
B34: Termometre Trip | F34: : | G34: UYGUN | I34: ü | K34: Termistor Kontrolü | O34: : | P34: UYGUN | R34: ü
B36: Fan OFF | F36: : | G36: UYGUN | I36: ü | K36: Topraklama Bağlantısı | O36: : | P36: UYGUN | R36: ü
B38: TOPRAKLAMA ÖLÇÜMÜ ( Ω ) | V38: ÇEVİRME ORANI ( TTR ) | AF38: ÇEVİRME ORANI ( TTR )
B40: Trafo Topraklaması | G40: : | H40: 0.16 | J40: Ω | K40: A.G Pano Topraklaması | P40: : | Q40: 0 | S40: Ω | V40: AB / an | Y40: BC / bn | AB40: CA / cn | AF40: AB / an | AI40: BC / bn | AL40: CA / cn
B42: Nötr (işletme) Topraklaması | G42: : | H42: 0.15 | J42: Ω | K42: Kapı Topraklaması | P42: : | Q42: 0.16 | S42: Ω | V42: =V51/1.0525889 | Y42: =Y51/1.0525889 | AB42: =AB51/1.0525889 | AF42: =AF51/1.045489 | AI42: =AI51/1.045489 | AL42: =AL51/1.045489
B44: Hücre Topraklaması | G44: : | H44: 0.16 | J44: Ω | K44: Direk Topraklaması | P44: : | Q44: _ | S44: Ω | V44: Kademe Bilgisi | Y44: : | Z44: 28500 / 400 | AF44: Kademe Bilgisi | AI44: : | AJ44: 33000 / 400
B47: 2 | C47: A | D47: SARGI DİRENÇLERİ ( Ω ) | I47: 100 | J47: A | K47: ÇEVİRME ORANI ( TTR ) | V47: ÇEVİRME ORANI ( TTR ) | AF47: ÇEVİRME ORANI ( TTR )
B49: RAB : | C49: 50.1 | F49: Ran : | G49: 0.000256 | K49: AB / an | N49: BC / bn | Q49: CA / cn | V49: AB / an | Y49: BC / bn | AB49: CA / cn | AF49: AB / an | AI49: BC / bn | AL49: CA / cn
B51: RAC : | C51: 50 | F51: Rbn : | G51: 0.000257 | K51: 149.539 | N51: 149.785 | Q51: 149.585 | V51: =V60/1.050038 | Y51: =Y60/1.050038 | AB51: =AB60/1.050038 | AF51: =K51 | AI51: =N51 | AL51: =Q51
B53: RBC : | C53: 50.2 | F53: Rcn : | G53: 0.000251 | K53: Kademe Bilgisi | N53: : | O53: 34500 | Q53: / | R53: 230.9494 | V53: Kademe Bilgisi | Y53: : | Z53: 30000 / 400 | AF53: Kademe Bilgisi | AI53: : | AJ53: 34500 / 400
B56: İZOLASYON (YALITIM) DİRENÇLERİ ( Ω ) | V56: ÇEVİRME ORANI ( TTR ) | AF56: ÇEVİRME ORANI ( TTR )
F58: 30 sn | I58: 45 sn | L58: 60 sn | O58: Birim | Q58: DAR | V58: AB / an | Y58: BC / bn | AB58: CA / cn | AF58: AB / an | AI58: BC / bn | AL58: CA / cn
B60: Y.G - TANK | F60: 1111 | I60: 2311 | L60: 3456 | O60: G | P60: Ω | Q60: =L60/F60 | V60: =AF42/1.04758 | Y60: =AI42/1.04758 | AB60: =AL42/1.04758 | AF60: =AF51*1.043443 | AI60: =AI51*1.043443 | AL60: =AL51*1.043443
B62: A.G - TANK | F62: 1111 | I62: 3232 | L62: 3456 | O62: G | P62: Ω | Q62: =L62/F62 | V62: Kademe Bilgisi | Y62: : | Z62: 31500 / 400 | AF62: Kademe Bilgisi | AI62: : | AJ62: 36000 / 400
B64: Y.G - A.G | F64: 1111 | I64: 3232 | L64: 3345 | O64: G | P64: Ω | Q64: =L64/F64
B67: NOTLAR : Trafonun rutin bakımları ve izolasyon testleri yapıldı. Herhangi bir olumsuzluğa rastlanmadı.
B72: Rapor Tarihi | E72: : | F72: ='KAPAK SAYFASI'!D55 | K72: ONAYLAYAN
B73: Test Tarihi | E73: : | F73: ='KAPAK SAYFASI'!D54 | K73: Ahmet YILMAZ
B74: Unvan | E74: : | F74: Elektrik Mühendisi
B75: Sicil No | E75: : | F75: 12345
B76: Ekipnet No | E76: : | F76: K202439698

Sheet OG SARGI MEVCUT KADEME
G2: ŞALT SAHASI | I2: : | J2: ='ANA SAYFA'!K2
G3: LOKASYON | I3: : | J3: ='ANA SAYFA'!K5
B5: PRİMER SARGI DİRENCİ TEST SONUÇLARI
B7: Üretici : | D7: ='ANA SAYFA'!G11 | G7: Model : | I7: ='ANA SAYFA'!O13 | L7: Seri Numarası : | O7: ='ANA SAYFA'!O15
B9: OTURUM TARİHİ : | J9: ='ANA SAYFA'!F72
B11: Operatör : | D11: Ahmet YILMAZ | H11: Cihaz : | J11: STS 5000 | M11: Cihaz S/N : | O11: SN-19B20
B13: Sonuçlar | V13: ='ANA SAYFA'!G13
V14: =V13/59.75575286
B15: PT Sargı Otomatik | J15: HV Mevcut Kademe Tap | O15: ='ANA SAYFA'!S11
B17: Nominal Direnç | J17: Sıcaklık Kompan. | N17: Hayır
B18: Vektör Grubu | F18: ='ANA SAYFA'!G17 | J18: Malzeme | N18: Cu
B19: 3-faz
B20: Nominal Değerler | F20: =(K24+K25+K26)/3 | H20: Ω
B21: Çıkış Kademesi | F21: DC 6A | T21: A | U21: =MAX(T32:T33)
T22: B | U22: =MAX(U32:U33)
C23: I Testi [A] | E23: I DC [A] | G23: V DC [V] | I23: Zaman [S] | K23: R.ölç[Ω] | M23: R. Nom | O23: Hata[%] | T23: C | U23: =MAX(V32:V33)
B24: A | C24: ='ANA SAYFA'!B47 | E24: =C24 | G24: =(E24*K24)*0.98 | I24: 40 | K24: ='ANA SAYFA'!C49 | M24: =F20 | O24: =U21 | Q24: =IF(O24>0.05,1,0) | T24: SINIR DEĞER | U24: 0.05
B25: B | C25: ='ANA SAYFA'!B47 | E25: =C25 | G25: =(E25*K25)*0.98 | I25: 40 | K25: ='ANA SAYFA'!C53 | M25: =M24 | O25: =U22 | Q25: =IF(O25>0.05,1,0)
B26: C | C26: ='ANA SAYFA'!B47 | E26: =C26 | G26: =(E26*K26)*0.98 | I26: 40 | K26: ='ANA SAYFA'!C51 | M26: =M24 | O26: =U23 | Q26: =IF(O26>0.05,1,0)
T32: =SQRT((K24-K25)^2)/K25 | U32: =SQRT((K24-K25)^2)/K24 | V32: =SQRT((K26-K24)^2)/K24
T33: =SQRT((K26-K24)^2)/K26 | U33: =SQRT((K25-K26)^2)/K26 | V33: =SQRT((K26-K25)^2)/K25
B39: Sonuç : | D39: Yapılan ölçümlerde OG (Orta gerilim) sargısına ait direnç değerleri uygundur.
B45: UNVAN | E45: : | F45: Elektrik Mühendisi | J45: ONAYLAYAN
B46: TEST TARİHİ | E46: : | F46: ='ANA SAYFA'!F73:J73
B47: ODA SİCİL NO | E47: : | F47: ='ANA SAYFA'!F75
B48: EKİPNET NO | E48: : | F48: ='ANA SAYFA'!F76

Sheet AG SARGI
G2: ŞALT SAHASI | I2: : | J2: ='ANA SAYFA'!K2
G3: LOKASYON | I3: : | J3: ='ANA SAYFA'!K5
B5: SEKONDER SARGI DİRENCİ TEST SONUÇLARI
B7: Üretici : | D7: ='OG SARGI MEVCUT KADEME'!D7:F7 | G7: Model : | I7: ='OG SARGI MEVCUT KADEME'!I7:K7 | L7: Seri Numarası : | O7: ='OG SARGI MEVCUT KADEME'!O7:Q7
B9: OTURUM TARİHİ : | J9: ='ANA SAYFA'!F72
B11: Operatör : | D11: Ahmet YILMAZ | H11: Cihaz : | J11: STS 5000 | M11: Cihaz S/N : | O11: SN-19B20
B13: Sonuçlar | V13: ='ANA SAYFA'!G13
V14: =V13/0.69282
B15: PT Sargı Otomatik | J15: LV Kademe Tap | N15: 1
B17: Nominal Direnç | J17: Sıcaklık Kompan. | N17: Hayır
B18: Vektör Grubu | F18: ='ANA SAYFA'!G17 | J18: Malzeme | N18: Cu
B19: 3-faz
B20: Nominal Değerler | F20: =(K24+K25+K26)/3 | H20: Ω
B21: Çıkış Kademesi | F21: DC 400A | T21: A | U21: =MIN(T32:T33)
T22: B | U22: =MIN(U32:U33)
C23: I Testi [A] | E23: I DC [A] | G23: V DC [V] | I23: Zaman [S] | K23: R.ölç[Ω] | M23: R. Nom | O23: Hata[%] | T23: C | U23: =MIN(V32:V33)
B24: A | C24: ='ANA SAYFA'!I47 | E24: =C24 | G24: =(K24*E24)*0.98 | I24: 35 | K24: ='ANA SAYFA'!G49 | M24: =F20 | O24: =MIN(T32:T33) | Q24: =IF(O24>0.05,1,0) | T24: SINIR DEĞER | U24: 0.05
B25: B | C25: ='ANA SAYFA'!I47 | E25: =C25 | G25: =(K25*E25)*0.98 | I25: 35 | K25: ='ANA SAYFA'!G51 | M25: =M24 | O25: =MIN(U32:U33) | Q25: =IF(O25>0.05,1,0)
B26: C | C26: ='ANA SAYFA'!I47 | E26: =C26 | G26: =(K26*E26)*0.98 | I26: 35 | K26: ='ANA SAYFA'!G53 | M26: =M24 | O26: =MIN(V32:V33) | Q26: =IF(O26>0.05,1,0)
T32: =SQRT((K24-K25)^2)/K25 | U32: =SQRT((K24-K25)^2)/K24 | V32: =SQRT((K26-K24)^2)/K24
T33: =SQRT((K26-K24)^2)/K26 | U33: =SQRT((K25-K26)^2)/K26 | V33: =SQRT((K26-K25)^2)/K25
B39: Sonuç : | D39: Yapılan ölçümlerde AG (Alçak gerilim) sargısına ait direnç değerleri uygundur.
B45: UNVAN | E45: : | F45: Elektrik Mühendisi | J45: ONAYLAYAN
B46: TEST TARİHİ | E46: : | F46: ='ANA SAYFA'!F73
B47: ODA SİCİL NO | E47: : | F47: ='ANA SAYFA'!F75
B48: EKİPNET NO | E48: : | F48: ='ANA SAYFA'!F76

Sheet İZOLASYON 
G2: ŞALT SAHASI | I2: : | J2: ='ANA SAYFA'!K2
G3: LOKASYON | I3: : | J3: ='ANA SAYFA'!K5
B5: D.C. İZOLASYON DİRENCİ TEST SONUÇLARI
B7: Üretici : | D7: ='OG SARGI MEVCUT KADEME'!D7:F7 | G7: Model : | I7: ='OG SARGI MEVCUT KADEME'!I7:K7 | L7: Seri Numarası : | O7: ='OG SARGI MEVCUT KADEME'!O7:Q7
Y8: OG-TANK | Z8: AG-TANK | AA8: OG-AG
B9: OTURUM TARİHİ : | J9: ='ANA SAYFA'!F72 | X9: LİMİT | Y9: =V15 | Z9: =V20 | AA9: =V25
X10: 30 | Y10: =H18 | Z10: =H23 | AA10: =H28
B11: Operatör : | D11: Ahmet YILMAZ | H11: Cihaz : | J11: STS 5000 | M11: Cihaz S/N : | O11: SN-19B20 | X11: 45 | Y11: =J18 | Z11: =J23 | AA11: =J28
X12: 60 | Y12: =L18 | Z12: =L23 | AA12: =L28
B13: Sonuçlar | N13: Sıcaklık | P13: ='ANA SAYFA'!G26 | Q13: °C
B15: O.G. TANK İZOLASYON | U15: OG-TANK | V15: 1.1
B16: 2500 | H16: HESAPLANAN DEĞERLER 20°C | V16: UYGUN
B17: 30 sn | D17: 2400 | F17: 60 sn | H17: 30 sn | J17: 45 sn | L17: 60 sn | N17: DAR | P17: Sonuç
B18: ='ANA SAYFA'!F60 | C18: GΩ | D18: ='ANA SAYFA'!I60 | E18: GΩ | F18: ='ANA SAYFA'!L60 | G18: GΩ | H18: =B18*V38 | I18: GΩ | J18: =D18*V38 | K18: GΩ | L18: =F18*V38 | M18: GΩ | N18: =L18/H18 | P18: =IF(L18<V15,V18,V16) | V18: DÜŞÜK
B20: A.G. TANK İZOLASYON | U20: AG-TANK | V20: 0.2
B21: ÖLÇÜLEN DEĞERLER | H21: HESAPLANAN DEĞERLER 20°C | V21: UYGUN
B22: 30 sn | D22: 45 sn | F22: 60 sn | H22: 30 sn | J22: 45 sn | L22: 60 sn | N22: DAR | P22: Sonuç
B23: ='ANA SAYFA'!F62 | C23: GΩ | D23: ='ANA SAYFA'!I62 | E23: GΩ | F23: ='ANA SAYFA'!L62 | G23: GΩ | H23: =B23*V38 | I23: GΩ | J23: =D23*V38 | K23: GΩ | L23: =F23*V38 | M23: GΩ | N23: =L23/H23 | P23: =IF(L23<V20,V23,V21) | V23: DÜŞÜK
Y24: Yapılan ölçümlerde trafonun izolasyon direnç değerleri uygun bulunmuştur.
B25: O.G. A.G. İZOLASYON | U25: OG-AG | V25: 1.1
B26: ÖLÇÜLEN DEĞERLER | H26: HESAPLANAN DEĞERLER 20°C | V26: UYGUN
B27: 30 sn | D27: 45 sn | F27: 60 sn | H27: 30 sn | J27: 45 sn | L27: 60 sn | N27: DAR | P27: Sonuç
B28: ='ANA SAYFA'!F64 | C28: GΩ | D28: ='ANA SAYFA'!I64 | E28: GΩ | F28: ='ANA SAYFA'!L64 | G28: GΩ | H28: =B28*V38 | I28: GΩ | J28: =D28*V38 | K28: GΩ | L28: =F28*V38 | M28: GΩ | N28: =L28/H28 | P28: =IF(L28<V25,V28,V26) | V28: DÜŞÜK
D30: 24
D31: 45
Y32: Yapılan ölçümlerde trafonun izolasyon direnç değerleri düşük bulunmuştur.
U38: ÇARPAN | V38: =IF(P13>40,X43,X42)
B41: Sonuç : | D41: =IF(L18<V15,Y32,Y24)
U42: Test Sıcaklığı | V42: İcra Katsayısı | X42: =IF(P13=0,V43, IF(P13=5,V44, IF(P13=10,V45, IF(P13=15,V46, IF(P13=20,V47, IF(P13=25,V48, IF(P13=30,V49, IF(P13=35,V50, IF(P13=40,V51, )))))))))
U43: 0 | V43: 0.25 | X43: =IF(P13=45,V52, IF(P13=50,V53, IF(P13=55,V54, IF(P13=60,V55, IF(P13=65,V56, IF(P13=70,V57, IF(P13=75,V58, )))))))
U44: 5 | V44: 0.36
U45: 10 | V45: 0.5
B46: Not: Polarizasyon endekslerine göre değerlendirme; hem fabrika deney sonuçları hem de daha önceki değerlerle yeni bulunan değerlerin kıyaslanması ile yapılmalıdır. Ölçülen değerler daha önceki değerlere yakın veya büyük ise normal kabul edilir. Ancak ölçüm ilk kez yapılıyorsa; PE=1,0-1,1 Zayıf / PE=1,1-1,25 Şüpheli / PE=1,25-1,40 Orta / PE=1,40-1,60 İyi / PE>1,60 Çok İyi değerlendirmesi yapılır. İzolasyon ölçümlerinde DAR endeksine bağlı kalınmaksızın, sınır değerlerin altında çıkan değerler kötü izolasyon olarak ifade edilmektedir. | U46: 15 | V46: 0.74
U47: 20 | V47: 1
U48: 25 | V48: 1.4
U49: 30 | V49: 1.98
B50: UNVAN | E50: : | F50: Elektrik Mühendisi | J50: ONAYLAYAN | U50: 35 | V50: 2.8
B51: TEST TARİHİ | E51: : | F51: ='ANA SAYFA'!F73 | U51: 40 | V51: 3.95
B52: ODA SİCİL NO | E52: : | F52: ='ANA SAYFA'!F75:J75 | U52: 45 | V52: 5.6
B53: EKİPNET NO | E53: : | F53: ='ANA SAYFA'!F76:J76 | U53: 50 | V53: 7.85
...

Sheet Ç.O 34500
G2: ŞALT SAHASI | I2: : | J2: ='ANA SAYFA'!K2
G3: LOKASYON | I3: : | J3: ='ANA SAYFA'!K5
B5: ÇEVİRME ORANI TEST SONUÇLARI
B7: Üretici : | D7: ='OG SARGI MEVCUT KADEME'!D7:F7 | G7: Model : | I7: ='OG SARGI MEVCUT KADEME'!I7:K7 | L7: Seri Numarası : | O7: ='OG SARGI MEVCUT KADEME'!O7:Q7
B9: OTURUM TARİHİ : | J9: ='ANA SAYFA'!F72
B11: Operatör : | D11: Ahmet YILMAZ | H11: Cihaz : | J11: STS 5000 | M11: Cihaz S/N : | O11: SN-19B20
B13: Sonuçlar
B15: PT Her Bir Kademe Oran | J15: Tap | K15: ='ANA SAYFA'!S11 | N15: Kademe #1 | T15: ='ANA SAYFA'!R53 | U15: A | V15: =O26
U16: B | V16: =O27
B17: Nominal Değerler | J17: Test Değerleri | U17: C | V17: =O28
B18: HV Kademeler | F18: ='ANA SAYFA'!O53 | H18: V | J18: Gerilim | N18: 500,0 V | U18: SINIR DEĞER | V18: 0.5
B19: LV Ratings | F19: 231 | H19: V | J19: Frekans | N19: 50, Hz | W19: 0.5 | X19: -0.5
B20: Çevirme Oranı | F20: =F18/T15
B22: Sonuçlar
C25: Vn HV [V] | E25: V HV[V] | G25: I HV[A] | I25: V LV[V] | K25: ᶲV LV [°] | M25: Ratio | O25: Err % | V25: ( A ) Fazına ait çevirme oranı hata yüzdesi uygundur.
B26: A | C26: 500 | E26: 500 | G26: =I26/M26 | I26: 1.5 | K26: 26,0m | M26: ='ANA SAYFA'!AF51 | O26: =(M26-F20)/F20*100
B27: B | C27: 500 | E27: 500 | G27: =I27/M27 | I27: 1.5 | K27: 26,0m | M27: ='ANA SAYFA'!AI51 | O27: =(M27-F20)/F20*100 | V27: ( A ) Fazına ait çevirme oranı hata yüzdesi hatalı olduğu tespit edilmiştir.
B28: C | C28: 500 | E28: 500 | G28: =I28/M28 | I28: 1.5 | K28: 26,0m | M28: ='ANA SAYFA'!AL51 | O28: =(M28-F20)/F20*100
V29: ( B ) Fazına ait çevirme oranı hata yüzdesi uygundur.
V31: ( B ) Fazına ait çevirme oranı hata yüzdesi hatalı olduğu tespit edilmiştir.
V34: ( C ) Fazına ait çevirme oranı hata yüzdesi uygundur.
V36: ( C ) Fazına ait çevirme oranı hata yüzdesi hatalı olduğu tespit edilmiştir.
B44: Sonuç : | D44: =IF(OR(O26>W19,O26<X19),V27,V25)
D46: =IF(OR(O27>W19,O27<X19),V31,V29)
D48: =IF(OR(O28>W19,O28<X19),V36,V34)
B50: UNVAN | E50: : | F50: Elektrik Mühendisi | J50: ONAYLAYAN
B51: TEST TARİHİ | E51: : | F51: ='ANA SAYFA'!F73
B52: ODA SİCİL NO | E52: : | F52: ='ANA SAYFA'!F75:J75
B53: EKİPNET NO | E53: : | F53: ='ANA SAYFA'!F76:J76

Sheet TOPRAKLAMALAR
G2: ŞALT SAHASI | I2: : | J2: ='ANA SAYFA'!K2
G3: LOKASYON | I3: : | J3: ='ANA SAYFA'!K5
B5: Dosya Adı : | E5: TOPRAKLAMA ÖLÇÜM SONUÇLARI
B7: OTURUM TARİHİ : | J7: ='ANA SAYFA'!F72
B9: Operatör : | D9: Ahmet YILMAZ | H9: Cihaz : | J9: STS 5000 | M9: Cihaz S/N : | O9: SN-19B20
B11: Sonuçlar
B13: İŞLETME (NÖTR) TOPRAK DİRENCİ
N15: Sonuç
B16: Max. Ω | D16: 2 | F16: Ω | H16: Ölçülen | J16: Ω | K16: ='ANA SAYFA'!H42 | M16: Ω | N16: =IF(K16<D16,W18,Y18)
W18: UYGUN | Y18: UYGUN DEĞİL
B23: KORUMA TOPRAK DİRENCİ
N25: Sonuç | V25: İşletme (NÖTR) topraklaması direnç değeri normaldir.
B26: Trafo | D26: Max. Ω | F26: 2 | G26: Ω | H26: Ölçülen | J26: Ω | K26: ='ANA SAYFA'!H40 | M26: Ω | N26: =IF(K26<F26,W18,Y18) | V26: İşletme (NÖTR) topraklaması direnç değeri yüksek bulunmuştur.
B27: Hücre | D27: Max. Ω | F27: 2 | G27: Ω | H27: Ölçülen | J27: Ω | K27: ='ANA SAYFA'!H44 | M27: Ω | N27: =IF(K27<F27,W18,Y18) | V27: Trafo topraklaması direnç değeri normaldir.
B28: Kapılar | D28: Max. Ω | F28: 2 | G28: Ω | H28: Ölçülen | J28: Ω | K28: ='ANA SAYFA'!Q42 | M28: Ω | N28: =IF(K28<F28,W18,Y18) | V28: Trafo topraklaması direnç değeri yüksek bulunmuştur.
B29: AG. Pano | D29: Max. Ω | F29: 2 | G29: Ω | H29: Ölçülen | J29: Ω | K29: ='ANA SAYFA'!Q40 | M29: Ω | N29: =IF(K29<F29,W18,Y18)
V30: Hücre topraklaması direnç değeri normaldir.
V31: Hücre topraklaması direnç değeri yüksek bulunmuştur.
V33: A.G. Pano topraklaması direnç değeri normaldir.
V34: A.G. Pano topraklaması direnç değeri yüksek bulunmuştur.
V36: Kapı topraklaması direnç değeri normaldir.
V37: Kapı topraklaması direnç değeri yüksek bulunmuştur.
V38: Direk topraklaması direnç değeri normaldir.
V39: Direk topraklaması direnç değeri yüksek bulunmuştur.
B41: Sonuç : | D41: =IF(K16<D16,V25,V26)
D42: =IF(K26<F26,V27,V28)
D43: =IF(K27<F27,V30,V31)
D44: =IF(K28<F28,V36,V37)
D45: =IF(K29<F29,V33,V34)
B47: UNVAN | E47: : | F47: Elektrik Mühendisi | J47: ONAYLAYAN
B48: TEST TARİHİ | E48: : | F48: ='ANA SAYFA'!F73
B49: ODA SİCİL NO | E49: : | F49: ='ANA SAYFA'!F75:J75
B50: EKİPNET NO | E50: : | F50: ='ANA SAYFA'!F76:J76

Sheet HV PF
G2: ŞALT SAHASI | I2: : | J2: ='ANA SAYFA'!K2
G3: LOKASYON | I3: : | J3: ='ANA SAYFA'!K5
B5: YÜKSEK GERİLİM GÜÇ FAKTÖRÜ TEST SONUÇLARI
V6: Test Sıcaklığı | X6: İcra Katsayısı
B7: Üretici : | D7: ='OG SARGI MEVCUT KADEME'!D7:F7 | G7: Model : | I7: ='OG SARGI MEVCUT KADEME'!I7:K7 | L7: Seri Numarası : | O7: ='OG SARGI MEVCUT KADEME'!O7:Q7
V8: 10 | X8: 0.8 | AA8: =IF(P15=10,X8, IF(P15=15,X9, IF(P15=20,X10, IF(P15=25,X11, IF(P15=30,X12, IF(P15=35,X13, IF(P15=40,X14, IF(P15=45,X15, IF(P15=50,X16)))))))))
B9: OTURUM TARİHİ : | J9: ='ANA SAYFA'!F72 | V9: 15 | X9: 0.9
V10: 20 | X10: 1
B11: Operatör : | D11: Ahmet YILMAZ | H11: Cihaz : | J11: STS 5000 | M11: Cihaz S/N : | O11: SN-19B20 | V11: 25 | X11: 1.2
V12: 30 | X12: 1.25
B13: Sonuçlar | V13: 35 | X13: 1.4
V14: 40 | X14: 1.55
B15: HV Sargı | K15: Sıcaklık: | O15: ~ | P15: ='ANA SAYFA'!G26 | Q15: °C | V15: 45 | X15: 1.75
B16: Testler | C16: # | E16: Kapasitans | H16: Tarama | K16: Mod | N16: V [V] | P16: f [Hz] | V16: 50 | X16: 1.95
C17: 1 | D17: 1 | E17: CH | H17: Hiçbiri | K17: GSTg-A | N17: 10000 | P17: 50 | V17: 55 | X17: 2.18
C18: 2 | D18: 1 | E18: CHL | H18: Hiçbiri | K18: UST-A | N18: 10000 | P18: 50 | V18: 60 | X18: 2.42
C19: 3 | D19: 1 | E19: CH+CHL | H19: Hiçbiri | K19: GST | N19: 10000 | P19: 50 | V19: 65 | X19: 2.7
V20: 70 | X20: 3
B21: Sonuçlar | C21: CH
C22: # | D22: V [V] | F22: f [Hz] | H22: PF (%) | J22: Kayıp W | L22: Z (kΩ) | N22: Stest (VA) | P22: PF20°C
C23: 1 | D23: 10000 | F23: 50 | H23: 0.202 | J23: 0.10592 | L23: 1919.95 | N23: 52.423 | P23: =H23/AA8
C25: CHL
C26: # | D26: V [V] | F26: f [Hz] | H26: PF (%) | J26: Kayıp W | L26: Z (kΩ) | N26: Stest (VA) | P26: PF20°C
C27: 2 | D27: 10000 | F27: 50 | H27: 0.32 | J27: 0.36838 | L27: 888.675 | N27: 113.255 | P27: =H27/AA8
C29: CH+CHL
C30: # | D30: V [V] | F30: f [Hz] | H30: PF (%) | J30: Kayıp W | L30: Z (kΩ) | N30: Stest (VA) | P30: PF20°C
C31: 3 | D31: 10000 | F31: 50 | H31: 0.345 | J31: 0.47396 | L31: 607.447 | N31: =N23+N27 | P31: =H31/AA8
B33: Not: Hava koşullarının test değerlerine olan etkisini ortadan kaldırıp, sonraki ölçümlerde kıyaslama imkanı sağlamak amacıyla, mevcut sıcaklık değeri kaydedilerek ölçülen %PF değerlerine, referans bir sıcaklığa (20°C) göre sıcaklık icralaması yapılmaktadır. İşletmedeki transformatörlerde PF(20°C) ≤ 1 olmalıdır.
B36: TEST DEĞERLERİNİN YORUMU
B37: CH (YG/Tank-Nüve) değerleri uygundur.
B39: CHL (YG/AG) değerleri uygundur.
B41: CH+CHL (∑YG/Tank-Nüve) değerleri uygundur.
B44: UNVAN | E44: : | F44: Elektrik Mühendisi | J44: ONAYLAYAN
B45: TEST TARİHİ | E45: : | F45: ='ANA SAYFA'!F73
B46: ODA SİCİL NO | E46: : | F46: ='ANA SAYFA'!F75
B47: EKİPNET NO | E47: : | F47: ='ANA SAYFA'!F76

Sheet LV PF
G2: ŞALT SAHASI | I2: : | J2: ='ANA SAYFA'!K2
G3: LOKASYON | I3: : | J3: ='ANA SAYFA'!K5
B5: ALÇAK GERİLİM GÜÇ FAKTÖRÜ TEST SONUÇLARI
V6: Test Sıcaklığı | X6: İcra Katsayısı
B7: Üretici : | D7: ='OG SARGI MEVCUT KADEME'!D7:F7 | G7: Model : | I7: ='OG SARGI MEVCUT KADEME'!I7:K7 | L7: Seri Numarası : | O7: ='OG SARGI MEVCUT KADEME'!O7:Q7
V8: 10 | X8: 0.8 | AA8: =IF(P15=10,X8, IF(P15=15,X9, IF(P15=20,X10, IF(P15=25,X11, IF(P15=30,X12, IF(P15=35,X13, IF(P15=40,X14, IF(P15=45,X15, IF(P15=50,X16,IF(P15=55,X17,IF(P15=60,X18)))))))))))
B9: OTURUM TARİHİ : | J9: ='ANA SAYFA'!F72 | V9: 15 | X9: 0.9
V10: 20 | X10: 1
B11: Operatör : | D11: Ahmet YILMAZ | H11: Cihaz : | J11: STS 5000 | M11: Cihaz S/N : | O11: SN-19B20 | V11: 25 | X11: 1.2
V12: 30 | X12: 1.25
B13: Sonuçlar | V13: 35 | X13: 1.4
V14: 40 | X14: 1.55
B15: LV Sargı | K15: Sıcaklık: | O15: ~ | P15: ='HV PF'!P15 | Q15: °C | V15: 45 | X15: 1.75
B16: Testler | C16: # | E16: Kapasitans | H16: Tarama | K16: Mod | N16: V [V] | P16: f [Hz] | V16: 50 | X16: 1.95
C17: 1 | D17: 1 | E17: CL | H17: Hiçbiri | K17: GSTg-A | N17: 10000 | P17: 50 | V17: 55 | X17: 2.18
C18: 2 | D18: 1 | E18: CHL | H18: Hiçbiri | K18: UST-A | N18: 10000 | P18: 50 | V18: 60 | X18: 2.42
C19: 3 | D19: 1 | E19: CL+CHL | H19: Hiçbiri | K19: GST | N19: 10000 | P19: 50 | V19: 65 | X19: 2.7
V20: 70 | X20: 3
B21: Sonuçlar | C21: CL
C22: # | D22: V [V] | F22: f [Hz] | H22: PF (%) | J22: Kayıp W | L22: Z (kΩ) | N22: Stest (VA) | P22: PF20°C
C23: 1 | D23: 1000 | F23: 50 | H23: 0.513 | J23: 0.10228 | L23: 202.124 | N23: 19.915 | P23: =H23/AA8
C25: CHL
C26: # | D26: V [V] | F26: f [Hz] | H26: PF (%) | J26: Kayıp W | L26: Z (kΩ) | N26: Stest (VA) | P26: PF20°C
C27: 2 | D27: 1000 | F27: 50 | H27: 0.323 | J27: 0.0146573 | N27: 4.528 | P27: =H27/AA8
C29: CL+CHL
C30: # | D30: V [V] | F30: f [Hz] | H30: PF (%) | J30: Kayıp W | L30: Z (kΩ) | N30: Stest (VA) | P30: PF20°C
C31: 3 | D31: 1000 | F31: 50 | H31: 0.477 | J31: 0.11662 | L31: 164.684 | N31: =N23+N27 | P31: =H31/AA8
B33: Not: Hava koşullarının test değerlerine olan etkisini ortadan kaldırıp, sonraki ölçümlerde kıyaslama imkanı sağlamak amacıyla, mevcut sıcaklık değeri kaydedilerek ölçülen %PF değerlerine, referans bir sıcaklığa (20°C) göre sıcaklık icralaması yapılmaktadır. İşletmedeki transformatörlerde PF(20°C) ≤ 1 olmalıdır.
B36: TEST DEĞERLERİNİN YORUMU
B37: CL (AG/Tank-Nüve) değerleri uygundur. Testlerin periyodik programa uygun olarak yaptırılıp takip edilmesi önerilir.
B39: CHL (AG/YG) değerleri uygundur.
B41: CL+CHL (∑AG/Tank-Nüve) değerleri uygundur.
B44: UNVAN | E44: : | F44: Elektrik Mühendisi | J44: ONAYLAYAN
B45: TEST TARİHİ | E45: : | F45: ='ANA SAYFA'!F73
B46: ODA SİCİL NO | E46: : | F46: ='ANA SAYFA'!F75
B47: EKİPNET NO | E47: : | F47: ='ANA SAYFA'!F76

Sheet ANA SAYFA KESİCİ
H2: ŞALT SAHASI | K2: ='ANA SAYFA'!K2
H5: LOKASYON | K5: ='ANA SAYFA'!K5
B9: KESİCİ BİLGİLERİ
B11: Kesici Markası | F11: : | G11: ABB | K11: Kesici Tipi | N11: : | O11: USFB-36R
B13: Anma Akımı (A) | F13: : | G13: 630 | K13: İmal Yılı | N13: : | O13: 2016
B15: Gerilim Seviyesi (V) | F15: : | G15: 36000 | K15: Seri Numarası | N15: : | O15: 2196
B17: Motor Gerilimi | F17: : | G17: 220 Vac | K17: Bobin Gerilimi | N17: : | O17: 24 Vdc
B21: KONTROLLER
I22: Evet | J22: Hayır | R22: Evet | S22: Hayır
B24: Kesici Görsel Kontrolü | F24: : | G24: UYGUN | I24: ü | K24: Kesici Temizliği | O24: : | P24: YAPILDI | R24: ü
B26: DC Redresör Kontrolü | F26: : | G26: 24 | H26: Vdc | I26: ü | K26: Hücre Temizliği | O26: : | P26: YAPILDI | R26: ü
B28: İndikatör Kontrolü | F28: : | G28: UYGUN | I28: ü | K28: Bara Kontrolü | O28: : | P28: UYGUN | R28: ü
B30: Mekanik Konrolü | F30: : | G30: UYGUN | I30: ü | K30: Isıtıcı Kontrolü | O30: : | P30: UYGUN | R30: ü
B32: Kablo Başlığı Kontrolü | F32: : | G32: UYGUN | I32: ü | K32: A.A Röle Kontrolü | O32: : | P32: UYGUN | R32: ü
B35: BASAMAK VOLTAJ TESTİ
C37: R1 (1.04kV) | F37: R2 (2.04kV) | I37: R3 (3.06kV) | L37: R4 (4.06kV) | O37: R5 (5.09kV) | R37: SONUÇ
B39: L-1 | C39: 2000 | E39: GΩ | F39: 4000 | H39: GΩ | I39: 6000 | K39: GΩ | L39: 8000 | N39: GΩ | O39: 10000 | Q39: GΩ | R39: =IF(O39>250,1,0)
B41: L-2 | C41: 2000 | E41: GΩ | F41: 4000 | H41: GΩ | I41: 6000 | K41: GΩ | L41: 8000 | N41: GΩ | O41: 10000 | Q41: GΩ | R41: =IF(O41>250,1,0)
B43: L-3 | C43: 2000 | E43: GΩ | F43: 4000 | H43: GΩ | I43: 6000 | K43: GΩ | L43: 8000 | N43: GΩ | O43: 10000 | Q43: GΩ | R43: =IF(O43>250,1,0)
B46: KESİCİ İZOLASYON DİRENCİ (GΩ) | K46: KESİCİ KONTAK DİRENCİ (Ω)
C48: TEST VOLTAJI | G48: SONUÇ | K48: TEST AKIMI | O48: SONUÇ
B50: L-1 | C50: 10.00 | F50: kV | G50: 20000 | I50: GΩ | J50: =IF(G50>50,1,0) | K50: 80.00A | O50: 38 | R50: µΩ | S50: =IF(O50<150,1,0)
B52: L-2 | C52: 10.00 | F52: kV | G52: 20000 | I52: GΩ | J52: =IF(G52>50,1,0) | K52: 80.00A | O52: 40 | R52: µΩ | S52: =IF(O52<150,1,0)
B54: L-3 | C54: 10.00 | F54: kV | G54: 20000 | I54: GΩ | J54: =IF(G54>50,1,0) | K54: 80.00A | O54: 54 | R54: µΩ | S54: =IF(O54<150,1,0)
B57: KESİCİ ACMA / KAPAMA ZAMANI
C59: KESİCİ AÇMA | F59: EŞ ZAMAN FARKI | J59: KESİCİ KAPAMA | M59: EŞ ZAMAN FARKI | Q59: SONUÇ
B61: L-1 | C61: 52.63 | E61: ms | F61: =MAX(V80:V85) | H61: ms | J61: 69.03 | L61: ms | M61: =MAX(X80:X85) | O61: ms | Q61: UYGUN
B63: L-2 | C63: 54.14 | E63: ms | F63: BOBİN AKIMI | J63: 66.57 | L63: ms | M63: BOBİN AKIMI | Q63: UYGUN
B65: L-3 | C65: 50.45 | E65: ms | F65: 1.3 | H65: A | J65: 68.79 | L65: ms | M65: 1.3 | O65: A | Q65: UYGUN
B68: Sonuç : | D68: Yapılan ölçümlerde kesicinin test değerleri uygun bulundu. Kesicinin ve hücrenin
B69: temizliği yapıldı.
B74: Rapor Tarihi | E74: : | F74: ='ANA SAYFA'!F72 | K74: ONAYLAYAN
B75: Test Tarihi | E75: : | F75: ='ANA SAYFA'!F73
B76: Unvan | E76: : | F76: Elektrik Mühendisi
B77: Sicil No | E77: : | F77: 88258
B78: Ekipnet No | E78: : | F78: K202439698
V80: =C61-C63 | X80: =J61-J63
V81: =C61-C65 | X81: =J61-J65
V82: =C63-C65 | X82: =J63-J65
V83: =C63-C61 | X83: =J63-J61
...

Sheet KESİCİ İZOLASYON
G2: ŞALT SAHASI | J2: : | K2: ='ANA SAYFA KESİCİ'!K2
G3: LOKASYON | J3: : | K3: ='ANA SAYFA KESİCİ'!K5
B5: KESİCİ İZOLASYON DİRENCİ TEST SONUÇLARI
B8: OTURUM TARİHİ : | J8: ='ANA SAYFA KESİCİ'!F74
B10: Operatör : | D10: Ahmet YILMAZ | H10: Cihaz : | J10: STS 5000 | M10: Cihaz S/N : | O10: SN-19B20 | U10: r1 | V10: 250 | W10: 200 | X10: 150 | Y10: 100 | Z10: 50
B12: Sonuçlar
B14: KESİCİ İZOLASYON
B16: R min. | D16: 50 | F16: GΩ | H16: Test Gerilimi | K16: Test Akımı | N16: Sonuç
B17: L-1 | D17: ='ANA SAYFA KESİCİ'!G50 | F17: GΩ | H17: 10000 | J17: VDC | K17: =H17/D17 | M17: nA | N17: =IF(D17>D16,1,0) | O17: =IF(D17>D16,"UYGUN","UYGUN DEĞİL")
B18: L-2 | D18: ='ANA SAYFA KESİCİ'!G52 | F18: GΩ | H18: 10000 | J18: VDC | K18: =H18/D18 | M18: nA | N18: =IF(D18>D16,1,0) | O18: =IF(D18>D16,"UYGUN","UYGUN DEĞİL")
B19: L-3 | D19: ='ANA SAYFA KESİCİ'!G54 | F19: GΩ | H19: 10000 | J19: VDC | K19: =H19/D19 | M19: nA | N19: =IF(D19>D16,1,0) | O19: =IF(D19>D16,"UYGUN","UYGUN DEĞİL")
X20: =N17+N18+N19
X24: =(N32+N33+N34+N35+N36)/5
X27: Yapılan ölçümlerde kesicinin İzolasyon değerleri uygundur.
X28: Yapılan ölçümlerde kesicinin İzolasyon değerleri uygun değildir.
B29: BASAMAK VOLTAJ TESTİ
D31: L-1 | F31: L-2 | H31: L-3 | K31: Basamak Gerilimi | N31: Sonuç
B32: R1 | D32: ='ANA SAYFA KESİCİ'!C39 | F32: ='ANA SAYFA KESİCİ'!C41 | H32: ='ANA SAYFA KESİCİ'!C43 | J32: GΩ | K32: 1.04 | M32: kV | N32: =IF(D32>50,1,0) | O32: =IF(D32>50,"UYGUN","UYGUN DEĞİL")
B33: R2 | D33: ='ANA SAYFA KESİCİ'!F39 | F33: ='ANA SAYFA KESİCİ'!F41 | H33: ='ANA SAYFA KESİCİ'!F43 | J33: GΩ | K33: 2.04 | M33: kV | N33: =IF(D33>50,1,0) | O33: =IF(D33>50,"UYGUN","UYGUN DEĞİL")
B34: R3 | D34: ='ANA SAYFA KESİCİ'!I39 | F34: ='ANA SAYFA KESİCİ'!I41 | H34: ='ANA SAYFA KESİCİ'!I43 | J34: GΩ | K34: 3.05 | M34: kV | N34: =IF(D34>50,1,0) | O34: =IF(D34>50,"UYGUN","UYGUN DEĞİL")
B35: R4 | D35: ='ANA SAYFA KESİCİ'!L39 | F35: ='ANA SAYFA KESİCİ'!L41 | H35: ='ANA SAYFA KESİCİ'!L43 | J35: GΩ | K35: 4.05 | M35: kV | N35: =IF(D35>50,1,0) | O35: =IF(D35>50,"UYGUN","UYGUN DEĞİL")
B36: R5 | D36: ='ANA SAYFA KESİCİ'!O39 | F36: ='ANA SAYFA KESİCİ'!O41 | H36: ='ANA SAYFA KESİCİ'!O43 | J36: GΩ | K36: 5.09 | M36: kV | N36: =IF(D36>50,1,0) | O36: =IF(D36>50,"UYGUN","UYGUN DEĞİL")
B47: Sonuç : | D47: =IF(OR(X24<1,X20<3),X28,X27)
B50: UNVAN | E50: : | F50: Elektrik Mühendisi | J50: ONAYLAYAN
B51: TEST TARİHİ | E51: : | F51: ='ANA SAYFA KESİCİ'!F75:J75
B52: ODA SİCİL NO | E52: : | F52: ='ANA SAYFA KESİCİ'!F77:J77
B53: EKİPNET NO | E53: : | F53: ='ANA SAYFA KESİCİ'!F78:J78

Sheet KESİCİ KONTAK
G2: ŞALT SAHASI | J2: : | K2: ='ANA SAYFA KESİCİ'!K2
G3: LOKASYON | J3: : | K3: ='ANA SAYFA KESİCİ'!K5
B5: KESİCİ KONTAK DİRENCİ TEST SONUÇLARI
B8: OTURUM TARİHİ : | J8: ='ANA SAYFA KESİCİ'!F74
B10: Operatör : | D10: Ahmet YILMAZ | H10: Cihaz : | J10: STS 5000 | M10: Cihaz S/N : | O10: SN-19B20
B12: Sonuçlar
B14: Kontak Direnci µΩ | J14: L-1 | P14: =IF(N20<150,1,0)
B16: Nominal Değerler | J16: Ölçülen
B17: Maksimum Direnç | F17: 150 | H17: µΩ | J17: Akım DC | N17: 82 | P17: A
J18: Gerilim DC | N18: =N20*N17/1000 | P18: mV
B19: Çıkış Kademesi | F19: DC 400A | J19: Sonuçlar
B20: Akım | F20: 80,00A | J20: Ölçülen Direnç | N20: ='ANA SAYFA KESİCİ'!O50 | P20: µΩ
J21: Hata | P21: %
B23: Kontak Direnci µΩ | J23: L-2 | P23: =IF(N29<150,1,0)
V24: Kesicinin L1 kontağına ait geçiş direci uygundur.
B25: Nominal Değerler | J25: Ölçülen | V25: Kesicinin L1 kontağına ait geçiş direci uygun değildir.
B26: Nominal Direnç | F26: 150 | H26: µΩ | J26: Akım DC | N26: 82 | P26: A | V26: Kesicinin L2 kontağına ait geçiş direci uygundur.
J27: Gerilim DC | N27: =N29*N26/1000 | P27: mV | V27: Kesicinin L2 kontağına ait geçiş direci uygun değildir.
B28: Çıkış Kademesi | F28: DC 400A | J28: Sonuçlar | V28: Kesicinin L3 kontağına ait geçiş direci uygundur.
B29: Akım | F29: 80,00A | J29: Ölçülen Direnç | N29: ='ANA SAYFA KESİCİ'!O52 | P29: µΩ | V29: Kesicinin L3 kontağına ait geçiş direci uygun değildir.
P30: %
B32: Kontak Direnci µΩ | J32: L-3 | P32: =IF(N38<150,1,0)
B34: Nominal Değerler | J34: Ölçülen
B35: Nominal Direnç | F35: 150 | H35: µΩ | J35: Akım DC | N35: 82 | P35: A
J36: Gerilim DC | N36: =N38*N35/1000 | P36: mV
B37: Çıkış Kademesi | F37: DC 400A | J37: Sonuçlar
B38: Akım | F38: 80,00A | J38: Ölçülen Direnç | N38: ='ANA SAYFA KESİCİ'!O54 | P38: µΩ
P39: %
B45: Sonuç: | D45: =IF(P14<1,V25,V24)
D46: =IF(P23<1,V27,V26)
D47: =IF(P32<1,V29,V28)
B50: UNVAN | E50: : | F50: Elektrik Mühendisi | J50: ONAYLAYAN
B51: TEST TARİHİ | E51: : | F51: ='ANA SAYFA KESİCİ'!F75:J75
B52: ODA SİCİL NO | E52: : | F52: ='ANA SAYFA KESİCİ'!F77:J77
B53: EKİPNET NO | E53: : | F53: ='ANA SAYFA KESİCİ'!F78:J78

Sheet AÇMA-KAPAMA
G2: ŞALT SAHASI | J2: : | K2: ='ANA SAYFA KESİCİ'!K2
G3: LOKASYON | J3: : | K3: ='ANA SAYFA KESİCİ'!K5
B5: KESİCİ AÇMA-KAPAMA SÜRELERİ TEST SONUÇLARI
B7: OTURUM TARİHİ : | J7: ='ANA SAYFA KESİCİ'!F74
T8: 1
B9: Operatör : | D9: Ahmet YILMAZ | H9: Cihaz : | J9: STS 5000 | M9: Cihaz S/N : | O9: SN-19B20 | V9: 3
B11: KESİCİ BİLGİLERİ | T11: 20
B13: Kesici Markası | F13: : | G13: ='ANA SAYFA KESİCİ'!G11 | J13: Kesici Tipi | M13: : | N13: ='ANA SAYFA KESİCİ'!O11
B15: Anma Akımı (A) | F15: : | G15: ='ANA SAYFA KESİCİ'!G13 | J15: İmal Yılı | M15: : | N15: ='ANA SAYFA KESİCİ'!O13 | W15: Uygun
B17: Gerilim Seviyesi (V) | F17: : | G17: ='ANA SAYFA KESİCİ'!G15 | J17: Seri Numarası | M17: : | N17: ='ANA SAYFA KESİCİ'!O15 | W17: Uygun Değil
B19: Motor Gerilimi | F19: : | G19: ='ANA SAYFA KESİCİ'!G17 | J19: Bobin Gerilimi | M19: : | N19: ='ANA SAYFA KESİCİ'!O17 | S19: Max. | T19: Max. | U19: Max.
B21: KESİCİ AÇMA / KAPAMA ZAMANI | S21: 80 | T21: 120 | U21: 5 | W21: 0
B23: Açma | J23: Kapama
S24: 40 | T24: 30 | U24: 20 | V24: 10
B25: A-1 | C25: ='ANA SAYFA KESİCİ'!C61:D61 | E25: ms | F25: Bobin Gerilimi | H25: ='ANA SAYFA KESİCİ'!O17 | J25: A-1 | K25: ='ANA SAYFA KESİCİ'!J61 | M25: ms | N25: Bobin Gerilimi | P25: ='ANA SAYFA KESİCİ'!O17 | S25: 40 | T25: 30 | U25: 20 | V25: 10
B26: B-1 | C26: ='ANA SAYFA KESİCİ'!C63:D63 | E26: ms | J26: B-1 | K26: ='ANA SAYFA KESİCİ'!J63 | M26: ms
B27: C-1 | C27: ='ANA SAYFA KESİCİ'!C65:D65 | E27: ms | F27: Bobin Akımı | H27: ='ANA SAYFA KESİCİ'!F65 | I27: A | J27: C-1 | K27: ='ANA SAYFA KESİCİ'!J65 | M27: ms | N27: Bobin Akımı | P27: ='ANA SAYFA KESİCİ'!M65 | Q27: A
B28: Faz Uyuşmazlığı | J28: Faz Uyuşmazlığı | W28: Kesicinin L1 fazına ait izolasyon direnç değeri uygun değildir.
B29: ='ANA SAYFA KESİCİ'!F61 | E29: ms | F29: =IF(B29>5,W17,W15) | J29: ='ANA SAYFA KESİCİ'!M61 | M29: ms | N29: =IF(J29>5,W17,W15)
W30: Kesicinin L2 fazına ait izolasyon direnç değeri uygundur.
W31: Kesicinin L2 fazına ait izolasyon direnç değeri uygun değildir.
W32: Kesicinin L3 fazına ait izolasyon direnç değeri uygundur.
W33: Kesicinin L3 fazına ait izolasyon direnç değeri uygun değildir.
W38: Kesicinin Açma süreleri ve bobin akım değerleri uygundur.
B39: TEDAŞ-MLZ/95-008.A İlgili Teknik Şartnamesi Gereği | W39: Kesicinin Açma süreleri uygun değildir.
B40: Açma süresi: 80 milisaniyeden az | W40: Kesicinin Kapama süreleri ve bobin akım değerleri uygundur.
B41: Kapama süresi: 120 milisaniyeden az | W41: Kesicinin Kapama süreleri uygun değildir.
B42: Açma süresi faz uyuşmazlığı: 5 milisaniyeden az | W42: Kesicinin Açma-Kapama Süresi Faz Uyuşmazlığı uygundur.
B43: Kapama süresi faz uyuşmazlığı: 5 milisaniyeden az | W43: Kesicinin Açma-Kapama Süresi Faz Uyuşmazlığı uygun değildir.
B45: Sonuç : | D45: =IF(OR(C25>S21,C26>S21,C27>S21),W39,W38)
D46: =IF(OR(K25>T21,K26>T21,K27>T21),W41,W40)
D47: =IF(OR(B29>U21,J29>U21),W43,W42)
B48: UNVAN | E48: : | F48: Elektrik Mühendisi | J48: ONAYLAYAN
B49: TEST TARİHİ | E49: : | F49: ='ANA SAYFA KESİCİ'!F75
B50: ODA SİCİL NO | E50: : | F50: ='ANA SAYFA KESİCİ'!F77
B51: EKİPNET NO | E51: : | F51: ='ANA SAYFA KESİCİ'!F78

Sheet DİĞER
G2: ŞALT SAHASI | I2: : | J2: ='ANA SAYFA'!K2
G3: LOKASYON | I3: : | J3: ='ANA SAYFA'!K5
B7: OTURUM TARİHİ : | J7: ='ANA SAYFA'!F72
T8: 1
B9: Operatör : | D9: Ahmet YILMAZ | H9: Cihaz : | J9: STS 5000 | M9: Cihaz S/N : | O9: SN-19B20
T10: 20
B11: Sonuçlar
B13: HÜCRE İZOLASYON
F15: GΩ | H15: Test Gerilimi | K15: Test Akımı | N15: Sonuç
B16: L1 | D16: STS 5000 | F16: GΩ | H16: 10000 | J16: VDC | K16: =H16/D16 | M16: nA | N16: =IF(D16>250,1,0) | O16: =IF(D16>250,"UYGUN","UYGUN DEĞİL")
B17: L2 | D17: SN-19B20 | F17: GΩ | H17: 10000 | J17: VDC | K17: =H17/D17 | M17: nA | N17: =IF(D17>250,1,0) | O17: =IF(D17>250,"UYGUN","UYGUN DEĞİL") | W17: L1 Fazına ait Akım Trafosunun izolasyon direnç değeri uygundur.
B18: L3 | D18: 20000 | F18: GΩ | H18: 10000 | J18: VDC | K18: =H18/D18 | M18: nA | N18: =IF(D18>250,1,0) | O18: =IF(D18>250,"UYGUN","UYGUN DEĞİL") | W18: L1 Fazına ait Akım Trafosunun izolasyon direnç değeri uygun değildir.
W19: L2 Fazına ait Akım Trafosunun izolasyon direnç değeri uygundur.
B20: ÇIKIŞ HÜCRESİ MESNET İZOLATÖRÜ İZOLASYON | W20: L2 Fazına ait Akım Trafosunun izolasyon direnç değeri uygun değildir.
W21: L3 Fazına ait Akım Trafosunun izolasyon direnç değeri uygundur.
F22: GΩ | H22: Test Gerilimi | K22: Test Akımı | N22: Sonuç | W22: L3 Fazına ait Akım Trafosunun izolasyon direnç değeri uygun değildir.
B23: L4 | D23: 7100 | F23: GΩ | H23: 10000 | J23: VDC | K23: =H23/D23 | M23: nA | N23: =IF(D23>250,1,0) | O23: =IF(D23>250,"UYGUN","UYGUN DEĞİL")
B24: L5 | D24: 20000 | F24: GΩ | H24: 10000 | J24: VDC | K24: =H24/D24 | M24: nA | N24: =IF(D24>250,1,0) | O24: =IF(D24>250,"UYGUN","UYGUN DEĞİL")
B25: L6 | D25: 20000 | F25: GΩ | H25: 10000 | J25: VDC | K25: =H25/D25 | M25: nA | N25: =IF(D25>250,1,0) | O25: =IF(D25>250,"UYGUN","UYGUN DEĞİL")
B27: HÜCRE-TRAFO ARASINDAKİ XLPE KABLO İZOLASYON
B29: R min. | F29: GΩ | H29: Test Gerilimi | K29: Test Akımı | N29: Sonuç
B30: L7 | D30: 22.9 | F30: GΩ | H30: 10000 | J30: VDC | K30: =H30/D30 | M30: nA | N30: =IF(D30>20,1,0) | O30: =IF(D30>20,"UYGUN","UYGUN DEĞİL")
B31: L8 | D31: 132 | F31: GΩ | H31: 10000 | J31: VDC | K31: =H31/D31 | M31: nA | N31: =IF(D31>20,1,0) | O31: =IF(D31>20,"UYGUN","UYGUN DEĞİL")
B32: L9 | D32: 60.8 | F32: GΩ | H32: 10000 | J32: VDC | K32: =H32/D32 | M32: nA | N32: =IF(D32>20,1,0) | O32: =IF(D32>20,"UYGUN","UYGUN DEĞİL")
B39: Sonuç : | D39: Ölçülen izolasyon direnci değerleri uygun bulunmuştur.
B44: UNVAN | E44: : | F44: Elektrik Mühendisi | J44: ONAYLAYAN
B45: TEST TARİHİ | E45: : | F45: ='ANA SAYFA'!F73:J73
B46: ODA SİCİL NO | E46: : | F46: ='ANA SAYFA'!$F$75
B47: EKİPNET NO | E47: : | F47: ='ANA SAYFA'!$F$76

Sheet AKIM TRAFOLARI
G2: ŞALT SAHASI | I2: : | J2: ='ANA SAYFA'!K2
G3: LOKASYON | I3: : | J3: ='ANA SAYFA'!K5
B7: OTURUM TARİHİ : | J7: ='ANA SAYFA'!F72
T8: 1
B9: Operatör : | D9: Ahmet YILMAZ | H9: Cihaz : | J9: STS 5000 | M9: Cihaz S/N : | O9: SN-19B20
T10: 20
B11: Sonuçlar
B13: AKIM TRAFOLARI
B15: R min. | D15: 250 | F15: GΩ | H15: Test Gerilimi | K15: Test Akımı | N15: Sonuç
B16: L1 | D16: 1500 | F16: GΩ | H16: 10000 | J16: VDC | K16: =H16/D16 | M16: nA | N16: =IF(D16>250,1,0) | O16: =IF(D16>250,"UYGUN","UYGUN DEĞİL")
B17: L2 | D17: 10000 | F17: GΩ | H17: 10000 | J17: VDC | K17: =H17/D17 | M17: nA | N17: =IF(D17>250,1,0) | O17: =IF(D17>250,"UYGUN","UYGUN DEĞİL") | W17: L1 Fazına ait Akım Trafosunun izolasyon direnç değeri uygundur.
B18: L3 | D18: 10000 | F18: GΩ | H18: 10000 | J18: VDC | K18: =H18/D18 | M18: nA | N18: =IF(D18>250,1,0) | O18: =IF(D18>250,"UYGUN","UYGUN DEĞİL") | W18: L1 Fazına ait Akım Trafosunun izolasyon direnç değeri uygun değildir.
W19: L2 Fazına ait Akım Trafosunun izolasyon direnç değeri uygundur.
W20: L2 Fazına ait Akım Trafosunun izolasyon direnç değeri uygun değildir.
W21: L3 Fazına ait Akım Trafosunun izolasyon direnç değeri uygundur.
W22: L3 Fazına ait Akım Trafosunun izolasyon direnç değeri uygun değildir.
B39: Sonuç : | D39: =IF(N16<1,W18,W17)
D40: =IF(N17<1,W20,W19)
D41: =IF(N18<1,W22,W21)
B44: UNVAN | E44: : | F44: Elektrik Mühendisi | J44: ONAYLAYAN
B45: TEST TARİHİ | E45: : | F45: ='ANA SAYFA KESİCİ'!F75
B46: ODA SİCİL NO | E46: : | F46: ='ANA SAYFA'!$F$75
B47: EKİPNET NO | E47: : | F47: ='ANA SAYFA'!$F$76
