Workbook

Sheet KAPAK SAYFASI
E1: B.T.S. ELEKTRİK TRAFO BAKIM
E3: MÜH. İNŞ. MAK. LAB. SAN. VE TİC. LTD. ŞTİ.
A7: TRAFO BAKIM RAPORU
A9: Müşterinin Adı | D9: BARMAK MAKİNA (ÇAĞLA ELK.)
A10: Trafo Etiketi | D10: TRAFO 1
A11: ADRESİ | D11: O.S.B. / BURSA
A12: RAPOR TARİHİ | D12: 45310
A13: REFERANS | D13: International Electrical Testing Association
A14: RAPOR KONUSU | D14: 45307 | E14: Tarihinde yapılan Trafo Bakım raporu.
B16: TRAFO BAKIMI VE KONTROLLERİ
A18: - | B18: Trafonun D.C. İzolasyon test değerleri uygun bulunmuştur.
A20: - | B20: Trafoda yapılan çevirme oranı (TTR) test sonuçları uygun bulmuştur, buna bağlı olarak kademe değiştirici ile sargılar arasındaki bağlantılarda herhangi bir sorun olmadığı gözlemlenmiştir.
A23: - | B23: Trafoda yapılan D.C. Sargı direnci test sonuçlarının uygun olduğu tespit edilmiştir, sargılar arasındaki direnç farklılıkları max. değerin (%5) altındadır. Bu sonuçlara göre; sargı bağlantı uçları, kademe değiştirici kontakları, tij bağlantılarında gevşeklik olmadığı gözlemlenmiştir.
A27: - | B27: Görsel olarak yapılan kontrollerde herhangi bir soruna rastlanmamıştır.
A29: SONUÇ
A31: Kontroller yapıldıktan sonra trafoya enerji verildi. Mevcut şartlar korunması halinde bir sonraki kontrol periyoduna kadar trafonun kullanımı UYGUNDUR. Aksi belirtilmediği sürece periyodik kontroller 1 (bir) yıl sonra yapılır.
A54: Test Tarihi | C54: : | D54: =D14 -> 45307 | G54: ONAYLAYAN
A55: Rapor Tarihi | C55: : | D55: =D12 -> 45310
A56: Unvan | C56: : | D56: Elektrik Mühendisi
A57: Sicil No | C57: : | D57: 88258
A58: Ekipnet No | C58: : | D58: K202439698
A60: Bu belge 5070 sayılı elektronik imza kanununa göre güvenli elektronik imza ile imzalanmıştır.
A62: Üçevler Mahallesi Ak-Va Sanayi Sitesi 80. Sokak No:2/P Nilüfer-BURSA
A63: Telefon : 444 0 287 - 0224 441 94 33 Mail: www.btselektrik.com.tr
A64: Gsm : 0532 206 58 32 - 0538 035 35 94

Sheet ANA SAYFA
H2: ŞALT SAHASI | K2: ='KAPAK SAYFASI'!D9 -> BARMAK MAKİNA (ÇAĞLA ELK.)
H5: TRAFO ETİKETİ | K5: ='KAPAK SAYFASI'!D10 -> TRAFO 1
B6: Üçevler Mh. AK-VA Sanayi Sitesi 80. Sk. No:2/P Nilüfer / BURSA / TÜRKİYE
B9: TRAFO BİLGİLERİ
B11: Trafo Markası | F11: : | G11: BEST | K11: Kademe Bilgisi | N11: : | O11: 6 | P11: / | Q11: 4 | R11: / | S11: 3
B13: Trafo Gücü (kVA) | F13: : | G13: 2000 | K13: İmal Yılı | N13: : | O13: 06/2013
B15: Gerilim Seviyesi (V) | F15: : | G15: 34500 / 400 | K15: Seri Numarası | N15: : | O15: 1330
B17: Bağlantı Grubu | F17: : | G17: Dyn11 | K17: Kısa Devre Emp.% | N17: : | O17: 6.42
B19: Kazan Tipi | F19: : | G19: Hermetik | K19: Genleşme Tanklı | P19: Kuru Tip | R19: ü
B23: KONTROLLER
I24: Evet | J24: Hayır | R24: Evet | S24: Hayır
B26: Trafo Sıcaklık Kontrolü | F26: : | G26: 35 | H26: °C | I26: ü | K26: Trafo Temizliği | O26: : | P26: YAPILDI | R26: ü
B28: Fan ON | F28: : | G28: UYGUN | I28: ü | K28: Bina Temizliği | O28: : | P28: UYGUN | R28: ü
B30: DC Redresör Kontrolü | F30: : | G30: 24 | H30: Vdc | I30: ü | K30: Kablo Sıkılık Kontrolü | O30: : | P30: UYGUN | R30: ü
B32: Termometre Alarm | F32: : | G32: UYGUN | I32: ü | K32: Epoksi Kontrolü | O32: : | P32: UYGUN | R32: ü
B34: Termometre Trip | F34: : | G34: UYGUN | I34: ü | K34: Termistor Kontrolü | O34: : | P34: UYGUN | R34: ü
B36: Fan OFF | F36: : | G36: UYGUN | I36: ü | K36: Topraklama Bağlantısı | O36: : | P36: UYGUN | R36: ü
B38: TOPRAKLAMA ÖLÇÜMÜ ( Ω ) | V38: ÇEVİRME ORANI ( TTR ) | AF38: ÇEVİRME ORANI ( TTR )
B40: Trafo Topraklaması | G40: : | H40: 0.16 | J40: Ω | K40: A.G Pano Topraklaması | P40: : | Q40: 0 | S40: Ω | V40: AB / an | Y40: BC / bn | AB40: CA / cn | AF40: AB / an | AI40: BC / bn | AL40: CA / cn
B42: Nötr (işletme) Topraklaması | G42: : | H42: 0.15 | J42: Ω | K42: Kapı Topraklaması | P42: : | Q42: 0.16 | S42: Ω | V42: =V51/1.0525889 -> 123.53329 | Y42: =Y51/1.0525889 -> 123.73651 | AB42: =AB51/1.0525889 -> 123.57129 | AF42: =AF51/1.045489 -> 143.03259 | AI42: =AI51/1.045489 -> 143.26789 | AL42: =AL51/1.045489 -> 143.07659
B44: Hücre Topraklaması | G44: : | H44: 0.16 | J44: Ω | K44: Direk Topraklaması | P44: : | Q44: _ | S44: Ω | V44: Kademe Bilgisi | Y44: : | Z44: 28500 / 400 | AF44: Kademe Bilgisi | AI44: : | AJ44: 33000 / 400
B47: 2 | C47: A | D47: SARGI DİRENÇLERİ ( Ω ) | I47: 100 | J47: A | K47: ÇEVİRME ORANI ( TTR ) | V47: ÇEVİRME ORANI ( TTR ) | AF47: ÇEVİRME ORANI ( TTR )
B49: RAB : | C49: 3.263 | F49: Ran : | G49: 0.000256 | K49: AB / an | N49: BC / bn | Q49: CA / cn | V49: AB / an | Y49: BC / bn | AB49: CA / cn | AF49: AB / an | AI49: BC / bn | AL49: CA / cn
B51: RAC : | C51: 3.258 | F51: Rbn : | G51: 0.000257 | K51: 149.539 | N51: 149.785 | Q51: 149.585 | V51: =V60/1.050038 -> 130.02977 | Y51: =Y60/1.050038 -> 130.24367 | AB51: =AB60/1.050038 -> 130.06977 | AF51: =K51 -> 149.539 | AI51: =N51 -> 149.785 | AL51: =Q51 -> 149.585
B53: RBC : | C53: 3.35 | F53: Rcn : | G53: 0.000251 | K53: Kademe Bilgisi | N53: : | O53: 34500 | Q53: / | R53: 230.9494 | V53: Kademe Bilgisi | Y53: : | Z53: 30000 / 400 | AF53: Kademe Bilgisi | AI53: : | AJ53: 34500 / 400
B56: İZOLASYON (YALITIM) DİRENÇLERİ ( Ω ) | V56: ÇEVİRME ORANI ( TTR ) | AF56: ÇEVİRME ORANI ( TTR )
F58: 30 sn | I58: 45 sn | L58: 60 sn | O58: Birim | Q58: DAR | V58: AB / an | Y58: BC / bn | AB58: CA / cn | AF58: AB / an | AI58: BC / bn | AL58: CA / cn
B60: Y.G - TANK | F60: 1111 | I60: 2311 | L60: 3456 | O60: G | P60: Ω | Q60: =L60/F60 -> 3.1107111 | V60: =AF42/1.04758 -> 136.5362 | Y60: =AI42/1.04758 -> 136.76081 | AB60: =AL42/1.04758 -> 136.5782 | AF60: =AF51*1.043443 -> 156.03542 | AI60: =AI51*1.043443 -> 156.29211 | AL60: =AL51*1.043443 -> 156.08342
B62: A.G - TANK | F62: 1111 | I62: 3232 | L62: 3456 | O62: G | P62: Ω | Q62: =L62/F62 -> 3.1107111 | V62: Kademe Bilgisi | Y62: : | Z62: 31500 / 400 | AF62: Kademe Bilgisi | AI62: : | AJ62: 36000 / 400
B64: Y.G - A.G | F64: 1111 | I64: 3232 | L64: 3345 | O64: G | P64: Ω | Q64: =L64/F64 -> 3.0108011
B67: NOTLAR : Trafonun, trafo odasının, hücre odasının, trafo koruma hücresinin, kesicinin test, kontrol ve temizliği yapıldı. Test sonuçlarının değerlendirilmesi kapak sayfasında yapılmıştır.
B72: Rapor Tarihi | E72: : | F72: ='KAPAK SAYFASI'!D55 -> 45310 | K72: ONAYLAYAN
B73: Test Tarihi | E73: : | F73: ='KAPAK SAYFASI'!D54 -> 45307
B74: Unvan | E74: : | F74: ='KAPAK SAYFASI'!D56 -> Elektrik Mühendisi
B75: Sicil No | E75: : | F75: ='KAPAK SAYFASI'!D57 -> 88258
B76: Ekipnet No | E76: : | F76: ='KAPAK SAYFASI'!D58 -> K202439698

Sheet OG SARGI MEVCUT KADEME
G2: ŞALT SAHASI | I2: : | J2: ='ANA SAYFA'!K2 -> BARMAK MAKİNA (ÇAĞLA ELK.)
G3: LOKASYON | I3: : | J3: ='ANA SAYFA'!K5 -> TRAFO 1
B5: PRİMER SARGI DİRENCİ TEST SONUÇLARI
B7: Üretici : | D7: ='ANA SAYFA'!G11 -> BEST | G7: Model : | I7: ='ANA SAYFA'!O13 -> 06/2013 | L7: Seri Numarası : | O7: ='ANA SAYFA'!O15 -> 1330
B9: OTURUM TARİHİ : | J9: ='ANA SAYFA'!F72 -> 45310
B11: Operatör : | D11: Hilmi GÜL | H11: Cihaz : | J11: STS 5000 | M11: Cihaz S/N : | O11: 19B20
B13: Sonuçlar | V13: ='ANA SAYFA'!G13 -> 2000
V14: =V13/59.75575286 -> 33.469581
B15: PT Sargı Otomatik | J15: HV Mevcut Kademe Tap | O15: ='ANA SAYFA'!S11 -> 3
B17: Nominal Direnç | J17: Sıcaklık Kompan. | N17: Hayır
B18: Vektör Grubu | F18: ='ANA SAYFA'!G17 -> Dyn11 | J18: Malzeme | N18: Cu
B19: 3-faz
B20: Nominal Değerler | F20: =(K24+K25+K26)/3 -> 3.2903333 | H20: Ω
B21: Çıkış Kademesi | F21: DC 6A | T21: A | U21: =MAX(T32:T33) -> 0.025970149
T22: B | U22: =MAX(U32:U33) -> 0.028238183
C23: I Testi [A] | E23: I DC [A] | G23: V DC [V] | I23: Zaman [S] | K23: R.ölç[Ω] | M23: R. Nom | O23: Hata[%] | T23: C | U23: =MAX(V32:V33) -> 0.027462687
B24: A | C24: ='ANA SAYFA'!B47 -> 2 | E24: =C24 -> 2 | G24: =(E24*K24)*0.98 -> 6.39548 | I24: 40 | K24: ='ANA SAYFA'!C49 -> 3.263 | M24: =F20 -> 3.2903333 | O24: =U21 -> 0.025970149 | Q24: =IF(O24>0.05,1,0) -> 0 | T24: SINIR DEĞER | U24: 0.05
B25: B | C25: ='ANA SAYFA'!B47 -> 2 | E25: =C25 -> 2 | G25: =(E25*K25)*0.98 -> 6.566 | I25: 40 | K25: ='ANA SAYFA'!C53 -> 3.35 | M25: =M24 -> 3.2903333 | O25: =U22 -> 0.028238183 | Q25: =IF(O25>0.05,1,0) -> 0
B26: C | C26: ='ANA SAYFA'!B47 -> 2 | E26: =C26 -> 2 | G26: =(E26*K26)*0.98 -> 6.38568 | I26: 40 | K26: ='ANA SAYFA'!C51 -> 3.258 | M26: =M24 -> 3.2903333 | O26: =U23 -> 0.027462687 | Q26: =IF(O26>0.05,1,0) -> 0
T32: =SQRT((K24-K25)^2)/K25 -> 0.025970149 | U32: =SQRT((K24-K25)^2)/K24 -> 0.02666258 | V32: =SQRT((K26-K24)^2)/K24 -> 0.0015323322
T33: =SQRT((K26-K24)^2)/K26 -> 0.0015346839 | U33: =SQRT((K25-K26)^2)/K26 -> 0.028238183 | V33: =SQRT((K26-K25)^2)/K25 -> 0.027462687
B39: Sonuç : | D39: Yapılan ölçümlerde OG (Orta gerilim) sargısına ait direnç değerleri uygundur.
B45: UNVAN | E45: : | F45: Elektrik Mühendisi | J45: ONAYLAYAN
B46: TEST TARİHİ | E46: : | F46: ='ANA SAYFA'!F73:J73 -> 45307
B47: ODA SİCİL NO | E47: : | F47: ='ANA SAYFA'!F75 -> 88258
B48: EKİPNET NO | E48: : | F48: ='ANA SAYFA'!F76 -> K202439698

Sheet AG SARGI
G2: ŞALT SAHASI | I2: : | J2: ='ANA SAYFA'!K2 -> BARMAK MAKİNA (ÇAĞLA ELK.)
G3: LOKASYON | I3: : | J3: ='ANA SAYFA'!K5 -> TRAFO 1
B5: SEKONDER SARGI DİRENCİ TEST SONUÇLARI
B7: Üretici : | D7: ='OG SARGI MEVCUT KADEME'!D7:F7 -> BEST | G7: Model : | I7: ='OG SARGI MEVCUT KADEME'!I7:K7 -> 06/2013 | L7: Seri Numarası : | O7: ='OG SARGI MEVCUT KADEME'!O7:Q7 -> 1330
B9: OTURUM TARİHİ : | J9: ='ANA SAYFA'!F72 -> 45310
B11: Operatör : | D11: ='OG SARGI MEVCUT KADEME'!D11 -> Hilmi GÜL | H11: Cihaz : | J11: STS 5000 | M11: Cihaz S/N : | O11: 19B20
B13: Sonuçlar | V13: ='ANA SAYFA'!G13 -> 2000
V14: =V13/0.69282 -> 2886.7527
B15: PT Sargı Otomatik | J15: LV Kademe Tap | N15: 1
B17: Nominal Direnç | J17: Sıcaklık Kompan. | N17: Hayır
B18: Vektör Grubu | F18: ='ANA SAYFA'!G17 -> Dyn11 | J18: Malzeme | N18: Cu
B19: 3-faz
B20: Nominal Değerler | F20: =(K24+K25+K26)/3 -> 0.00025466667 | H20: Ω
B21: Çıkış Kademesi | F21: DC 400A | T21: A | U21: =MIN(T32:T33) -> 0.0038910506
T22: B | U22: =MIN(U32:U33) -> 0.00390625
C23: I Testi [A] | E23: I DC [A] | G23: V DC [V] | I23: Zaman [S] | K23: R.ölç[Ω] | M23: R. Nom | O23: Hata[%] | T23: C | U23: =MIN(V32:V33) -> 0.01953125
B24: A | C24: ='ANA SAYFA'!I47 -> 100 | E24: =C24 -> 100 | G24: =(K24*E24)*0.98 -> 0.025088 | I24: 35 | K24: ='ANA SAYFA'!G49 -> 0.000256 | M24: =F20 -> 0.00025466667 | O24: =MIN(T32:T33) -> 0.0038910506 | Q24: =IF(O24>0.05,1,0) -> 0 | T24: SINIR DEĞER | U24: 0.05
B25: B | C25: ='ANA SAYFA'!I47 -> 100 | E25: =C25 -> 100 | G25: =(K25*E25)*0.98 -> 0.025186 | I25: 35 | K25: ='ANA SAYFA'!G51 -> 0.000257 | M25: =M24 -> 0.00025466667 | O25: =MIN(U32:U33) -> 0.00390625 | Q25: =IF(O25>0.05,1,0) -> 0
B26: C | C26: ='ANA SAYFA'!I47 -> 100 | E26: =C26 -> 100 | G26: =(K26*E26)*0.98 -> 0.024598 | I26: 35 | K26: ='ANA SAYFA'!G53 -> 0.000251 | M26: =M24 -> 0.00025466667 | O26: =MIN(V32:V33) -> 0.01953125 | Q26: =IF(O26>0.05,1,0) -> 0
T32: =SQRT((K24-K25)^2)/K25 -> 0.0038910506 | U32: =SQRT((K24-K25)^2)/K24 -> 0.00390625 | V32: =SQRT((K26-K24)^2)/K24 -> 0.01953125
T33: =SQRT((K26-K24)^2)/K26 -> 0.019920319 | U33: =SQRT((K25-K26)^2)/K26 -> 0.023904382 | V33: =SQRT((K26-K25)^2)/K25 -> 0.023346304
B39: Sonuç : | D39: Yapılan ölçümlerde AG (Alçak gerilim) sargısına ait direnç değerleri uygundur.
B45: UNVAN | E45: : | F45: Elektrik Mühendisi | J45: ONAYLAYAN
B46: TEST TARİHİ | E46: : | F46: ='ANA SAYFA'!F73 -> 45307
B47: ODA SİCİL NO | E47: : | F47: ='ANA SAYFA'!F75 -> 88258
B48: EKİPNET NO | E48: : | F48: ='ANA SAYFA'!F76 -> K202439698

Sheet İZOLASYON 
G2: ŞALT SAHASI | I2: : | J2: ='ANA SAYFA'!K2 -> BARMAK MAKİNA (ÇAĞLA ELK.)
G3: LOKASYON | I3: : | J3: ='ANA SAYFA'!K5 -> TRAFO 1
B5: D.C. İZOLASYON DİRENCİ TEST SONUÇLARI
B7: Üretici : | D7: ='OG SARGI MEVCUT KADEME'!D7:F7 -> BEST | G7: Model : | I7: ='OG SARGI MEVCUT KADEME'!I7:K7 -> 06/2013 | L7: Seri Numarası : | O7: ='OG SARGI MEVCUT KADEME'!O7:Q7 -> 1330
Y8: OG-TANK | Z8: AG-TANK | AA8: OG-AG
B9: OTURUM TARİHİ : | J9: ='ANA SAYFA'!F72 -> 45310 | X9: LİMİT | Y9: =V15 -> 1.1 | Z9: =V20 -> 0.2 | AA9: =V25 -> 1.1
X10: 30 | Y10: =H18 -> 3110.8 | Z10: =H23 -> 3110.8 | AA10: =H28 -> 3110.8
B11: Operatör : | D11: ='OG SARGI MEVCUT KADEME'!D11 -> Hilmi GÜL | H11: Cihaz : | J11: METREL-MI3210 | M11: Cihaz S/N : | O11: 16060016 | X11: 45 | Y11: =J18 -> 6470.8 | Z11: =J23 -> 9049.6 | AA11: =J28 -> 9049.6
X12: 60 | Y12: =L18 -> 9676.8 | Z12: =L23 -> 9676.8 | AA12: =L28 -> 9366
B13: Sonuçlar | N13: Sıcaklık | P13: ='ANA SAYFA'!G26 -> 35 | Q13: °C
B15: O.G. TANK İZOLASYON | U15: OG-TANK | V15: 1.1
B16: ÖLÇÜLEN DEĞERLER | H16: HESAPLANAN DEĞERLER 20°C | V16: UYGUN
B17: 30 sn | D17: 45 sn | F17: 60 sn | H17: 30 sn | J17: 45 sn | L17: 60 sn | N17: DAR | P17: Sonuç
B18: ='ANA SAYFA'!F60 -> 1111 | C18: GΩ | D18: ='ANA SAYFA'!I60 -> 2311 | E18: GΩ | F18: ='ANA SAYFA'!L60 -> 3456 | G18: GΩ | H18: =B18*V38 -> 3110.8 | I18: GΩ | J18: =D18*V38 -> 6470.8 | K18: GΩ | L18: =F18*V38 -> 9676.8 | M18: GΩ | N18: =L18/H18 -> 3.1107111 | P18: =IF(L18<V15,V18,V16) -> UYGUN | V18: DÜŞÜK
B20: A.G. TANK İZOLASYON | U20: AG-TANK | V20: 0.2
B21: ÖLÇÜLEN DEĞERLER | H21: HESAPLANAN DEĞERLER 20°C | V21: UYGUN
B22: 30 sn | D22: 45 sn | F22: 60 sn | H22: 30 sn | J22: 45 sn | L22: 60 sn | N22: DAR | P22: Sonuç
B23: ='ANA SAYFA'!F62 -> 1111 | C23: GΩ | D23: ='ANA SAYFA'!I62 -> 3232 | E23: GΩ | F23: ='ANA SAYFA'!L62 -> 3456 | G23: GΩ | H23: =B23*V38 -> 3110.8 | I23: GΩ | J23: =D23*V38 -> 9049.6 | K23: GΩ | L23: =F23*V38 -> 9676.8 | M23: GΩ | N23: =L23/H23 -> 3.1107111 | P23: =IF(L23<V20,V23,V21) -> UYGUN | V23: DÜŞÜK
Y24: Yapılan ölçümlerde trafonun izolasyon direnç değerleri uygun bulunmuştur.
B25: O.G. A.G. İZOLASYON | U25: OG-AG | V25: 1.1
B26: ÖLÇÜLEN DEĞERLER | H26: HESAPLANAN DEĞERLER 20°C | V26: UYGUN
B27: 30 sn | D27: 45 sn | F27: 60 sn | H27: 30 sn | J27: 45 sn | L27: 60 sn | N27: DAR | P27: Sonuç
B28: ='ANA SAYFA'!F64 -> 1111 | C28: GΩ | D28: ='ANA SAYFA'!I64 -> 3232 | E28: GΩ | F28: ='ANA SAYFA'!L64 -> 3345 | G28: GΩ | H28: =B28*V38 -> 3110.8 | I28: GΩ | J28: =D28*V38 -> 9049.6 | K28: GΩ | L28: =F28*V38 -> 9366 | M28: GΩ | N28: =L28/H28 -> 3.0108011 | P28: =IF(L28<V25,V28,V26) -> UYGUN | V28: DÜŞÜK
Y32: Yapılan ölçümlerde trafonun izolasyon direnç değerleri düşük bulunmuştur.
U38: ÇARPAN | V38: =IF(P13>40,X43,X42) -> 2.8
B41: Sonuç : | D41: =IF(L18<V15,Y32,Y24) -> Yapılan ölçümlerde trafonun izolasyon direnç değerleri uygun bulunmuştur.
U42: Test Sıcaklığı | V42: İcra Katsayısı | X42: =IF(P13=0,V43, IF(P13=5,V44, IF(P13=10,V45, IF(P13=15,V46, IF(P13=20,V47, IF(P13=25,V48, IF(P13=30,V49, IF(P13=35,V50, IF(P13=40,V51, ))))))))) -> 2.8
U43: 0 | V43: 0.25 | X43: =IF(P13=45,V52, IF(P13=50,V53, IF(P13=55,V54, IF(P13=60,V55, IF(P13=65,V56, IF(P13=70,V57, IF(P13=75,V58, ))))))) -> 0
U44: 5 | V44: 0.36
U45: 10 | V45: 0.5
B46: Not: Polarizasyon endekslerine göre değerlendirme; hem fabrika deney sonuçları hem de daha önceki değerlerle yeni bulunan değerlerin kıyaslanması ile yapılmalıdır. Ölçülen değerler daha önceki değerlere yakın veya büyük ise normal kabul edilir. Ancak ölçüm ilk kez yapılıyorsa; PE=1,0-1,1 Zayıf / PE=1,1-1,25 Şüpheli / PE=1,25-1,40 Orta / PE=1,40-1,60 İyi / PE>1,60 Çok İyi değerlendirmesi yapılır. İzolasyon ölçümlerinde DAR endeksine bağlı kalınmaksızın, sınır değerlerin altında çıkan değerler kötü izolasyon olarak ifade edilmektedir. | U46: 15 | V46: 0.74
U47: 20 | V47: 1
U48: 25 | V48: 1.4
U49: 30 | V49: 1.98
B50: UNVAN | E50: : | F50: Elektrik Mühendisi | J50: ONAYLAYAN | U50: 35 | V50: 2.8
B51: TEST TARİHİ | E51: : | F51: ='ANA SAYFA'!F73 -> 45307 | U51: 40 | V51: 3.95
B52: ODA SİCİL NO | E52: : | F52: ='ANA SAYFA'!F75:J75 -> 88258 | U52: 45 | V52: 5.6
B53: EKİPNET NO | E53: : | F53: ='ANA SAYFA'!F76:J76 -> K202439698 | U53: 50 | V53: 7.85
U54: 55 | V54: 11.2
U55: 60 | V55: 15.85
...

Sheet Ç.O 34500
G2: ŞALT SAHASI | I2: : | J2: ='ANA SAYFA'!K2 -> BARMAK MAKİNA (ÇAĞLA ELK.)
G3: LOKASYON | I3: : | J3: ='ANA SAYFA'!K5 -> TRAFO 1
B5: ÇEVİRME ORANI TEST SONUÇLARI
B7: Üretici : | D7: ='OG SARGI MEVCUT KADEME'!D7:F7 -> BEST | G7: Model : | I7: ='OG SARGI MEVCUT KADEME'!I7:K7 -> 06/2013 | L7: Seri Numarası : | O7: ='OG SARGI MEVCUT KADEME'!O7:Q7 -> 1330
B9: OTURUM TARİHİ : | J9: ='ANA SAYFA'!F72 -> 45310
B11: Operatör : | D11: ='OG SARGI MEVCUT KADEME'!D11 -> Hilmi GÜL | H11: Cihaz : | J11: STS 5000 | M11: Cihaz S/N : | O11: 19B20
B13: Sonuçlar
B15: PT Her Bir Kademe Oran | J15: Tap | K15: ='ANA SAYFA'!S11 -> 3 | N15: Kademe #1 | T15: ='ANA SAYFA'!R53 -> 230.9494 | U15: A | V15: =O26 -> 0.10418066
U16: B | V16: =O27 -> 0.26885762
B17: Nominal Değerler | J17: Test Değerleri | U17: C | V17: =O28 -> 0.13497391
B18: HV Kademeler | F18: ='ANA SAYFA'!O53 -> 34500 | H18: V | J18: Gerilim | N18: 500,0 V | U18: SINIR DEĞER | V18: 0.5
B19: LV Ratings | F19: 231 | H19: V | J19: Frekans | N19: 50, Hz | W19: 0.5 | X19: -0.5
B20: Çevirme Oranı | F20: =F18/T15 -> 149.38337
B22: Sonuçlar
C25: Vn HV [V] | E25: V HV[V] | G25: I HV[A] | I25: V LV[V] | K25: ᶲV LV [°] | M25: Ratio | O25: Err % | V25: ( A ) Fazına ait çevirme oranı hata yüzdesi uygundur.
B26: A | C26: 500 | E26: 500 | G26: =I26/M26 -> 0.010030828 | I26: 1.5 | K26: 26,0m | M26: ='ANA SAYFA'!AF51 -> 149.539 | O26: =(M26-F20)/F20*100 -> 0.10418066
B27: B | C27: 500 | E27: 500 | G27: =I27/M27 -> 0.010014354 | I27: 1.5 | K27: 26,0m | M27: ='ANA SAYFA'!AI51 -> 149.785 | O27: =(M27-F20)/F20*100 -> 0.26885762 | V27: ( A ) Fazına ait çevirme oranı hata yüzdesi hatalı olduğu tespit edilmiştir.
B28: C | C28: 500 | E28: 500 | G28: =I28/M28 -> 0.010027743 | I28: 1.5 | K28: 26,0m | M28: ='ANA SAYFA'!AL51 -> 149.585 | O28: =(M28-F20)/F20*100 -> 0.13497391
V29: ( B ) Fazına ait çevirme oranı hata yüzdesi uygundur.
V31: ( B ) Fazına ait çevirme oranı hata yüzdesi hatalı olduğu tespit edilmiştir.
V34: ( C ) Fazına ait çevirme oranı hata yüzdesi uygundur.
V36: ( C ) Fazına ait çevirme oranı hata yüzdesi hatalı olduğu tespit edilmiştir.
B44: Sonuç : | D44: =IF(OR(O26>W19,O26<X19),V27,V25) -> ( A ) Fazına ait çevirme oranı hata yüzdesi uygundur.
D46: =IF(OR(O27>W19,O27<X19),V31,V29) -> ( B ) Fazına ait çevirme oranı hata yüzdesi uygundur.
D48: =IF(OR(O28>W19,O28<X19),V36,V34) -> ( C ) Fazına ait çevirme oranı hata yüzdesi uygundur.
B50: UNVAN | E50: : | F50: Elektrik Mühendisi | J50: ONAYLAYAN
B51: TEST TARİHİ | E51: : | F51: ='ANA SAYFA'!F73 -> 45307
B52: ODA SİCİL NO | E52: : | F52: ='ANA SAYFA'!F75:J75 -> 88258
B53: EKİPNET NO | E53: : | F53: ='ANA SAYFA'!F76:J76 -> K202439698

Sheet TOPRAKLAMALAR
G2: ŞALT SAHASI | I2: : | J2: ='ANA SAYFA'!K2 -> BARMAK MAKİNA (ÇAĞLA ELK.)
G3: LOKASYON | I3: : | J3: ='ANA SAYFA'!K5 -> TRAFO 1
B5: Dosya Adı : | E5: TOPRAKLAMA ÖLÇÜM SONUÇLARI
B7: OTURUM TARİHİ : | J7: ='ANA SAYFA'!F72 -> 45310
B9: Operatör : | D9: ='OG SARGI MEVCUT KADEME'!D11 -> Hilmi GÜL | H9: Cihaz : | J9: METREL-MI3123 | M9: Cihaz S/N : | O9: 16350177
B11: Sonuçlar
B13: İŞLETME (NÖTR) TOPRAK DİRENCİ
N15: Sonuç
B16: Max. Ω | D16: 2 | F16: Ω | H16: Ölçülen | J16: Ω | K16: ='ANA SAYFA'!H42 -> 0.15 | M16: Ω | N16: =IF(K16<D16,W18,Y18) -> UYGUN
W18: UYGUN | Y18: UYGUN DEĞİL
B23: KORUMA TOPRAK DİRENCİ
N25: Sonuç | V25: İşletme (NÖTR) topraklaması direnç değeri normaldir.
B26: Trafo | D26: Max. Ω | F26: 2 | G26: Ω | H26: Ölçülen | J26: Ω | K26: ='ANA SAYFA'!H40 -> 0.16 | M26: Ω | N26: =IF(K26<F26,W18,Y18) -> UYGUN | V26: İşletme (NÖTR) topraklaması direnç değeri yüksek bulunmuştur.
B27: Hücre | D27: Max. Ω | F27: 2 | G27: Ω | H27: Ölçülen | J27: Ω | K27: ='ANA SAYFA'!H44 -> 0.16 | M27: Ω | N27: =IF(K27<F27,W18,Y18) -> UYGUN | V27: Trafo topraklaması direnç değeri normaldir.
B28: Kapılar | D28: Max. Ω | F28: 2 | G28: Ω | H28: Ölçülen | J28: Ω | K28: ='ANA SAYFA'!Q42 -> 0.16 | M28: Ω | N28: =IF(K28<F28,W18,Y18) -> UYGUN | V28: Trafo topraklaması direnç değeri yüksek bulunmuştur.
B29: AG. Pano | D29: Max. Ω | F29: 2 | G29: Ω | H29: Ölçülen | J29: Ω | K29: ='ANA SAYFA'!Q40 -> 0 | M29: Ω | N29: =IF(K29<F29,W18,Y18) -> UYGUN
V30: Hücre topraklaması direnç değeri normaldir.
V31: Hücre topraklaması direnç değeri yüksek bulunmuştur.
V33: A.G. Pano topraklaması direnç değeri normaldir.
V34: A.G. Pano topraklaması direnç değeri yüksek bulunmuştur.
V36: Kapı topraklaması direnç değeri normaldir.
V37: Kapı topraklaması direnç değeri yüksek bulunmuştur.
V38: Direk topraklaması direnç değeri normaldir.
V39: Direk topraklaması direnç değeri yüksek bulunmuştur.
B41: Sonuç : | D41: =IF(K16<D16,V25,V26) -> İşletme (NÖTR) topraklaması direnç değeri normaldir.
D42: =IF(K26<F26,V27,V28) -> Trafo topraklaması direnç değeri normaldir.
D43: =IF(K27<F27,V30,V31) -> Hücre topraklaması direnç değeri normaldir.
D44: =IF(K28<F28,V36,V37) -> Kapı topraklaması direnç değeri normaldir.
D45: =IF(K29<F29,V33,V34) -> A.G. Pano topraklaması direnç değeri normaldir.
B47: UNVAN | E47: : | F47: Elektrik Mühendisi | J47: ONAYLAYAN
B48: TEST TARİHİ | E48: : | F48: ='ANA SAYFA'!F73 -> 45307
B49: ODA SİCİL NO | E49: : | F49: ='ANA SAYFA'!F75:J75 -> 88258
B50: EKİPNET NO | E50: : | F50: ='ANA SAYFA'!F76:J76 -> K202439698

Sheet HV PF
G2: ŞALT SAHASI | I2: : | J2: ='ANA SAYFA'!K2 -> BARMAK MAKİNA (ÇAĞLA ELK.)
G3: LOKASYON | I3: : | J3: ='ANA SAYFA'!K5 -> TRAFO 1
B5: YÜKSEK GERİLİM GÜÇ FAKTÖRÜ TEST SONUÇLARI
V6: Test Sıcaklığı | X6: İcra Katsayısı
B7: Üretici : | D7: ='OG SARGI MEVCUT KADEME'!D7:F7 -> BEST | G7: Model : | I7: ='OG SARGI MEVCUT KADEME'!I7:K7 -> 06/2013 | L7: Seri Numarası : | O7: ='OG SARGI MEVCUT KADEME'!O7:Q7 -> 1330
V8: 10 | X8: 0.8 | AA8: =IF(P15=10,X8, IF(P15=15,X9, IF(P15=20,X10, IF(P15=25,X11, IF(P15=30,X12, IF(P15=35,X13, IF(P15=40,X14, IF(P15=45,X15, IF(P15=50,X16))))))))) -> 1.4
B9: OTURUM TARİHİ : | J9: ='ANA SAYFA'!F72 -> 45310 | V9: 15 | X9: 0.9
V10: 20 | X10: 1
B11: Operatör : | D11: ='OG SARGI MEVCUT KADEME'!D11 -> Hilmi GÜL | H11: Cihaz : | J11: STS 5000 | M11: Cihaz S/N : | O11: 19B20 | V11: 25 | X11: 1.2
V12: 30 | X12: 1.25
B13: Sonuçlar | V13: 35 | X13: 1.4
V14: 40 | X14: 1.55
B15: HV Sargı | K15: Sıcaklık: | O15: ~ | P15: ='ANA SAYFA'!G26 -> 35 | Q15: °C | V15: 45 | X15: 1.75
B16: Testler | C16: # | E16: Kapasitans | H16: Tarama | K16: Mod | N16: V [V] | P16: f [Hz] | V16: 50 | X16: 1.95
C17: 1 | D17: 1 | E17: CH | H17: Hiçbiri | K17: GSTg-A | N17: 10000 | P17: 50 | V17: 55 | X17: 2.18
C18: 2 | D18: 1 | E18: CHL | H18: Hiçbiri | K18: UST-A | N18: 10000 | P18: 50 | V18: 60 | X18: 2.42
C19: 3 | D19: 1 | E19: CH+CHL | H19: Hiçbiri | K19: GST | N19: 10000 | P19: 50 | V19: 65 | X19: 2.7
V20: 70 | X20: 3
B21: Sonuçlar | C21: CH
C22: # | D22: V [V] | F22: f [Hz] | H22: PF (%) | J22: Kayıp W | L22: Z (kΩ) | N22: Stest (VA) | P22: PF20°C
C23: 1 | D23: 10000 | F23: 50 | H23: 0.202 | J23: 0.10592 | L23: 1919.95 | N23: 52.423 | P23: =H23/AA8 -> 0.14428571
C25: CHL
C26: # | D26: V [V] | F26: f [Hz] | H26: PF (%) | J26: Kayıp W | L26: Z (kΩ) | N26: Stest (VA) | P26: PF20°C
C27: 2 | D27: 10000 | F27: 50 | H27: 0.32 | J27: 0.36838 | L27: 888.675 | N27: 113.255 | P27: =H27/AA8 -> 0.22857143
C29: CH+CHL
C30: # | D30: V [V] | F30: f [Hz] | H30: PF (%) | J30: Kayıp W | L30: Z (kΩ) | N30: Stest (VA) | P30: PF20°C
C31: 3 | D31: 10000 | F31: 50 | H31: 0.345 | J31: 0.47396 | L31: 607.447 | N31: =N23+N27 -> 165.678 | P31: =H31/AA8 -> 0.24642857
B33: Not: Hava koşullarının test değerlerine olan etkisini ortadan kaldırıp, sonraki ölçümlerde kıyaslama imkanı sağlamak amacıyla, mevcut sıcaklık değeri kaydedilerek ölçülen %PF değerlerine, referans bir sıcaklığa (20°C) göre sıcaklık icralaması yapılmaktadır. İşletmedeki transformatörlerde PF(20°C) ≤ 1 olmalıdır.
B36: TEST DEĞERLERİNİN YORUMU
B37: CH (YG/Tank-Nüve) değerleri uygundur.
B39: CHL (YG/AG) değerleri uygundur.
B41: CH+CHL (∑YG/Tank-Nüve) değerleri uygundur.
B44: UNVAN | E44: : | F44: Elektrik Mühendisi | J44: ONAYLAYAN
B45: TEST TARİHİ | E45: : | F45: ='ANA SAYFA'!F73 -> 45307
B46: ODA SİCİL NO | E46: : | F46: ='ANA SAYFA'!F75 -> 88258
B47: EKİPNET NO | E47: : | F47: ='ANA SAYFA'!F76 -> K202439698

Sheet LV PF
G2: ŞALT SAHASI | I2: : | J2: ='ANA SAYFA'!K2 -> BARMAK MAKİNA (ÇAĞLA ELK.)
G3: LOKASYON | I3: : | J3: ='ANA SAYFA'!K5 -> TRAFO 1
B5: ALÇAK GERİLİM GÜÇ FAKTÖRÜ TEST SONUÇLARI
V6: Test Sıcaklığı | X6: İcra Katsayısı
B7: Üretici : | D7: ='OG SARGI MEVCUT KADEME'!D7:F7 -> BEST | G7: Model : | I7: ='OG SARGI MEVCUT KADEME'!I7:K7 -> 06/2013 | L7: Seri Numarası : | O7: ='OG SARGI MEVCUT KADEME'!O7:Q7 -> 1330
V8: 10 | X8: 0.8 | AA8: =IF(P15=10,X8, IF(P15=15,X9, IF(P15=20,X10, IF(P15=25,X11, IF(P15=30,X12, IF(P15=35,X13, IF(P15=40,X14, IF(P15=45,X15, IF(P15=50,X16,IF(P15=55,X17,IF(P15=60,X18))))))))))) -> 1.4
B9: OTURUM TARİHİ : | J9: ='ANA SAYFA'!F72 -> 45310 | V9: 15 | X9: 0.9
V10: 20 | X10: 1
B11: Operatör : | D11: ='OG SARGI MEVCUT KADEME'!D11 -> Hilmi GÜL | H11: Cihaz : | J11: STS 5000 | M11: Cihaz S/N : | O11: 19B20 | V11: 25 | X11: 1.2
V12: 30 | X12: 1.25
B13: Sonuçlar | V13: 35 | X13: 1.4
V14: 40 | X14: 1.55
B15: LV Sargı | K15: Sıcaklık: | O15: ~ | P15: ='HV PF'!P15 -> 35 | Q15: °C | V15: 45 | X15: 1.75
B16: Testler | C16: # | E16: Kapasitans | H16: Tarama | K16: Mod | N16: V [V] | P16: f [Hz] | V16: 50 | X16: 1.95
C17: 1 | D17: 1 | E17: CL | H17: Hiçbiri | K17: GSTg-A | N17: 10000 | P17: 50 | V17: 55 | X17: 2.18
C18: 2 | D18: 1 | E18: CHL | H18: Hiçbiri | K18: UST-A | N18: 10000 | P18: 50 | V18: 60 | X18: 2.42
C19: 3 | D19: 1 | E19: CL+CHL | H19: Hiçbiri | K19: GST | N19: 10000 | P19: 50 | V19: 65 | X19: 2.7
V20: 70 | X20: 3
B21: Sonuçlar | C21: CL
C22: # | D22: V [V] | F22: f [Hz] | H22: PF (%) | J22: Kayıp W | L22: Z (kΩ) | N22: Stest (VA) | P22: PF20°C
C23: 1 | D23: 1000 | F23: 50 | H23: 0.513 | J23: 0.10228 | L23: 202.124 | N23: 19.915 | P23: =H23/AA8 -> 0.36642857
C25: CHL
C26: # | D26: V [V] | F26: f [Hz] | H26: PF (%) | J26: Kayıp W | L26: Z (kΩ) | N26: Stest (VA) | P26: PF20°C
C27: 2 | D27: 1000 | F27: 50 | H27: 0.323 | J27: 0.0146573 | N27: 4.528 | P27: =H27/AA8 -> 0.23071429
C29: CL+CHL
C30: # | D30: V [V] | F30: f [Hz] | H30: PF (%) | J30: Kayıp W | L30: Z (kΩ) | N30: Stest (VA) | P30: PF20°C
C31: 3 | D31: 1000 | F31: 50 | H31: 0.477 | J31: 0.11662 | L31: 164.684 | N31: =N23+N27 -> 24.443 | P31: =H31/AA8 -> 0.34071429
B33: Not: Hava koşullarının test değerlerine olan etkisini ortadan kaldırıp, sonraki ölçümlerde kıyaslama imkanı sağlamak amacıyla, mevcut sıcaklık değeri kaydedilerek ölçülen %PF değerlerine, referans bir sıcaklığa (20°C) göre sıcaklık icralaması yapılmaktadır. İşletmedeki transformatörlerde PF(20°C) ≤ 1 olmalıdır.
B36: TEST DEĞERLERİNİN YORUMU
B37: CL (AG/Tank-Nüve) değerleri uygundur. Testlerin periyodik programa uygun olarak yaptırılıp takip edilmesi önerilir.
B39: CHL (AG/YG) değerleri uygundur.
B41: CL+CHL (∑AG/Tank-Nüve) değerleri uygundur.
B44: UNVAN | E44: : | F44: Elektrik Mühendisi | J44: ONAYLAYAN
B45: TEST TARİHİ | E45: : | F45: ='ANA SAYFA'!F73 -> 45307
B46: ODA SİCİL NO | E46: : | F46: ='ANA SAYFA'!F75 -> 88258
B47: EKİPNET NO | E47: : | F47: ='ANA SAYFA'!F76 -> K202439698

Sheet ANA SAYFA KESİCİ
H2: ŞALT SAHASI | K2: ='ANA SAYFA'!K2 -> BARMAK MAKİNA (ÇAĞLA ELK.)
H5: LOKASYON | K5: ='ANA SAYFA'!K5 -> TRAFO 1
B9: KESİCİ BİLGİLERİ
B11: Kesici Markası | F11: : | G11: ULUSOY | K11: Kesici Tipi | N11: : | O11: USFB-36R
B13: Anma Akımı (A) | F13: : | G13: 630 | K13: İmal Yılı | N13: : | O13: 2016
B15: Gerilim Seviyesi (V) | F15: : | G15: 36000 | K15: Seri Numarası | N15: : | O15: 2196
B17: Motor Gerilimi | F17: : | G17: 220 Vac | K17: Bobin Gerilimi | N17: : | O17: 24 Vdc
B21: KONTROLLER
I22: Evet | J22: Hayır | R22: Evet | S22: Hayır
B24: Kesici Görsel Kontrolü | F24: : | G24: UYGUN | I24: ü | K24: Kesici Temizliği | O24: : | P24: YAPILDI | R24: ü
B26: DC Redresör Kontrolü | F26: : | G26: 24 | H26: Vdc | I26: ü | K26: Hücre Temizliği | O26: : | P26: YAPILDI | R26: ü
B28: İndikatör Kontrolü | F28: : | G28: UYGUN | I28: ü | K28: Bara Kontrolü | O28: : | P28: UYGUN | R28: ü
B30: Mekanik Konrolü | F30: : | G30: UYGUN | I30: ü | K30: Isıtıcı Kontrolü | O30: : | P30: UYGUN | R30: ü
B32: Kablo Başlığı Kontrolü | F32: : | G32: UYGUN | I32: ü | K32: A.A Röle Kontrolü | O32: : | P32: UYGUN | R32: ü
B35: BASAMAK VOLTAJ TESTİ
C37: R1 (1.04kV) | F37: R2 (2.04kV) | I37: R3 (3.06kV) | L37: R4 (4.06kV) | O37: R5 (5.09kV) | R37: SONUÇ
B39: L-1 | C39: 2000 | E39: GΩ | F39: 4000 | H39: GΩ | I39: 6000 | K39: GΩ | L39: 8000 | N39: GΩ | O39: 10000 | Q39: GΩ | R39: =IF(O39>250,1,0) -> 1
B41: L-2 | C41: 2000 | E41: GΩ | F41: 4000 | H41: GΩ | I41: 6000 | K41: GΩ | L41: 8000 | N41: GΩ | O41: 10000 | Q41: GΩ | R41: =IF(O41>250,1,0) -> 1
B43: L-3 | C43: 2000 | E43: GΩ | F43: 4000 | H43: GΩ | I43: 6000 | K43: GΩ | L43: 8000 | N43: GΩ | O43: 10000 | Q43: GΩ | R43: =IF(O43>250,1,0) -> 1
B46: KESİCİ İZOLASYON DİRENCİ (GΩ) | K46: KESİCİ KONTAK DİRENCİ (Ω)
C48: TEST VOLTAJI | G48: SONUÇ | K48: TEST AKIMI | O48: SONUÇ
B50: L-1 | C50: 10.00 | F50: kV | G50: 20000 | I50: GΩ | J50: =IF(G50>50,1,0) -> 1 | K50: 80.00A | O50: 38 | R50: µΩ | S50: =IF(O50<150,1,0) -> 1
B52: L-2 | C52: 10.00 | F52: kV | G52: 20000 | I52: GΩ | J52: =IF(G52>50,1,0) -> 1 | K52: 80.00A | O52: 40 | R52: µΩ | S52: =IF(O52<150,1,0) -> 1
B54: L-3 | C54: 10.00 | F54: kV | G54: 20000 | I54: GΩ | J54: =IF(G54>50,1,0) -> 1 | K54: 80.00A | O54: 54 | R54: µΩ | S54: =IF(O54<150,1,0) -> 1
B57: KESİCİ ACMA / KAPAMA ZAMANI
C59: KESİCİ AÇMA | F59: EŞ ZAMAN FARKI | J59: KESİCİ KAPAMA | M59: EŞ ZAMAN FARKI | Q59: SONUÇ
B61: L-1 | C61: 52.63 | E61: ms | F61: =MAX(V80:V85) -> 3.69 | H61: ms | J61: 69.03 | L61: ms | M61: =MAX(X80:X85) -> 2.46 | O61: ms | Q61: UYGUN
B63: L-2 | C63: 54.14 | E63: ms | F63: BOBİN AKIMI | J63: 66.57 | L63: ms | M63: BOBİN AKIMI | Q63: UYGUN
B65: L-3 | C65: 50.45 | E65: ms | F65: 1.3 | H65: A | J65: 68.79 | L65: ms | M65: 1.3 | O65: A | Q65: UYGUN
B68: Sonuç : | D68: Yapılan ölçümlerde kesicinin test değerleri uygun bulundu. Kesicinin ve hücrenin
B69: temizliği yapıldı.
B74: Rapor Tarihi | E74: : | F74: ='ANA SAYFA'!F72 -> 45310 | K74: ONAYLAYAN
B75: Test Tarihi | E75: : | F75: ='ANA SAYFA'!F73 -> 45307
B76: Unvan | E76: : | F76: Elektrik Mühendisi
B77: Sicil No | E77: : | F77: 88258
B78: Ekipnet No | E78: : | F78: K202439698
V80: =C61-C63 -> -1.51 | X80: =J61-J63 -> 2.46
V81: =C61-C65 -> 2.18 | X81: =J61-J65 -> 0.24
V82: =C63-C65 -> 3.69 | X82: =J63-J65 -> -2.22
V83: =C63-C61 -> 1.51 | X83: =J63-J61 -> -2.46
...

Sheet KESİCİ İZOLASYON
G2: ŞALT SAHASI | J2: : | K2: ='ANA SAYFA KESİCİ'!K2 -> BARMAK MAKİNA (ÇAĞLA ELK.)
G3: LOKASYON | J3: : | K3: ='ANA SAYFA KESİCİ'!K5 -> TRAFO 1
B5: KESİCİ İZOLASYON DİRENCİ TEST SONUÇLARI
B8: OTURUM TARİHİ : | J8: ='ANA SAYFA KESİCİ'!F74 -> 45310
B10: Operatör : | D10: Hilmi GÜL | H10: Cihaz : | J10: METREL MI 3210 | M10: Cihaz S/N : | O10: 16060016 | U10: r1 | V10: 250 | W10: 200 | X10: 150 | Y10: 100 | Z10: 50
B12: Sonuçlar
B14: KESİCİ İZOLASYON
B16: R min. | D16: 50 | F16: GΩ | H16: Test Gerilimi | K16: Test Akımı | N16: Sonuç
B17: L-1 | D17: ='ANA SAYFA KESİCİ'!G50 -> 20000 | F17: GΩ | H17: 10000 | J17: VDC | K17: =H17/D17 -> 0.5 | M17: nA | N17: =IF(D17>D16,1,0) -> 1 | O17: =IF(D17>D16,"UYGUN","UYGUN DEĞİL") -> UYGUN
B18: L-2 | D18: ='ANA SAYFA KESİCİ'!G52 -> 20000 | F18: GΩ | H18: 10000 | J18: VDC | K18: =H18/D18 -> 0.5 | M18: nA | N18: =IF(D18>D16,1,0) -> 1 | O18: =IF(D18>D16,"UYGUN","UYGUN DEĞİL") -> UYGUN
B19: L-3 | D19: ='ANA SAYFA KESİCİ'!G54 -> 20000 | F19: GΩ | H19: 10000 | J19: VDC | K19: =H19/D19 -> 0.5 | M19: nA | N19: =IF(D19>D16,1,0) -> 1 | O19: =IF(D19>D16,"UYGUN","UYGUN DEĞİL") -> UYGUN
X20: =N17+N18+N19 -> 3
X24: =(N32+N33+N34+N35+N36)/5 -> 1
X27: Yapılan ölçümlerde kesicinin İzolasyon değerleri uygundur.
X28: Yapılan ölçümlerde kesicinin İzolasyon değerleri uygun değildir.
B29: BASAMAK VOLTAJ TESTİ
D31: L-1 | F31: L-2 | H31: L-3 | K31: Basamak Gerilimi | N31: Sonuç
B32: R1 | D32: ='ANA SAYFA KESİCİ'!C39 -> 2000 | F32: ='ANA SAYFA KESİCİ'!C41 -> 2000 | H32: ='ANA SAYFA KESİCİ'!C43 -> 2000 | J32: GΩ | K32: 1.04 | M32: kV | N32: =IF(D32>50,1,0) -> 1 | O32: =IF(D32>50,"UYGUN","UYGUN DEĞİL") -> UYGUN
B33: R2 | D33: ='ANA SAYFA KESİCİ'!F39 -> 4000 | F33: ='ANA SAYFA KESİCİ'!F41 -> 4000 | H33: ='ANA SAYFA KESİCİ'!F43 -> 4000 | J33: GΩ | K33: 2.04 | M33: kV | N33: =IF(D33>50,1,0) -> 1 | O33: =IF(D33>50,"UYGUN","UYGUN DEĞİL") -> UYGUN
B34: R3 | D34: ='ANA SAYFA KESİCİ'!I39 -> 6000 | F34: ='ANA SAYFA KESİCİ'!I41 -> 6000 | H34: ='ANA SAYFA KESİCİ'!I43 -> 6000 | J34: GΩ | K34: 3.05 | M34: kV | N34: =IF(D34>50,1,0) -> 1 | O34: =IF(D34>50,"UYGUN","UYGUN DEĞİL") -> UYGUN
B35: R4 | D35: ='ANA SAYFA KESİCİ'!L39 -> 8000 | F35: ='ANA SAYFA KESİCİ'!L41 -> 8000 | H35: ='ANA SAYFA KESİCİ'!L43 -> 8000 | J35: GΩ | K35: 4.05 | M35: kV | N35: =IF(D35>50,1,0) -> 1 | O35: =IF(D35>50,"UYGUN","UYGUN DEĞİL") -> UYGUN
B36: R5 | D36: ='ANA SAYFA KESİCİ'!O39 -> 10000 | F36: ='ANA SAYFA KESİCİ'!O41 -> 10000 | H36: ='ANA SAYFA KESİCİ'!O43 -> 10000 | J36: GΩ | K36: 5.09 | M36: kV | N36: =IF(D36>50,1,0) -> 1 | O36: =IF(D36>50,"UYGUN","UYGUN DEĞİL") -> UYGUN
B47: Sonuç : | D47: =IF(OR(X24<1,X20<3),X28,X27) -> Yapılan ölçümlerde kesicinin İzolasyon değerleri uygundur.
B50: UNVAN | E50: : | F50: Elektrik Mühendisi | J50: ONAYLAYAN
B51: TEST TARİHİ | E51: : | F51: ='ANA SAYFA KESİCİ'!F75:J75 -> 45307
B52: ODA SİCİL NO | E52: : | F52: ='ANA SAYFA KESİCİ'!F77:J77 -> 88258
B53: EKİPNET NO | E53: : | F53: ='ANA SAYFA KESİCİ'!F78:J78 -> K202439698

Sheet KESİCİ KONTAK
G2: ŞALT SAHASI | J2: : | K2: ='ANA SAYFA KESİCİ'!K2 -> BARMAK MAKİNA (ÇAĞLA ELK.)
G3: LOKASYON | J3: : | K3: ='ANA SAYFA KESİCİ'!K5 -> TRAFO 1
B5: KESİCİ KONTAK DİRENCİ TEST SONUÇLARI
B8: OTURUM TARİHİ : | J8: ='ANA SAYFA KESİCİ'!F74 -> 45310
B10: Operatör : | D10: Hilmi GÜL | H10: Cihaz : | J10: STS 5000 | M10: Cihaz S/N : | O10: 19B20
B12: Sonuçlar
B14: Kontak Direnci µΩ | J14: L-1 | P14: =IF(N20<150,1,0) -> 1
B16: Nominal Değerler | J16: Ölçülen
B17: Maksimum Direnç | F17: 150 | H17: µΩ | J17: Akım DC | N17: 82 | P17: A
J18: Gerilim DC | N18: =N20*N17/1000 -> 3.116 | P18: mV
B19: Çıkış Kademesi | F19: DC 400A | J19: Sonuçlar
B20: Akım | F20: 80,00A | J20: Ölçülen Direnç | N20: ='ANA SAYFA KESİCİ'!O50 -> 38 | P20: µΩ
J21: Hata | P21: %
B23: Kontak Direnci µΩ | J23: L-2 | P23: =IF(N29<150,1,0) -> 1
V24: Kesicinin L1 kontağına ait geçiş direci uygundur.
B25: Nominal Değerler | J25: Ölçülen | V25: Kesicinin L1 kontağına ait geçiş direci uygun değildir.
B26: Nominal Direnç | F26: 150 | H26: µΩ | J26: Akım DC | N26: 82 | P26: A | V26: Kesicinin L2 kontağına ait geçiş direci uygundur.
J27: Gerilim DC | N27: =N29*N26/1000 -> 3.28 | P27: mV | V27: Kesicinin L2 kontağına ait geçiş direci uygun değildir.
B28: Çıkış Kademesi | F28: DC 400A | J28: Sonuçlar | V28: Kesicinin L3 kontağına ait geçiş direci uygundur.
B29: Akım | F29: 80,00A | J29: Ölçülen Direnç | N29: ='ANA SAYFA KESİCİ'!O52 -> 40 | P29: µΩ | V29: Kesicinin L3 kontağına ait geçiş direci uygun değildir.
P30: %
B32: Kontak Direnci µΩ | J32: L-3 | P32: =IF(N38<150,1,0) -> 1
B34: Nominal Değerler | J34: Ölçülen
B35: Nominal Direnç | F35: 150 | H35: µΩ | J35: Akım DC | N35: 82 | P35: A
J36: Gerilim DC | N36: =N38*N35/1000 -> 4.428 | P36: mV
B37: Çıkış Kademesi | F37: DC 400A | J37: Sonuçlar
B38: Akım | F38: 80,00A | J38: Ölçülen Direnç | N38: ='ANA SAYFA KESİCİ'!O54 -> 54 | P38: µΩ
P39: %
B45: Sonuç: | D45: =IF(P14<1,V25,V24) -> Kesicinin L1 kontağına ait geçiş direci uygundur.
D46: =IF(P23<1,V27,V26) -> Kesicinin L2 kontağına ait geçiş direci uygundur.
D47: =IF(P32<1,V29,V28) -> Kesicinin L3 kontağına ait geçiş direci uygundur.
B50: UNVAN | E50: : | F50: Elektrik Mühendisi | J50: ONAYLAYAN
B51: TEST TARİHİ | E51: : | F51: ='ANA SAYFA KESİCİ'!F75:J75 -> 45307
B52: ODA SİCİL NO | E52: : | F52: ='ANA SAYFA KESİCİ'!F77:J77 -> 88258
B53: EKİPNET NO | E53: : | F53: ='ANA SAYFA KESİCİ'!F78:J78 -> K202439698

Sheet AÇMA-KAPAMA
G2: ŞALT SAHASI | J2: : | K2: ='ANA SAYFA KESİCİ'!K2 -> BARMAK MAKİNA (ÇAĞLA ELK.)
G3: LOKASYON | J3: : | K3: ='ANA SAYFA KESİCİ'!K5 -> TRAFO 1
B5: KESİCİ AÇMA-KAPAMA SÜRELERİ TEST SONUÇLARI
B7: OTURUM TARİHİ : | J7: ='ANA SAYFA KESİCİ'!F74 -> 45310
T8: 1
B9: Operatör : | D9: ='KESİCİ İZOLASYON'!D10:G10 -> Hilmi GÜL | H9: Cihaz : | J9: METREL MI 3210 | M9: Cihaz S/N : | O9: 16060016 | V9: 3
B11: KESİCİ BİLGİLERİ | T11: 20
B13: Kesici Markası | F13: : | G13: ='ANA SAYFA KESİCİ'!G11 -> ULUSOY | J13: Kesici Tipi | M13: : | N13: ='ANA SAYFA KESİCİ'!O11 -> USFB-36R
B15: Anma Akımı (A) | F15: : | G15: ='ANA SAYFA KESİCİ'!G13 -> 630 | J15: İmal Yılı | M15: : | N15: ='ANA SAYFA KESİCİ'!O13 -> 2016 | W15: Uygun
B17: Gerilim Seviyesi (V) | F17: : | G17: ='ANA SAYFA KESİCİ'!G15 -> 36000 | J17: Seri Numarası | M17: : | N17: ='ANA SAYFA KESİCİ'!O15 -> 2196 | W17: Uygun Değil
B19: Motor Gerilimi | F19: : | G19: ='ANA SAYFA KESİCİ'!G17 -> 220 Vac | J19: Bobin Gerilimi | M19: : | N19: ='ANA SAYFA KESİCİ'!O17 -> 24 Vdc | S19: Max. | T19: Max. | U19: Max.
B21: KESİCİ AÇMA / KAPAMA ZAMANI | S21: 80 | T21: 120 | U21: 5 | W21: 0
B23: Açma | J23: Kapama
S24: 40 | T24: 30 | U24: 20 | V24: 10
B25: A-1 | C25: ='ANA SAYFA KESİCİ'!C61:D61 -> 52.63 | E25: ms | F25: Bobin Gerilimi | H25: ='ANA SAYFA KESİCİ'!O17 -> 24 Vdc | J25: A-1 | K25: ='ANA SAYFA KESİCİ'!J61 -> 69.03 | M25: ms | N25: Bobin Gerilimi | P25: ='ANA SAYFA KESİCİ'!O17 -> 24 Vdc | S25: 40 | T25: 30 | U25: 20 | V25: 10
B26: B-1 | C26: ='ANA SAYFA KESİCİ'!C63:D63 -> 54.14 | E26: ms | J26: B-1 | K26: ='ANA SAYFA KESİCİ'!J63 -> 66.57 | M26: ms
B27: C-1 | C27: ='ANA SAYFA KESİCİ'!C65:D65 -> 50.45 | E27: ms | F27: Bobin Akımı | H27: ='ANA SAYFA KESİCİ'!F65 -> 1.3 | I27: A | J27: C-1 | K27: ='ANA SAYFA KESİCİ'!J65 -> 68.79 | M27: ms | N27: Bobin Akımı | P27: ='ANA SAYFA KESİCİ'!M65 -> 1.3 | Q27: A
B28: Faz Uyuşmazlığı | J28: Faz Uyuşmazlığı | W28: Kesicinin L1 fazına ait izolasyon direnç değeri uygun değildir.
B29: ='ANA SAYFA KESİCİ'!F61 -> 3.69 | E29: ms | F29: =IF(B29>5,W17,W15) -> Uygun | J29: ='ANA SAYFA KESİCİ'!M61 -> 2.46 | M29: ms | N29: =IF(J29>5,W17,W15) -> Uygun
W30: Kesicinin L2 fazına ait izolasyon direnç değeri uygundur.
W31: Kesicinin L2 fazına ait izolasyon direnç değeri uygun değildir.
W32: Kesicinin L3 fazına ait izolasyon direnç değeri uygundur.
W33: Kesicinin L3 fazına ait izolasyon direnç değeri uygun değildir.
W38: Kesicinin Açma süreleri ve bobin akım değerleri uygundur.
B39: TEDAŞ-MLZ/95-008.A İlgili Teknik Şartnamesi Gereği | W39: Kesicinin Açma süreleri uygun değildir.
B40: Açma süresi: 80 milisaniyeden az | W40: Kesicinin Kapama süreleri ve bobin akım değerleri uygundur.
B41: Kapama süresi: 120 milisaniyeden az | W41: Kesicinin Kapama süreleri uygun değildir.
B42: Açma süresi faz uyuşmazlığı: 5 milisaniyeden az | W42: Kesicinin Açma-Kapama Süresi Faz Uyuşmazlığı uygundur.
B43: Kapama süresi faz uyuşmazlığı: 5 milisaniyeden az | W43: Kesicinin Açma-Kapama Süresi Faz Uyuşmazlığı uygun değildir.
B45: Sonuç : | D45: =IF(OR(C25>S21,C26>S21,C27>S21),W39,W38) -> Kesicinin Açma süreleri ve bobin akım değerleri uygundur.
D46: =IF(OR(K25>T21,K26>T21,K27>T21),W41,W40) -> Kesicinin Kapama süreleri ve bobin akım değerleri uygundur.
D47: =IF(OR(B29>U21,J29>U21),W43,W42) -> Kesicinin Açma-Kapama Süresi Faz Uyuşmazlığı uygundur.
B48: UNVAN | E48: : | F48: Elektrik Mühendisi | J48: ONAYLAYAN
B49: TEST TARİHİ | E49: : | F49: ='ANA SAYFA KESİCİ'!F75 -> 45307
B50: ODA SİCİL NO | E50: : | F50: ='ANA SAYFA KESİCİ'!F77 -> 88258
B51: EKİPNET NO | E51: : | F51: ='ANA SAYFA KESİCİ'!F78 -> K202439698

Sheet DİĞER
G2: ŞALT SAHASI | I2: : | J2: ='ANA SAYFA'!K2 -> BARMAK MAKİNA (ÇAĞLA ELK.)
G3: LOKASYON | I3: : | J3: ='ANA SAYFA'!K5 -> TRAFO 1
B7: OTURUM TARİHİ : | J7: ='ANA SAYFA'!F72 -> 45310
T8: 1
B9: Operatör : | D9: Hilmi GÜL | H9: Cihaz : | J9: METREL MI 3210 | M9: Cihaz S/N : | O9: 16060016
T10: 20
B11: Sonuçlar
B13: HÜCRE İZOLASYON
F15: GΩ | H15: Test Gerilimi | K15: Test Akımı | N15: Sonuç
B16: L1 | D16: 20000 | F16: GΩ | H16: 10000 | J16: VDC | K16: =H16/D16 -> 0.5 | M16: nA | N16: =IF(D16>250,1,0) -> 1 | O16: =IF(D16>250,"UYGUN","UYGUN DEĞİL") -> UYGUN
B17: L2 | D17: 20000 | F17: GΩ | H17: 10000 | J17: VDC | K17: =H17/D17 -> 0.5 | M17: nA | N17: =IF(D17>250,1,0) -> 1 | O17: =IF(D17>250,"UYGUN","UYGUN DEĞİL") -> UYGUN | W17: L1 Fazına ait Akım Trafosunun izolasyon direnç değeri uygundur.
B18: L3 | D18: 20000 | F18: GΩ | H18: 10000 | J18: VDC | K18: =H18/D18 -> 0.5 | M18: nA | N18: =IF(D18>250,1,0) -> 1 | O18: =IF(D18>250,"UYGUN","UYGUN DEĞİL") -> UYGUN | W18: L1 Fazına ait Akım Trafosunun izolasyon direnç değeri uygun değildir.
W19: L2 Fazına ait Akım Trafosunun izolasyon direnç değeri uygundur.
B20: ÇIKIŞ HÜCRESİ MESNET İZOLATÖRÜ İZOLASYON | W20: L2 Fazına ait Akım Trafosunun izolasyon direnç değeri uygun değildir.
W21: L3 Fazına ait Akım Trafosunun izolasyon direnç değeri uygundur.
F22: GΩ | H22: Test Gerilimi | K22: Test Akımı | N22: Sonuç | W22: L3 Fazına ait Akım Trafosunun izolasyon direnç değeri uygun değildir.
B23: L4 | D23: 7100 | F23: GΩ | H23: 10000 | J23: VDC | K23: =H23/D23 -> 1.4084507 | M23: nA | N23: =IF(D23>250,1,0) -> 1 | O23: =IF(D23>250,"UYGUN","UYGUN DEĞİL") -> UYGUN
B24: L5 | D24: 20000 | F24: GΩ | H24: 10000 | J24: VDC | K24: =H24/D24 -> 0.5 | M24: nA | N24: =IF(D24>250,1,0) -> 1 | O24: =IF(D24>250,"UYGUN","UYGUN DEĞİL") -> UYGUN
B25: L6 | D25: 20000 | F25: GΩ | H25: 10000 | J25: VDC | K25: =H25/D25 -> 0.5 | M25: nA | N25: =IF(D25>250,1,0) -> 1 | O25: =IF(D25>250,"UYGUN","UYGUN DEĞİL") -> UYGUN
B27: HÜCRE-TRAFO ARASINDAKİ XLPE KABLO İZOLASYON
B29: R min. | F29: GΩ | H29: Test Gerilimi | K29: Test Akımı | N29: Sonuç
B30: L7 | D30: 22.9 | F30: GΩ | H30: 10000 | J30: VDC | K30: =H30/D30 -> 436.68122 | M30: nA | N30: =IF(D30>20,1,0) -> 1 | O30: =IF(D30>20,"UYGUN","UYGUN DEĞİL") -> UYGUN
B31: L8 | D31: 132 | F31: GΩ | H31: 10000 | J31: VDC | K31: =H31/D31 -> 75.757576 | M31: nA | N31: =IF(D31>20,1,0) -> 1 | O31: =IF(D31>20,"UYGUN","UYGUN DEĞİL") -> UYGUN
B32: L9 | D32: 60.8 | F32: GΩ | H32: 10000 | J32: VDC | K32: =H32/D32 -> 164.47368 | M32: nA | N32: =IF(D32>20,1,0) -> 1 | O32: =IF(D32>20,"UYGUN","UYGUN DEĞİL") -> UYGUN
B39: Sonuç : | D39: Ölçülen izolasyon direnci değerleri uygun bulunmuştur.
B44: UNVAN | E44: : | F44: Elektrik Mühendisi | J44: ONAYLAYAN
B45: TEST TARİHİ | E45: : | F45: ='ANA SAYFA'!F73:J73 -> 45307
B46: ODA SİCİL NO | E46: : | F46: ='ANA SAYFA'!$F$75 -> 88258
B47: EKİPNET NO | E47: : | F47: ='ANA SAYFA'!$F$76 -> K202439698

Sheet AKIM TRAFOLARI
G2: ŞALT SAHASI | I2: : | J2: ='ANA SAYFA'!K2 -> BARMAK MAKİNA (ÇAĞLA ELK.)
G3: LOKASYON | I3: : | J3: ='ANA SAYFA'!K5 -> TRAFO 1
B7: OTURUM TARİHİ : | J7: ='ANA SAYFA'!F72 -> 45310
T8: 1
B9: Operatör : | D9: ='İZOLASYON '!D11:G11 -> Hilmi GÜL | H9: Cihaz : | J9: METREL MI 3210 | M9: Cihaz S/N : | O9: 16060016
T10: 20
B11: Sonuçlar
B13: AKIM TRAFOLARI
B15: R min. | D15: 250 | F15: GΩ | H15: Test Gerilimi | K15: Test Akımı | N15: Sonuç
B16: L1 | D16: 1500 | F16: GΩ | H16: 10000 | J16: VDC | K16: =H16/D16 -> 6.6666667 | M16: nA | N16: =IF(D16>250,1,0) -> 1 | O16: =IF(D16>250,"UYGUN","UYGUN DEĞİL") -> UYGUN
B17: L2 | D17: 10000 | F17: GΩ | H17: 10000 | J17: VDC | K17: =H17/D17 -> 1 | M17: nA | N17: =IF(D17>250,1,0) -> 1 | O17: =IF(D17>250,"UYGUN","UYGUN DEĞİL") -> UYGUN | W17: L1 Fazına ait Akım Trafosunun izolasyon direnç değeri uygundur.
B18: L3 | D18: 10000 | F18: GΩ | H18: 10000 | J18: VDC | K18: =H18/D18 -> 1 | M18: nA | N18: =IF(D18>250,1,0) -> 1 | O18: =IF(D18>250,"UYGUN","UYGUN DEĞİL") -> UYGUN | W18: L1 Fazına ait Akım Trafosunun izolasyon direnç değeri uygun değildir.
W19: L2 Fazına ait Akım Trafosunun izolasyon direnç değeri uygundur.
W20: L2 Fazına ait Akım Trafosunun izolasyon direnç değeri uygun değildir.
W21: L3 Fazına ait Akım Trafosunun izolasyon direnç değeri uygundur.
W22: L3 Fazına ait Akım Trafosunun izolasyon direnç değeri uygun değildir.
B39: Sonuç : | D39: =IF(N16<1,W18,W17) -> L1 Fazına ait Akım Trafosunun izolasyon direnç değeri uygundur.
D40: =IF(N17<1,W20,W19) -> L2 Fazına ait Akım Trafosunun izolasyon direnç değeri uygundur.
D41: =IF(N18<1,W22,W21) -> L3 Fazına ait Akım Trafosunun izolasyon direnç değeri uygundur.
B44: UNVAN | E44: : | F44: Elektrik Mühendisi | J44: ONAYLAYAN
B45: TEST TARİHİ | E45: : | F45: ='ANA SAYFA KESİCİ'!F75 -> 45307
B46: ODA SİCİL NO | E46: : | F46: ='ANA SAYFA'!$F$75 -> 88258
B47: EKİPNET NO | E47: : | F47: ='ANA SAYFA'!$F$76 -> K202439698
