Workbook

Sheet KAPAK SAYFASI
E1: B.T.S. ELEKTRİK TRAFO BAKIM
E3: MÜH. İNŞ. MAK. LAB. SAN. VE TİC. LTD. ŞTİ.
A7: TRAFO TEST RAPORU
A9: Müşterinin Adı | D9: OK AMBALAJ
A10: Trafo Etiketi | D10: TR-1
A11: ADRESİ | D11: KAYAPA/BURSA
A12: RAPOR TARİHİ | D12: 05.08.2026
A13: REFERANS | D13: International Electrical Testing Association
A14: RAPOR KONUSU | D14: 05.08.2026 | E14: Tarihinde yapılan Trafo test raporu.
B16: TRAFO BAKIMI VE KONTROLLERİ
A18: - | B18: Trafonun D.C. İzolasyon test değerleri uygun bulunmuştur.
A20: - | B20: Trafoda yapılan çevirme oranı (TTR) test sonuçları uygun bulmuştur, buna bağlı olarak kademe değiştirici ile sargılar arasındaki bağlantılarda herhangi bir sorun olmadığı gözlemlenmiştir.
A23: - | B23: Trafoda yapılan D.C. Sargı direnci test sonuçlarının uygun olduğu tespit edilmiştir, sargılar arasındaki direnç farklılıkları max. değerin (%5) altındadır. Bu sonuçlara göre; sargı bağlantı uçları, kademe değiştirici kontakları, tij bağlantılarında gevşeklik olmadığı gözlemlenmiştir.
A27: SONUÇ
A29: Mevcut şartlar korunması halinde trafonun kullanımı UYGUNDUR.
G52: ONAYLAYAN
A53: Test Tarihi | C53: : | D53: =D14
A54: Rapor Tarihi | C54: : | D54: =D12
A55: Unvan | C55: : | D55: Elektrik Mühendisi
A58: Bu belge 5070 sayılı elektronik imza kanununa göre güvenli elektronik imza ile imzalanmıştır.
A60: Üçevler Mahallesi Ak-Va Sanayi Sitesi 80. Sokak No:2/P Nilüfer-BURSA
A61: Telefon : 444 0 287 - 0224 441 94 33 Mail: www.btselektrik.com.tr
A62: Gsm : 0532 206 58 32 - 0538 035 35 94

Sheet ANA SAYFA
H2: ŞALT SAHASI | K2: ='KAPAK SAYFASI'!D9
H5: TRAFO ETİKETİ | K5: ='KAPAK SAYFASI'!D10
B6: Üçevler Mh. AK-VA Sanayi Sitesi 80. Sk. No:2/P Nilüfer / BURSA / TÜRKİYE
B9: TRAFO BİLGİLERİ
B11: Trafo Markası | F11: : | G11: ASTOR | K11: Kademe Bilgisi | N11: : | O11: 6 | P11: / | Q11: 4 | R11: / | S11: 5
B13: Trafo Gücü (kVA) | F13: : | G13: 1000 | K13: İmal Yılı | N13: : | O13: 2017
B15: Gerilim Seviyesi (V) | F15: : | G15: 34500 | K15: Seri Numarası | N15: : | O15: 27-07840
B17: Yağ Markası | F17: : | G17: NYNAS | K17: Yağ Ağırlığı (kg) | N17: : | O17: 510
B19: Bağlantı Grubu | F19: : | G19: Dyn11 | K19: Kısa Devre Emp.% | N19: : | O19: 5.61
B21: Kazan Tipi | F21: : | G21: Hermetik | I21: ü | K21: Genleşme Tanklı | P21: Kuru Tip
B24: KONTROLLER
I25: Evet | J25: Hayır | R25: Evet | S25: Hayır
B27: Trafo Sıcaklık Kontrolü | F27: : | G27: 30 | H27: °C | I27: ü | K27: Trafo Temizliği | O27: : | P27: -
B29: Yağ Seviyesi Kontrolü | F29: : | G29: UYGUN | I29: ü | K29: Bina Temizliği | O29: : | P29: -
B31: DC Redresör Kontrolü | F31: : | G31: 24 VDC | I31: ü | K31: Kablo Sıkılık Kontrolü | O31: : | P31: UYGUN | R31: ü
B33: Basınç Açma | F33: : | G33: UYGUN | I33: ü | K33: Yağ Kaçağı Kontrolü | O33: : | P33: UYGUN | R33: ü
B35: Gaz Açma | F35: : | G35: UYGUN | I35: ü | K35: Kademe Conta Kontrolü | O35: : | P35: UYGUN | R35: ü
B37: Termik Alarm | F37: : | G37: UYGUN | I37: ü | K37: O.G Conta Kontrolü | O37: : | P37: UYGUN | R37: ü
B39: Termik Açma | F39: : | G39: UYGUN | I39: ü | K39: Kapak Conta Kontrolü | O39: : | P39: UYGUN | R39: ü
B41: İzolatör Kontrolü | F41: : | G41: UYGUN | I41: ü | K41: A.G Conta Kontrolü | O41: : | P41: UYGUN | R41: ü
V44: ÇEVİRME ORANI ( TTR ) | AF44: ÇEVİRME ORANI ( TTR )
V46: AB / an | Y46: BC / bn | AB46: CA / cn | AF46: AB / an | AI46: BC / bn | AL46: CA / cn
V48: =V57/1.0525889 | Y48: =Y57/1.0525889 | AB48: =AB57/1.0525889 | AF48: =AF57/1.045489 | AI48: =AI57/1.045489 | AL48: =AL57/1.045489
V50: Kademe Bilgisi | Y50: : | Z50: 28500 / 400 | AF50: Kademe Bilgisi | AI50: : | AJ50: 33000 / 400
B53: 2 | C53: A | D53: SARGI DİRENÇLERİ ( Ω ) | I53: 50 | J53: A | K53: ÇEVİRME ORANI ( TTR ) | V53: ÇEVİRME ORANI ( TTR ) | AF53: ÇEVİRME ORANI ( TTR )
B55: RAB : | C55: 9.35 | F55: Ran : | G55: 0.0004878 | K55: AB / an | N55: BC / bn | Q55: CA / cn | V55: AB / an | Y55: BC / bn | AB55: CA / cn | AF55: AB / an | AI55: BC / bn | AL55: CA / cn
B57: RAC : | C57: 9.3783 | F57: Rbn : | G57: 0.0004699 | K57: 149.574 | N57: 149.572 | Q57: 149.594 | V57: =V66/1.050038 | Y57: =Y66/1.050038 | AB57: =AB66/1.050038 | AF57: =K57 | AI57: =N57 | AL57: =Q57
B59: RBC : | C59: 9.3655 | F59: Rcn : | G59: 0.000472 | K59: Kademe Bilgisi | N59: : | O59: 34500 | Q59: / | R59: 230.9494 | V59: Kademe Bilgisi | Y59: : | Z59: 30000 / 400 | AF59: Kademe Bilgisi | AI59: : | AJ59: 34500 / 400
B62: İZOLASYON (YALITIM) DİRENÇLERİ ( Ω ) | V62: ÇEVİRME ORANI ( TTR ) | AF62: ÇEVİRME ORANI ( TTR )
F64: 30 sn | I64: 45 sn | L64: 60 sn | O64: Birim | Q64: DAR | V64: AB / an | Y64: BC / bn | AB64: CA / cn | AF64: AB / an | AI64: BC / bn | AL64: CA / cn
B66: Y.G - TANK | F66: 54.6 | I66: 60.3 | L66: 64.7 | O66: G | P66: Ω | Q66: =L66/F66 | V66: =AF48/1.04758 | Y66: =AI48/1.04758 | AB66: =AL48/1.04758 | AF66: =AF57*1.043443 | AI66: =AI57*1.043443 | AL66: =AL57*1.043443
B68: A.G - TANK | F68: 37.7 | I68: 44.4 | L68: 48.8 | O68: G | P68: Ω | Q68: =L68/F68 | V68: Kademe Bilgisi | Y68: : | Z68: 31500 / 400 | AF68: Kademe Bilgisi | AI68: : | AJ68: 36000 / 400
B70: Y.G - A.G | F70: 57.8 | I70: 63.3 | L70: 68.8 | O70: G | P70: Ω | Q70: =L70/F70
B73: NOTLAR : Test sonuçlarının değerlendirilmesi kapak sayfasında yapılmıştır.
K78: ONAYLAYAN
B79: Test Tarihi | E79: : | F79: ='KAPAK SAYFASI'!D53
B80: Rapor Tarihi | E80: : | F80: ='KAPAK SAYFASI'!D54
B81: Unvan | E81: : | F81: Elektrik Mühendisi

Sheet OG SARGI MEVCUT KADEME
G2: ŞALT SAHASI | I2: : | J2: ='ANA SAYFA'!K2
G3: LOKASYON | I3: : | J3: ='ANA SAYFA'!K5
B5: PRİMER SARGI DİRENCİ TEST SONUÇLARI
B7: Üretici : | D7: ='ANA SAYFA'!G11 | G7: Model : | I7: ='ANA SAYFA'!O13 | L7: Seri Numarası : | O7: ='ANA SAYFA'!O15
B9: OTURUM TARİHİ : | J9: ='KAPAK SAYFASI'!D54
B11: Operatör : | H11: Cihaz : | M11: Cihaz S/N :
B13: Sonuçlar | V13: ='ANA SAYFA'!G13
V14: =V13/59.75575286
B15: PT Sargı Otomatik | J15: HV Mevcut Kademe Tap | O15: ='ANA SAYFA'!S11
B17: Nominal Direnç
B18: Vektör Grubu | F18: ='ANA SAYFA'!G19
B19: 3-faz
B20: Nominal Değerler | F20: =(K24+K25+K26)/3 | H20: Ω
B21: Çıkış Kademesi | F21: DC 6A | T21: A | U21: =MAX(T32:T33)
T22: B | U22: =MAX(U32:U33)
C23: I Testi [A] | E23: I DC [A] | G23: V DC [V] | I23: Zaman [S] | K23: R.ölç[Ω] | M23: R. Nom | O23: Hata[%] | T23: C | U23: =MAX(V32:V33)
B24: A | C24: ='ANA SAYFA'!B53 | E24: =C24 | G24: =(E24*K24)*0.98 | K24: ='ANA SAYFA'!C55 | M24: =F20 | O24: =U21 | Q24: =IF(O24>0.05,1,0) | T24: SINIR DEĞER | U24: 0.05
B25: B | C25: ='ANA SAYFA'!B53 | E25: =C25 | G25: =(E25*K25)*0.98 | K25: ='ANA SAYFA'!C59 | M25: =M24 | O25: =U22 | Q25: =IF(O25>0.05,1,0)
B26: C | C26: ='ANA SAYFA'!B53 | E26: =C26 | G26: =(E26*K26)*0.98 | K26: ='ANA SAYFA'!C57 | M26: =M24 | O26: =U23 | Q26: =IF(O26>0.05,1,0)
T32: =SQRT((K24-K25)^2)/K25 | U32: =SQRT((K24-K25)^2)/K24 | V32: =SQRT((K26-K24)^2)/K24
T33: =SQRT((K26-K24)^2)/K26 | U33: =SQRT((K25-K26)^2)/K26 | V33: =SQRT((K26-K25)^2)/K25
B39: Sonuç : | D39: Yapılan ölçümlerde OG (Orta gerilim) sargısına ait direnç değerleri uygundur.
J45: ONAYLAYAN
B46: UNVAN | E46: : | F46: Elektrik Mühendisi
B47: TEST TARİHİ | E47: : | F47: ='KAPAK SAYFASI'!D53

Sheet AG SARGI
G2: ŞALT SAHASI | I2: : | J2: ='ANA SAYFA'!K2
G3: LOKASYON | I3: : | J3: ='ANA SAYFA'!K5
B5: SEKONDER SARGI DİRENCİ TEST SONUÇLARI
B7: Üretici : | D7: ='OG SARGI MEVCUT KADEME'!D7:F7 | G7: Model : | I7: ='OG SARGI MEVCUT KADEME'!I7:K7 | L7: Seri Numarası : | O7: ='OG SARGI MEVCUT KADEME'!O7:Q7
B9: OTURUM TARİHİ : | J9: ='KAPAK SAYFASI'!D54
B11: Operatör : | D11: ='OG SARGI MEVCUT KADEME'!D11 | H11: Cihaz : | M11: Cihaz S/N :
B13: Sonuçlar | V13: ='ANA SAYFA'!G13
V14: =V13/0.69282
B15: PT Sargı Otomatik | J15: LV Kademe Tap | N15: 1
B17: Nominal Direnç
B18: Vektör Grubu | F18: ='ANA SAYFA'!G19
B19: 3-faz
B20: Nominal Değerler | F20: =(K24+K25+K26)/3 | H20: Ω
B21: Çıkış Kademesi | F21: DC 400A | T21: A | U21: =MIN(T32:T33)
T22: B | U22: =MIN(U32:U33)
C23: I Testi [A] | E23: I DC [A] | G23: V DC [V] | I23: Zaman [S] | K23: R.ölç[Ω] | M23: R. Nom | O23: Hata[%] | T23: C | U23: =MIN(V32:V33)
B24: A | C24: ='ANA SAYFA'!I53 | E24: =C24 | G24: =(K24*E24)*0.98 | K24: ='ANA SAYFA'!G55 | M24: =F20 | O24: =MIN(T32:T33) | Q24: =IF(O24>0.05,1,0) | T24: SINIR DEĞER | U24: 0.05
B25: B | C25: ='ANA SAYFA'!I53 | E25: =C25 | G25: =(K25*E25)*0.98 | K25: ='ANA SAYFA'!G57 | M25: =M24 | O25: =MIN(U32:U33) | Q25: =IF(O25>0.05,1,0)
B26: C | C26: ='ANA SAYFA'!I53 | E26: =C26 | G26: =(K26*E26)*0.98 | K26: ='ANA SAYFA'!G59 | M26: =M24 | O26: =MIN(V32:V33) | Q26: =IF(O26>0.05,1,0)
T32: =SQRT((K24-K25)^2)/K25 | U32: =SQRT((K24-K25)^2)/K24 | V32: =SQRT((K26-K24)^2)/K24
T33: =SQRT((K26-K24)^2)/K26 | U33: =SQRT((K25-K26)^2)/K26 | V33: =SQRT((K26-K25)^2)/K25
B39: Sonuç : | D39: Yapılan ölçümlerde AG (Alçak gerilim) sargısına ait direnç değerleri uygundur.
J45: ONAYLAYAN
B46: UNVAN | E46: : | F46: Elektrik Mühendisi
B47: TEST TARİHİ | E47: : | F47: ='KAPAK SAYFASI'!D53

Sheet İZOLASYON 
G2: ŞALT SAHASI | I2: : | J2: ='ANA SAYFA'!K2
G3: LOKASYON | I3: : | J3: ='ANA SAYFA'!K5
B5: D.C. İZOLASYON DİRENCİ TEST SONUÇLARI
B7: Üretici : | D7: ='OG SARGI MEVCUT KADEME'!D7:F7 | G7: Model : | I7: ='OG SARGI MEVCUT KADEME'!I7:K7 | L7: Seri Numarası : | O7: ='OG SARGI MEVCUT KADEME'!O7:Q7
Y8: OG-TANK | Z8: AG-TANK | AA8: OG-AG
B9: OTURUM TARİHİ : | J9: ='KAPAK SAYFASI'!D54 | X9: LİMİT | Y9: =V15 | Z9: =V20 | AA9: =V25
X10: 30 | Y10: =H18 | Z10: =H23 | AA10: =H28
B11: Operatör : | D11: ='OG SARGI MEVCUT KADEME'!D11 | H11: Cihaz : | M11: Cihaz S/N : | X11: 45 | Y11: =J18 | Z11: =J23 | AA11: =J28
X12: 60 | Y12: =L18 | Z12: =L23 | AA12: =L28
B13: Sonuçlar | N13: Sıcaklık | P13: ='ANA SAYFA'!G27 | Q13: °C
B15: O.G. TANK İZOLASYON | U15: OG-TANK | V15: 1.1
B16: ÖLÇÜLEN DEĞERLER | H16: HESAPLANAN DEĞERLER 20°C | V16: UYGUN
B17: 30 sn | F17: 60 sn | H17: 30 sn | J17: 45 sn | L17: 60 sn | N17: DAR | P17: Sonuç
B18: ='ANA SAYFA'!F66 | C18: GΩ | D18: ='ANA SAYFA'!I66 | E18: GΩ | F18: ='ANA SAYFA'!L66 | G18: GΩ | H18: =B18*V38 | I18: GΩ | J18: =D18*V38 | K18: GΩ | L18: =F18*V38 | M18: GΩ | N18: =L18/H18 | P18: =IF(L18<V15,V18,V16) | V18: DÜŞÜK
B20: A.G. TANK İZOLASYON | U20: AG-TANK | V20: 0.2
B21: ÖLÇÜLEN DEĞERLER | H21: HESAPLANAN DEĞERLER 20°C | V21: UYGUN
B22: 30 sn | D22: 45 sn | F22: 60 sn | H22: 30 sn | J22: 45 sn | L22: 60 sn | N22: DAR | P22: Sonuç
B23: ='ANA SAYFA'!F68 | C23: GΩ | D23: ='ANA SAYFA'!I68 | E23: GΩ | F23: ='ANA SAYFA'!L68 | G23: GΩ | H23: =B23*V38 | I23: GΩ | J23: =D23*V38 | K23: GΩ | L23: =F23*V38 | M23: GΩ | N23: =L23/H23 | P23: =IF(L23<V20,V23,V21) | V23: DÜŞÜK
Y24: Yapılan ölçümlerde trafonun izolasyon direnç değerleri uygun bulunmuştur.
B25: O.G. A.G. İZOLASYON | U25: OG-AG | V25: 1.1
B26: ÖLÇÜLEN DEĞERLER | H26: HESAPLANAN DEĞERLER 20°C | V26: UYGUN
B27: 30 sn | D27: 45 sn | F27: 60 sn | H27: 30 sn | J27: 45 sn | L27: 60 sn | N27: DAR | P27: Sonuç
B28: ='ANA SAYFA'!F70 | C28: GΩ | D28: ='ANA SAYFA'!I70 | E28: GΩ | F28: ='ANA SAYFA'!L70 | G28: GΩ | H28: =B28*V38 | I28: GΩ | J28: =D28*V38 | K28: GΩ | L28: =F28*V38 | M28: GΩ | N28: =L28/H28 | P28: =IF(L28<V25,V28,V26) | V28: DÜŞÜK
Y32: Yapılan ölçümlerde trafonun izolasyon direnç değerleri düşük bulunmuştur.
U38: ÇARPAN | V38: =IF(P13>40,X43,X42)
B41: Sonuç : | D41: =IF(L18<V15,Y32,Y24)
U42: Test Sıcaklığı | V42: İcra Katsayısı | X42: =IF(P13=0,V43, IF(P13=5,V44, IF(P13=10,V45, IF(P13=15,V46, IF(P13=20,V47, IF(P13=25,V48, IF(P13=30,V49, IF(P13=35,V50, IF(P13=40,V51, )))))))))
U43: 0 | V43: 0.25 | X43: =IF(P13=45,V52, IF(P13=50,V53, IF(P13=55,V54, IF(P13=60,V55, IF(P13=65,V56, IF(P13=70,V57, IF(P13=75,V58, )))))))
U44: 5 | V44: 0.36
U45: 10 | V45: 0.5
B46: Not: Polarizasyon endekslerine göre değerlendirme; hem fabrika deney sonuçları hem de daha önceki değerlerle yeni bulunan değerlerin kıyaslanması ile yapılmalıdır. Ölçülen değerler daha önceki değerlere yakın veya büyük ise normal kabul edilir. Ancak ölçüm ilk kez yapılıyorsa; PE=1,0-1,1 Zayıf / PE=1,1-1,25 Şüpheli / PE=1,25-1,40 Orta / PE=1,40-1,60 İyi / PE>1,60 Çok İyi değerlendirmesi yapılır. İzolasyon ölçümlerinde DAR endeksine bağlı kalınmaksızın, sınır değerlerin altında çıkan değerler kötü izolasyon olarak ifade edilmektedir. | U46: 15 | V46: 0.74
U47: 20 | V47: 1
U48: 25 | V48: 1.4
U49: 30 | V49: 1.98
J50: ONAYLAYAN | U50: 35 | V50: 2.8
B51: UNVAN | E51: : | F51: Elektrik Mühendisi | U51: 40 | V51: 3.95
B52: TEST TARİHİ | E52: : | F52: ='ANA SAYFA'!F79 | U52: 45 | V52: 5.6
U53: 50 | V53: 7.85
U54: 55 | V54: 11.2
U55: 60 | V55: 15.85
...

Sheet Ç.O 34500
G2: ŞALT SAHASI | I2: : | J2: ='ANA SAYFA'!K2
G3: LOKASYON | I3: : | J3: ='ANA SAYFA'!K5
B5: ÇEVİRME ORANI TEST SONUÇLARI
B7: Üretici : | D7: ='OG SARGI MEVCUT KADEME'!D7:F7 | G7: Model : | I7: ='OG SARGI MEVCUT KADEME'!I7:K7 | L7: Seri Numarası : | O7: ='OG SARGI MEVCUT KADEME'!O7:Q7
B9: OTURUM TARİHİ : | J9: ='KAPAK SAYFASI'!D54
B11: Operatör : | D11: ='OG SARGI MEVCUT KADEME'!D11 | H11: Cihaz : | M11: Cihaz S/N :
B13: Sonuçlar
B15: PT Her Bir Kademe Oran | J15: Tap | K15: ='ANA SAYFA'!S11 | N15: Kademe #1 | T15: ='ANA SAYFA'!R59 | U15: A | V15: =O26
U16: B | V16: =O27
J17: Test Değerleri | U17: C | V17: =O28
F18: ='ANA SAYFA'!O59 | H18: V | J18: Gerilim | N18: 500,0 V | U18: SINIR DEĞER | V18: 0.5
F19: 231 | H19: V | J19: Frekans | N19: 50, Hz | W19: 0.5 | X19: -0.5
F20: =F18/T15
B22: Sonuçlar
C25: Vn HV [V] | E25: V HV[V] | G25: I HV[A] | I25: V LV[V] | K25: ᶲV LV [°] | M25: Ratio | O25: Err % | V25: ( A ) Fazına ait çevirme oranı hata yüzdesi uygundur.
B26: A | C26: 500 | E26: 500 | G26: =I26/M26 | I26: 1.5 | K26: 26,0m | M26: ='ANA SAYFA'!AF57 | O26: =(M26-F20)/F20*100
B27: B | C27: 500 | E27: 500 | G27: =I27/M27 | I27: 1.5 | K27: 26,0m | M27: ='ANA SAYFA'!AI57 | O27: =(M27-F20)/F20*100 | V27: ( A ) Fazına ait çevirme oranı hata yüzdesi hatalı olduğu tespit edilmiştir.
B28: C | C28: 500 | E28: 500 | G28: =I28/M28 | I28: 1.5 | K28: 26,0m | M28: ='ANA SAYFA'!AL57 | O28: =(M28-F20)/F20*100
V29: ( B ) Fazına ait çevirme oranı hata yüzdesi uygundur.
V31: ( B ) Fazına ait çevirme oranı hata yüzdesi hatalı olduğu tespit edilmiştir.
V34: ( C ) Fazına ait çevirme oranı hata yüzdesi uygundur.
V36: ( C ) Fazına ait çevirme oranı hata yüzdesi hatalı olduğu tespit edilmiştir.
B44: Sonuç : | D44: =IF(OR(O26>W19,O26<X19),V27,V25)
D46: =IF(OR(O27>W19,O27<X19),V31,V29)
D48: =IF(OR(O28>W19,O28<X19),V36,V34)
J50: ONAYLAYAN
B51: UNVAN | E51: : | F51: Elektrik Mühendisi
B52: TEST TARİHİ | E52: : | F52: ='ANA SAYFA'!F79

Sheet TOPRAKLAMALAR
G2: ŞALT SAHASI | I2: : | J2: ='ANA SAYFA'!K2
G3: LOKASYON | I3: : | J3: ='ANA SAYFA'!K5
B5: Dosya Adı : | E5: TOPRAKLAMA ÖLÇÜM SONUÇLARI
B7: OTURUM TARİHİ : | J7: ='ANA SAYFA'!F78
B9: Operatör : | D9: ='OG SARGI MEVCUT KADEME'!D11 | H9: Cihaz : | M9: Cihaz S/N :
B11: Sonuçlar
B13: İŞLETME (NÖTR) TOPRAK DİRENCİ
N15: Sonuç
B16: Max. Ω | D16: 4 | F16: Ω | H16: Ölçülen | J16: Ω | K16: ='ANA SAYFA'!H48 | M16: Ω | N16: =IF(K16<D16,W18,Y18)
W18: UYGUN | Y18: UYGUN DEĞİL
B23: KORUMA TOPRAK DİRENCİ
N25: Sonuç | V25: İşletme (NÖTR) topraklaması direnç değeri normaldir.
B26: Trafo | D26: Max. Ω | F26: 4 | G26: Ω | H26: Ölçülen | J26: Ω | K26: ='ANA SAYFA'!H46 | M26: Ω | N26: =IF(K26<F26,W18,Y18) | V26: İşletme (NÖTR) topraklaması direnç değeri yüksek bulunmuştur.
B27: Hücre | D27: Max. Ω | F27: 4 | G27: Ω | H27: Ölçülen | J27: Ω | K27: ='ANA SAYFA'!H50 | M27: Ω | N27: =IF(K27<F27,W18,Y18) | V27: Trafo topraklaması direnç değeri normaldir.
B28: Kapılar | D28: Max. Ω | F28: 4 | G28: Ω | H28: Ölçülen | J28: Ω | K28: ='ANA SAYFA'!Q48 | M28: Ω | N28: =IF(K28<F28,W18,Y18) | V28: Trafo topraklaması direnç değeri yüksek bulunmuştur.
B29: AG. Pano | D29: Max. Ω | F29: 4 | G29: Ω | H29: Ölçülen | J29: Ω | K29: ='ANA SAYFA'!Q46 | M29: Ω | N29: =IF(K29<F29,W18,Y18)
V30: Hücre topraklaması direnç değeri normaldir.
V31: Hücre topraklaması direnç değeri yüksek bulunmuştur.
V33: A.G. Pano topraklaması direnç değeri normaldir.
V34: A.G. Pano topraklaması direnç değeri yüksek bulunmuştur.
V36: Kapı topraklaması direnç değeri normaldir.
V37: Kapı topraklaması direnç değeri yüksek bulunmuştur.
V38: Direk topraklaması direnç değeri normaldir.
V39: Direk topraklaması direnç değeri yüksek bulunmuştur.
B41: Sonuç : | D41: =IF(K16<D16,V25,V26)
D42: =IF(K26<F26,V27,V28)
D43: =IF(K27<F27,V30,V31)
D44: =IF(K28<F28,V36,V37)
D45: =IF(K29<F29,V33,V34)
B47: UNVAN | E47: : | F47: Elektrik Mühendisi | J47: ONAYLAYAN
B48: TEST TARİHİ | E48: : | F48: ='ANA SAYFA'!F79
B49: ODA SİCİL NO | E49: : | F49: ='ANA SAYFA'!F81:J81
B50: EKİPNET NO | E50: : | F50: ='ANA SAYFA'!F82:J82

Sheet ANA SAYFA KESİCİ
H2: ŞALT SAHASI | K2: ='ANA SAYFA'!K2
H5: LOKASYON | K5: ='ANA SAYFA'!K5
B9: KESİCİ BİLGİLERİ
B11: Kesici Markası | F11: : | K11: Kesici Tipi | N11: :
B13: Anma Akımı (A) | F13: : | K13: İmal Yılı | N13: :
B15: Gerilim Seviyesi (V) | F15: : | K15: Seri Numarası | N15: :
B17: Motor Gerilimi | F17: : | K17: Bobin Gerilimi | N17: :
B21: KONTROLLER
I22: Evet | J22: Hayır | R22: Evet | S22: Hayır
B24: Kesici Görsel Kontrolü | F24: : | K24: Kesici Temizliği | O24: :
B26: DC Redresör Kontrolü | F26: : | K26: Hücre Temizliği | O26: :
B28: İndikatör Kontrolü | F28: : | K28: Bara Kontrolü | O28: :
B30: Mekanik Konrolü | F30: : | K30: Isıtıcı Kontrolü | O30: :
B32: Kablo Başlığı Kontrolü | F32: : | K32: A.A Röle Kontrolü | O32: :
B46: KESİCİ İZOLASYON DİRENCİ (GΩ) | K46: KESİCİ KONTAK DİRENCİ (Ω)
C48: TEST VOLTAJI | G48: SONUÇ | K48: TEST AKIMI | O48: SONUÇ
B50: L-1 | F50: kV | I50: GΩ | J50: =IF(G50>50,1,0) | R50: µΩ | S50: =IF(O50<150,1,0)
B52: L-2 | F52: kV | I52: GΩ | J52: =IF(G52>50,1,0) | R52: µΩ | S52: =IF(O52<150,1,0)
B54: L-3 | F54: kV | I54: GΩ | J54: =IF(G54>50,1,0) | R54: µΩ | S54: =IF(O54<150,1,0)
B57: KESİCİ ACMA / KAPAMA ZAMANI
C59: KESİCİ AÇMA | F59: EŞ ZAMAN FARKI | J59: KESİCİ KAPAMA | M59: EŞ ZAMAN FARKI | Q59: SONUÇ
B61: L-1 | E61: ms | F61: =MAX(V80:V85) | H61: ms | L61: ms | M61: =MAX(X80:X85) | O61: ms
B63: L-2 | E63: ms | F63: BOBİN AKIMI | L63: ms | M63: BOBİN AKIMI
B65: L-3 | E65: ms | H65: A | L65: ms | O65: A
B68: Sonuç : | D68: Yapılan ölçümlerde kesicinin test değerleri uygun bulundu. Kesicinin ve hücrenin
B69: temizliği yapıldı.
B74: Rapor Tarihi | E74: : | F74: ='ANA SAYFA'!F78 | K74: ONAYLAYAN
B75: Test Tarihi | E75: : | F75: ='ANA SAYFA'!F79
B76: Unvan | E76: : | F76: Elektrik Mühendisi
B77: Sicil No | E77: :
B78: Ekipnet No | E78: :
V80: =C61-C63 | X80: =J61-J63
V81: =C61-C65 | X81: =J61-J65
V82: =C63-C65 | X82: =J63-J65
V83: =C63-C61 | X83: =J63-J61
V84: =C65-C61 | X84: =J65-J61
V85: =C65-C63 | X85: =J65-J63

Sheet KESİCİ İZOLASYON
G2: ŞALT SAHASI | J2: : | K2: ='ANA SAYFA KESİCİ'!K2
G3: LOKASYON | J3: : | K3: ='ANA SAYFA KESİCİ'!K5
B5: KESİCİ İZOLASYON DİRENCİ TEST SONUÇLARI
B8: OTURUM TARİHİ : | J8: ='ANA SAYFA KESİCİ'!F74
B10: Operatör : | H10: Cihaz : | M10: Cihaz S/N : | U10: r1 | V10: 250 | W10: 200 | X10: 150 | Y10: 100 | Z10: 50
B12: Sonuçlar
B14: KESİCİ İZOLASYON
B16: R min. | D16: 50 | F16: GΩ | H16: Test Gerilimi | K16: Test Akımı | N16: Sonuç
B17: L-1 | D17: ='ANA SAYFA KESİCİ'!G50 | F17: GΩ | H17: 10000 | J17: VDC | K17: =H17/D17 | M17: nA | N17: =IF(D17>D16,1,0) | O17: =IF(D17>D16,"UYGUN","UYGUN DEĞİL")
B18: L-2 | D18: ='ANA SAYFA KESİCİ'!G52 | F18: GΩ | H18: 10000 | J18: VDC | K18: =H18/D18 | M18: nA | N18: =IF(D18>D16,1,0) | O18: =IF(D18>D16,"UYGUN","UYGUN DEĞİL")
B19: L-3 | D19: ='ANA SAYFA KESİCİ'!G54 | F19: GΩ | H19: 10000 | J19: VDC | K19: =H19/D19 | M19: nA | N19: =IF(D19>D16,1,0) | O19: =IF(D19>D16,"UYGUN","UYGUN DEĞİL")
X20: =N17+N18+N19
X24: =(N32+N33+N34+N35+N36)/5
X27: Yapılan ölçümlerde kesicinin İzolasyon değerleri uygundur.
X28: Yapılan ölçümlerde kesicinin İzolasyon değerleri uygun değildir.
B47: Sonuç : | D47: Yapılan ölçümlerde kesicinin İzolasyon değerleri uygundur.
B50: UNVAN | E50: : | F50: Elektrik Mühendisi | J50: ONAYLAYAN
B51: TEST TARİHİ | E51: : | F51: ='ANA SAYFA KESİCİ'!F75:J75
B52: ODA SİCİL NO | E52: : | F52: ='ANA SAYFA KESİCİ'!F77:J77
B53: EKİPNET NO | E53: : | F53: ='ANA SAYFA KESİCİ'!F78:J78

Sheet KESİCİ KONTAK
G2: ŞALT SAHASI | J2: : | K2: ='ANA SAYFA KESİCİ'!K2
G3: LOKASYON | J3: : | K3: ='ANA SAYFA KESİCİ'!K5
B5: KESİCİ KONTAK DİRENCİ TEST SONUÇLARI
B8: OTURUM TARİHİ : | J8: ='ANA SAYFA KESİCİ'!F74
B10: Operatör : | H10: Cihaz : | M10: Cihaz S/N :
B12: Sonuçlar
B14: Kontak Direnci µΩ | J14: L-1 | P14: =IF(N20<150,1,0)
B16: Nominal Değerler | J16: Ölçülen
B17: Maksimum Direnç | F17: 150 | H17: µΩ | J17: Akım DC | N17: 82 | P17: A
J18: Gerilim DC | N18: =N20*N17/1000 | P18: mV
B19: Çıkış Kademesi | F19: DC 400A | J19: Sonuçlar
B20: Akım | F20: 80,00A | J20: Ölçülen Direnç | N20: ='ANA SAYFA KESİCİ'!O50 | P20: µΩ
J21: Hata | P21: %
B23: Kontak Direnci µΩ | J23: L-2 | P23: =IF(N29<150,1,0)
V24: Kesicinin L1 kontağına ait geçiş direci uygundur.
B25: Nominal Değerler | J25: Ölçülen | V25: Kesicinin L1 kontağına ait geçiş direci uygun değildir.
B26: Nominal Direnç | F26: 150 | H26: µΩ | J26: Akım DC | N26: 82 | P26: A | V26: Kesicinin L2 kontağına ait geçiş direci uygundur.
J27: Gerilim DC | N27: =N29*N26/1000 | P27: mV | V27: Kesicinin L2 kontağına ait geçiş direci uygun değildir.
B28: Çıkış Kademesi | F28: DC 400A | J28: Sonuçlar | V28: Kesicinin L3 kontağına ait geçiş direci uygundur.
B29: Akım | F29: 80,00A | J29: Ölçülen Direnç | N29: ='ANA SAYFA KESİCİ'!O52 | P29: µΩ | V29: Kesicinin L3 kontağına ait geçiş direci uygun değildir.
P30: %
B32: Kontak Direnci µΩ | J32: L-3 | P32: =IF(N38<150,1,0)
B34: Nominal Değerler | J34: Ölçülen
B35: Nominal Direnç | F35: 150 | H35: µΩ | J35: Akım DC | N35: 82 | P35: A
J36: Gerilim DC | N36: =N38*N35/1000 | P36: mV
B37: Çıkış Kademesi | F37: DC 400A | J37: Sonuçlar
B38: Akım | F38: 80,00A | J38: Ölçülen Direnç | N38: ='ANA SAYFA KESİCİ'!O54 | P38: µΩ
P39: %
B45: Sonuç: | D45: =IF(P14<1,V25,V24)
D46: =IF(P23<1,V27,V26)
D47: =IF(P32<1,V29,V28)
B50: UNVAN | E50: : | F50: Elektrik Mühendisi | J50: ONAYLAYAN
B51: TEST TARİHİ | E51: : | F51: ='ANA SAYFA KESİCİ'!F75:J75
B52: ODA SİCİL NO | E52: : | F52: ='ANA SAYFA KESİCİ'!F77:J77
B53: EKİPNET NO | E53: : | F53: ='ANA SAYFA KESİCİ'!F78:J78

Sheet AÇMA-KAPAMA
G2: ŞALT SAHASI | J2: : | K2: ='ANA SAYFA KESİCİ'!K2
G3: LOKASYON | J3: : | K3: ='ANA SAYFA KESİCİ'!K5
B5: KESİCİ AÇMA-KAPAMA SÜRELERİ TEST SONUÇLARI
B7: OTURUM TARİHİ : | J7: ='ANA SAYFA KESİCİ'!F74
T8: 1
B9: Operatör : | D9: ='KESİCİ İZOLASYON'!D10:G10 | H9: Cihaz : | M9: Cihaz S/N : | V9: 3
B11: KESİCİ BİLGİLERİ | T11: 20
B13: Kesici Markası | F13: : | G13: ='ANA SAYFA KESİCİ'!G11 | J13: Kesici Tipi | M13: : | N13: ='ANA SAYFA KESİCİ'!O11
B15: Anma Akımı (A) | F15: : | G15: ='ANA SAYFA KESİCİ'!G13 | J15: İmal Yılı | M15: : | N15: ='ANA SAYFA KESİCİ'!O13 | W15: Uygun
B17: Gerilim Seviyesi (V) | F17: : | G17: ='ANA SAYFA KESİCİ'!G15 | J17: Seri Numarası | M17: : | N17: ='ANA SAYFA KESİCİ'!O15 | W17: Uygun Değil
B19: Motor Gerilimi | F19: : | G19: ='ANA SAYFA KESİCİ'!G17 | J19: Bobin Gerilimi | M19: : | N19: ='ANA SAYFA KESİCİ'!O17 | S19: Max. | T19: Max. | U19: Max.
B21: KESİCİ AÇMA / KAPAMA ZAMANI | S21: 80 | T21: 120 | U21: 5 | W21: 0
B23: Açma | J23: Kapama
S24: 40 | T24: 30 | U24: 20 | V24: 10
B25: A-1 | C25: ='ANA SAYFA KESİCİ'!C61:D61 | E25: ms | F25: Bobin Gerilimi | H25: ='ANA SAYFA KESİCİ'!O17 | J25: A-1 | K25: ='ANA SAYFA KESİCİ'!J61 | M25: ms | N25: Bobin Gerilimi | P25: ='ANA SAYFA KESİCİ'!O17 | S25: 40 | T25: 30 | U25: 20 | V25: 10
B26: B-1 | C26: ='ANA SAYFA KESİCİ'!C63:D63 | E26: ms | J26: B-1 | K26: ='ANA SAYFA KESİCİ'!J63 | M26: ms
B27: C-1 | C27: ='ANA SAYFA KESİCİ'!C65:D65 | E27: ms | F27: Bobin Akımı | H27: ='ANA SAYFA KESİCİ'!F65 | I27: A | J27: C-1 | K27: ='ANA SAYFA KESİCİ'!J65 | M27: ms | N27: Bobin Akımı | P27: ='ANA SAYFA KESİCİ'!M65 | Q27: A
B28: Faz Uyuşmazlığı | J28: Faz Uyuşmazlığı | W28: Kesicinin L1 fazına ait izolasyon direnç değeri uygun değildir.
B29: ='ANA SAYFA KESİCİ'!F61 | E29: ms | F29: =IF(B29>5,W17,W15) | J29: ='ANA SAYFA KESİCİ'!M61 | M29: ms | N29: =IF(J29>5,W17,W15)
W30: Kesicinin L2 fazına ait izolasyon direnç değeri uygundur.
W31: Kesicinin L2 fazına ait izolasyon direnç değeri uygun değildir.
W32: Kesicinin L3 fazına ait izolasyon direnç değeri uygundur.
W33: Kesicinin L3 fazına ait izolasyon direnç değeri uygun değildir.
W38: Kesicinin Açma süreleri ve bobin akım değerleri uygundur.
B39: TEDAŞ-MLZ/95-008.A İlgili Teknik Şartnamesi Gereği | W39: Kesicinin Açma süreleri uygun değildir.
B40: Açma süresi: 80 milisaniyeden az | W40: Kesicinin Kapama süreleri ve bobin akım değerleri uygundur.
B41: Kapama süresi: 120 milisaniyeden az | W41: Kesicinin Kapama süreleri uygun değildir.
B42: Açma süresi faz uyuşmazlığı: 5 milisaniyeden az | W42: Kesicinin Açma-Kapama Süresi Faz Uyuşmazlığı uygundur.
B43: Kapama süresi faz uyuşmazlığı: 5 milisaniyeden az | W43: Kesicinin Açma-Kapama Süresi Faz Uyuşmazlığı uygun değildir.
B45: Sonuç : | D45: =IF(OR(C25>S21,C26>S21,C27>S21),W39,W38)
D46: =IF(OR(K25>T21,K26>T21,K27>T21),W41,W40)
D47: =IF(OR(B29>U21,J29>U21),W43,W42)
B48: UNVAN | E48: : | F48: Elektrik Mühendisi | J48: ONAYLAYAN
B49: TEST TARİHİ | E49: : | F49: ='ANA SAYFA KESİCİ'!F75
B50: ODA SİCİL NO | E50: : | F50: ='ANA SAYFA KESİCİ'!F77
B51: EKİPNET NO | E51: : | F51: ='ANA SAYFA KESİCİ'!F78

Sheet YAĞ RAPORU
G2: ŞALT SAHASI | I2: : | J2: ='ANA SAYFA'!K2
G3: LOKASYON | I3: : | J3: ='ANA SAYFA'!K5
B5: Dosya Adı : | E5: İZOLASYON YAĞI TEST SONUÇLARI | L5: Güç: | O5: ='ANA SAYFA'!G13 | Q5: kVA
B7: Üretici : | D7: ='ANA SAYFA'!G11 | G7: Model : | I7: ='ANA SAYFA'!O13 | L7: Seri Numarası : | O7: ='ANA SAYFA'!O15
B8: Yağ Markası: | D8: ='ANA SAYFA'!G17 | G8: Yağ Ağırlığı: | I8: ='ANA SAYFA'!O17 | L8: Gerilim Seviyesi: | O8: ='ANA SAYFA'!G15
B10: RAPOR TARİHİ : | J10: ='ANA SAYFA'!F78
T11: 30
B12: Sonuçlar
B14: DİELEKTRİK DAYANIM TESTİ ( VDE0370 )
B16: DENEY 1 | D16: 60 | F16: kV
B18: DENEY 2 | D18: 60 | F18: kV
B20: DENEY 3 | D20: 60 | F20: kV | W20: 30
B22: DENEY 4 | D22: 60 | F22: kV
B24: DENEY 5 | D24: 60 | F24: kV
B26: DENEY 6 | D26: 60 | F26: kV
B28: Vort | D28: =(D16+D18+D20+D22+D24+D26)/6 | F28: kV
B30: Testin Adı | E30: Değer | H30: Birim | K30: Standardı | N30: Sınır Değerler
B32: Asidite | E32: 0.094 | H32: mgKOH/g | K32: ASTMD664 | N32: max 0,300 mgKOH/g
B34: Yoğunluk | E34: 0.886 | H34: g/cm3 | K34: ASTMD1298 | N34: 0,800-0,950 g/cm3
B36: Çözünmüş Su | E36: 10.5 | H36: ppm | K36: ASTMD1533 | N36: max 30 ppm
B38: Görünüş | E38: AÇIK SARI
B39: KULLANILAN CİHAZLARA AİT BİLGİLER
C40: SA-60 DİELEKTRİK DAYANIM TEST CİHAZI
C41: SERİ NO: 97142 KAL. NO: 537602 / TARİH: 27.05.2025
C42: MEZÜR
C43: KAL. NO: 389202 / TARİH: 16.04.2025
C44: DENSİMETRE
C45: KAL.NO: 389201 / TARİH: 17.04.2025
C46: COU-LO AQUAMAX KF Moisture Meter
B47: Sonuç : Yapılan ölçümler sonucu izolasyon yağının test değerleri uygun bulunmuştur.
B51: Not: | C51: Yağ örneği firmamız çalışanları tarafından alınmıştır.
B52: UNVAN | E52: : | F52: ='ANA SAYFA'!F80:J80 | J52: ONAYLAYAN
B53: TEST TARİHİ | E53: : | F53: ='ANA SAYFA'!F79:J79+1
B54: ODA SİCİL NO | E54: : | F54: ='ANA SAYFA'!F81:J81
B55: EKİPNET NO | E55: : | F55: ='ANA SAYFA'!F82:J82

Sheet HERMETİK YAĞ DİLEKÇESİ
G2: ŞALT SAHASI | I2: : | J2: ='KAPAK SAYFASI'!D9
G3: LOKASYON | I3: : | J3: ='KAPAK SAYFASI'!D11
B8: FİRMA YETKİLİLERİNİN DİKKATİNE
B10: İşletmenizde bulunan trafoların testini 05.08.2026 tarihinde yapmış bulunmaktayız. Test kapsamı içerisinde istenilen trafo yağ analizi işleminin yapılabilmesi için trafodan yağ numunesi alınması gerekmektedir. İşletmenizde bulunan ASTOR marka, 1000kVA, '27-07840' seri numaralı trafonun hermetik tip olmasından dolayı yağ numunesi alınmamıştır. Hermetik tip trafolar atmosfere kapalıdır ve numune alma yerleri mühürlüdür. Mühürlerin açılıp numune alınması durumunda trafonun hermetik özelliği bozulacağından dolayı, fabrika standartlarına göre arıza durumu olmadığı sürece hiçbir şekilde hermetik trafolardan yağ numunesi alınamaz. Bilgilerinize sunarız.
T11: 30
W20: 30
J52: ONAYLAYAN
B53: UNVAN | E53: : | F53: Elektrik Mühendisi
B54: TEST TARİHİ | E54: : | F54: ='KAPAK SAYFASI'!D53
