Workbook

Sheet KAPAK SAYFASI
E1: B.T.S. ELEKTRİK TRAFO BAKIM
E3: MÜH. İNŞ. MAK. LAB. SAN. VE TİC. LTD. ŞTİ.
A7: TRAFO TEST RAPORU
A9: Müşterinin Adı | D9: OK AMBALAJ
A10: Trafo Etiketi | D10: TR-1
A11: ADRESİ | D11: KAYAPA/BURSA
A12: RAPOR TARİHİ | D12: 05.08.2026
A13: REFERANS | D13: International Electrical Testing Association
A14: RAPOR KONUSU | D14: 05.08.2026 | E14: Tarihinde yapılan Trafo test raporu.
B16: TRAFO BAKIMI VE KONTROLLERİ
A18: - | B18: Trafonun D.C. İzolasyon test değerleri uygun bulunmuştur.
A20: - | B20: Trafoda yapılan çevirme oranı (TTR) test sonuçları uygun bulmuştur, buna bağlı olarak kademe değiştirici ile sargılar arasındaki bağlantılarda herhangi bir sorun olmadığı gözlemlenmiştir.
A23: - | B23: Trafoda yapılan D.C. Sargı direnci test sonuçlarının uygun olduğu tespit edilmiştir, sargılar arasındaki direnç farklılıkları max. değerin (%5) altındadır. Bu sonuçlara göre; sargı bağlantı uçları, kademe değiştirici kontakları, tij bağlantılarında gevşeklik olmadığı gözlemlenmiştir.
A27: SONUÇ
A29: Mevcut şartlar korunması halinde trafonun kullanımı UYGUNDUR.
G52: ONAYLAYAN
A53: Test Tarihi | C53: : | D53: =D14 -> 05.08.2026
A54: Rapor Tarihi | C54: : | D54: =D12 -> 05.08.2026
A55: Unvan | C55: : | D55: Elektrik Mühendisi
A58: Bu belge 5070 sayılı elektronik imza kanununa göre güvenli elektronik imza ile imzalanmıştır.
A60: Üçevler Mahallesi Ak-Va Sanayi Sitesi 80. Sokak No:2/P Nilüfer-BURSA
A61: Telefon : 444 0 287 - 0224 441 94 33 Mail: www.btselektrik.com.tr
A62: Gsm : 0532 206 58 32 - 0538 035 35 94

Sheet ANA SAYFA
H2: ŞALT SAHASI | K2: ='KAPAK SAYFASI'!D9 -> OK AMBALAJ
H5: TRAFO ETİKETİ | K5: ='KAPAK SAYFASI'!D10 -> TR-1
B6: Üçevler Mh. AK-VA Sanayi Sitesi 80. Sk. No:2/P Nilüfer / BURSA / TÜRKİYE
B9: TRAFO BİLGİLERİ
B11: Trafo Markası | F11: : | G11: ASTOR | K11: Kademe Bilgisi | N11: : | O11: 6 | P11: / | Q11: 4 | R11: / | S11: 5
B13: Trafo Gücü (kVA) | F13: : | G13: 1000 | K13: İmal Yılı | N13: : | O13: 2017
B15: Gerilim Seviyesi (V) | F15: : | G15: 34500 | K15: Seri Numarası | N15: : | O15: 27-07840
B17: Yağ Markası | F17: : | G17: NYNAS | K17: Yağ Ağırlığı (kg) | N17: : | O17: 510
B19: Bağlantı Grubu | F19: : | G19: Dyn11 | K19: Kısa Devre Emp.% | N19: : | O19: 5.61
B21: Kazan Tipi | F21: : | G21: Hermetik | I21: ü | K21: Genleşme Tanklı | P21: Kuru Tip
B24: KONTROLLER
I25: Evet | J25: Hayır | R25: Evet | S25: Hayır
B27: Trafo Sıcaklık Kontrolü | F27: : | G27: 30 | H27: °C | I27: ü | K27: Trafo Temizliği | O27: : | P27: -
B29: Yağ Seviyesi Kontrolü | F29: : | G29: UYGUN | I29: ü | K29: Bina Temizliği | O29: : | P29: -
B31: DC Redresör Kontrolü | F31: : | G31: 24 VDC | I31: ü | K31: Kablo Sıkılık Kontrolü | O31: : | P31: UYGUN | R31: ü
B33: Basınç Açma | F33: : | G33: UYGUN | I33: ü | K33: Yağ Kaçağı Kontrolü | O33: : | P33: UYGUN | R33: ü
B35: Gaz Açma | F35: : | G35: UYGUN | I35: ü | K35: Kademe Conta Kontrolü | O35: : | P35: UYGUN | R35: ü
B37: Termik Alarm | F37: : | G37: UYGUN | I37: ü | K37: O.G Conta Kontrolü | O37: : | P37: UYGUN | R37: ü
B39: Termik Açma | F39: : | G39: UYGUN | I39: ü | K39: Kapak Conta Kontrolü | O39: : | P39: UYGUN | R39: ü
B41: İzolatör Kontrolü | F41: : | G41: UYGUN | I41: ü | K41: A.G Conta Kontrolü | O41: : | P41: UYGUN | R41: ü
V44: ÇEVİRME ORANI ( TTR ) | AF44: ÇEVİRME ORANI ( TTR )
V46: AB / an | Y46: BC / bn | AB46: CA / cn | AF46: AB / an | AI46: BC / bn | AL46: CA / cn
V48: =V57/1.0525889 -> 123.5622 | Y48: =Y57/1.0525889 -> 123.56055 | AB48: =AB57/1.0525889 -> 123.57872 | AF48: =AF57/1.045489 -> 143.06607 | AI48: =AI57/1.045489 -> 143.06415 | AL48: =AL57/1.045489 -> 143.0852
V50: Kademe Bilgisi | Y50: : | Z50: 28500 / 400 | AF50: Kademe Bilgisi | AI50: : | AJ50: 33000 / 400
B53: 2 | C53: A | D53: SARGI DİRENÇLERİ ( Ω ) | I53: 50 | J53: A | K53: ÇEVİRME ORANI ( TTR ) | V53: ÇEVİRME ORANI ( TTR ) | AF53: ÇEVİRME ORANI ( TTR )
B55: RAB : | C55: 9.35 | F55: Ran : | G55: 0.0004878 | K55: AB / an | N55: BC / bn | Q55: CA / cn | V55: AB / an | Y55: BC / bn | AB55: CA / cn | AF55: AB / an | AI55: BC / bn | AL55: CA / cn
B57: RAC : | C57: 9.3783 | F57: Rbn : | G57: 0.0004699 | K57: 149.574 | N57: 149.572 | Q57: 149.594 | V57: =V66/1.050038 -> 130.0602 | Y57: =Y66/1.050038 -> 130.05846 | AB57: =AB66/1.050038 -> 130.07759 | AF57: =K57 -> 149.574 | AI57: =N57 -> 149.572 | AL57: =Q57 -> 149.594
B59: RBC : | C59: 9.3655 | F59: Rcn : | G59: 0.000472 | K59: Kademe Bilgisi | N59: : | O59: 34500 | Q59: / | R59: 230.9494 | V59: Kademe Bilgisi | Y59: : | Z59: 30000 / 400 | AF59: Kademe Bilgisi | AI59: : | AJ59: 34500 / 400
B62: İZOLASYON (YALITIM) DİRENÇLERİ ( Ω ) | V62: ÇEVİRME ORANI ( TTR ) | AF62: ÇEVİRME ORANI ( TTR )
F64: 30 sn | I64: 45 sn | L64: 60 sn | O64: Birim | Q64: DAR | V64: AB / an | Y64: BC / bn | AB64: CA / cn | AF64: AB / an | AI64: BC / bn | AL64: CA / cn
B66: Y.G - TANK | F66: 54.6 | I66: 60.3 | L66: 64.7 | O66: G | P66: Ω | Q66: =L66/F66 -> 1.1849817 | V66: =AF48/1.04758 -> 136.56815 | Y66: =AI48/1.04758 -> 136.56633 | AB66: =AL48/1.04758 -> 136.58642 | AF66: =AF57*1.043443 -> 156.07194 | AI66: =AI57*1.043443 -> 156.06986 | AL66: =AL57*1.043443 -> 156.09281
B68: A.G - TANK | F68: 37.7 | I68: 44.4 | L68: 48.8 | O68: G | P68: Ω | Q68: =L68/F68 -> 1.2944297 | V68: Kademe Bilgisi | Y68: : | Z68: 31500 / 400 | AF68: Kademe Bilgisi | AI68: : | AJ68: 36000 / 400
B70: Y.G - A.G | F70: 57.8 | I70: 63.3 | L70: 68.8 | O70: G | P70: Ω | Q70: =L70/F70 -> 1.1903114
B73: NOTLAR : Test sonuçlarının değerlendirilmesi kapak sayfasında yapılmıştır.
K78: ONAYLAYAN
B79: Test Tarihi | E79: : | F79: ='KAPAK SAYFASI'!D53 -> 05.08.2026
B80: Rapor Tarihi | E80: : | F80: ='KAPAK SAYFASI'!D54 -> 05.08.2026
B81: Unvan | E81: : | F81: Elektrik Mühendisi

Sheet OG SARGI MEVCUT KADEME
G2: ŞALT SAHASI | I2: : | J2: ='ANA SAYFA'!K2 -> OK AMBALAJ
G3: LOKASYON | I3: : | J3: ='ANA SAYFA'!K5 -> TR-1
B5: PRİMER SARGI DİRENCİ TEST SONUÇLARI
B7: Üretici : | D7: ='ANA SAYFA'!G11 -> ASTOR | G7: Model : | I7: ='ANA SAYFA'!O13 -> 2017 | L7: Seri Numarası : | O7: ='ANA SAYFA'!O15 -> 27-07840
B9: OTURUM TARİHİ : | J9: ='KAPAK SAYFASI'!D54 -> 05.08.2026
B11: Operatör : | D11: Hilmi GÜL | H11: Cihaz : | J11: STS 5000 | M11: Cihaz S/N : | O11: 19B20
B13: Sonuçlar | V13: ='ANA SAYFA'!G13 -> 1000
V14: =V13/59.75575286 -> 16.73479
B15: PT Sargı Otomatik | J15: HV Mevcut Kademe Tap | O15: ='ANA SAYFA'!S11 -> 5
B17: Nominal Direnç
B18: Vektör Grubu | F18: ='ANA SAYFA'!G19 -> Dyn11
B19: 3-faz
B20: Nominal Değerler | F20: =(K24+K25+K26)/3 -> 9.3646 | H20: Ω
B21: Çıkış Kademesi | F21: DC 6A | T21: A | U21: =MAX(T32:T33) -> 0.0030176045
T22: B | U22: =MAX(U32:U33) -> 0.001657754
C23: I Testi [A] | E23: I DC [A] | G23: V DC [V] | I23: Zaman [S] | K23: R.ölç[Ω] | M23: R. Nom | O23: Hata[%] | T23: C | U23: =MAX(V32:V33) -> 0.003026738
B24: A | C24: ='ANA SAYFA'!B53 -> 2 | E24: =C24 -> 2 | G24: =(E24*K24)*0.98 -> 18.326 | I24: 40 | K24: ='ANA SAYFA'!C55 -> 9.35 | M24: =F20 -> 9.3646 | O24: =U21 -> 0.0030176045 | Q24: =IF(O24>0.05,1,0) -> 0 | T24: SINIR DEĞER | U24: 0.05
B25: B | C25: ='ANA SAYFA'!B53 -> 2 | E25: =C25 -> 2 | G25: =(E25*K25)*0.98 -> 18.35638 | I25: 40 | K25: ='ANA SAYFA'!C59 -> 9.3655 | M25: =M24 -> 9.3646 | O25: =U22 -> 0.001657754 | Q25: =IF(O25>0.05,1,0) -> 0
B26: C | C26: ='ANA SAYFA'!B53 -> 2 | E26: =C26 -> 2 | G26: =(E26*K26)*0.98 -> 18.381468 | I26: 40 | K26: ='ANA SAYFA'!C57 -> 9.3783 | M26: =M24 -> 9.3646 | O26: =U23 -> 0.003026738 | Q26: =IF(O26>0.05,1,0) -> 0
T32: =SQRT((K24-K25)^2)/K25 -> 0.0016550104 | U32: =SQRT((K24-K25)^2)/K24 -> 0.001657754 | V32: =SQRT((K26-K24)^2)/K24 -> 0.003026738
T33: =SQRT((K26-K24)^2)/K26 -> 0.0030176045 | U33: =SQRT((K25-K26)^2)/K26 -> 0.0013648529 | V33: =SQRT((K26-K25)^2)/K25 -> 0.0013667183
B39: Sonuç : | D39: Yapılan ölçümlerde OG (Orta gerilim) sargısına ait direnç değerleri uygundur.
J45: ONAYLAYAN
B46: UNVAN | E46: : | F46: Elektrik Mühendisi
B47: TEST TARİHİ | E47: : | F47: ='KAPAK SAYFASI'!D53 -> 05.08.2026

Sheet AG SARGI
G2: ŞALT SAHASI | I2: : | J2: ='ANA SAYFA'!K2 -> OK AMBALAJ
G3: LOKASYON | I3: : | J3: ='ANA SAYFA'!K5 -> TR-1
B5: SEKONDER SARGI DİRENCİ TEST SONUÇLARI
B7: Üretici : | D7: ='OG SARGI MEVCUT KADEME'!D7:F7 -> ASTOR | G7: Model : | I7: ='OG SARGI MEVCUT KADEME'!I7:K7 -> 2017 | L7: Seri Numarası : | O7: ='OG SARGI MEVCUT KADEME'!O7:Q7 -> 27-07840
B9: OTURUM TARİHİ : | J9: ='KAPAK SAYFASI'!D54 -> 05.08.2026
B11: Operatör : | D11: ='OG SARGI MEVCUT KADEME'!D11 -> Hilmi GÜL | H11: Cihaz : | J11: STS 5000 | M11: Cihaz S/N : | O11: 19B20
B13: Sonuçlar | V13: ='ANA SAYFA'!G13 -> 1000
V14: =V13/0.69282 -> 1443.3763
B15: PT Sargı Otomatik | J15: LV Kademe Tap | N15: 1
B17: Nominal Direnç
B18: Vektör Grubu | F18: ='ANA SAYFA'!G19 -> Dyn11
B19: 3-faz
B20: Nominal Değerler | F20: =(K24+K25+K26)/3 -> 0.00047656667 | H20: Ω
B21: Çıkış Kademesi | F21: DC 400A | T21: A | U21: =MIN(T32:T33) -> 0.033474576
T22: B | U22: =MIN(U32:U33) -> 0.0044491525
C23: I Testi [A] | E23: I DC [A] | G23: V DC [V] | I23: Zaman [S] | K23: R.ölç[Ω] | M23: R. Nom | O23: Hata[%] | T23: C | U23: =MIN(V32:V33) -> 0.004469036
B24: A | C24: ='ANA SAYFA'!I53 -> 50 | E24: =C24 -> 50 | G24: =(K24*E24)*0.98 -> 0.0239022 | I24: 35 | K24: ='ANA SAYFA'!G55 -> 0.0004878 | M24: =F20 -> 0.00047656667 | O24: =MIN(T32:T33) -> 0.033474576 | Q24: =IF(O24>0.05,1,0) -> 0 | T24: SINIR DEĞER | U24: 0.05
B25: B | C25: ='ANA SAYFA'!I53 -> 50 | E25: =C25 -> 50 | G25: =(K25*E25)*0.98 -> 0.0230251 | I25: 35 | K25: ='ANA SAYFA'!G57 -> 0.0004699 | M25: =M24 -> 0.00047656667 | O25: =MIN(U32:U33) -> 0.0044491525 | Q25: =IF(O25>0.05,1,0) -> 0
B26: C | C26: ='ANA SAYFA'!I53 -> 50 | E26: =C26 -> 50 | G26: =(K26*E26)*0.98 -> 0.023128 | I26: 35 | K26: ='ANA SAYFA'!G59 -> 0.000472 | M26: =M24 -> 0.00047656667 | O26: =MIN(V32:V33) -> 0.004469036 | Q26: =IF(O26>0.05,1,0) -> 0
T32: =SQRT((K24-K25)^2)/K25 -> 0.038093211 | U32: =SQRT((K24-K25)^2)/K24 -> 0.036695367 | V32: =SQRT((K26-K24)^2)/K24 -> 0.032390324
T33: =SQRT((K26-K24)^2)/K26 -> 0.033474576 | U33: =SQRT((K25-K26)^2)/K26 -> 0.0044491525 | V33: =SQRT((K26-K25)^2)/K25 -> 0.004469036
B39: Sonuç : | D39: Yapılan ölçümlerde AG (Alçak gerilim) sargısına ait direnç değerleri uygundur.
J45: ONAYLAYAN
B46: UNVAN | E46: : | F46: Elektrik Mühendisi
B47: TEST TARİHİ | E47: : | F47: ='KAPAK SAYFASI'!D53 -> 05.08.2026

Sheet İZOLASYON 
G2: ŞALT SAHASI | I2: : | J2: ='ANA SAYFA'!K2 -> OK AMBALAJ
G3: LOKASYON | I3: : | J3: ='ANA SAYFA'!K5 -> TR-1
B5: D.C. İZOLASYON DİRENCİ TEST SONUÇLARI
B7: Üretici : | D7: ='OG SARGI MEVCUT KADEME'!D7:F7 -> ASTOR | G7: Model : | I7: ='OG SARGI MEVCUT KADEME'!I7:K7 -> 2017 | L7: Seri Numarası : | O7: ='OG SARGI MEVCUT KADEME'!O7:Q7 -> 27-07840
Y8: OG-TANK | Z8: AG-TANK | AA8: OG-AG
B9: OTURUM TARİHİ : | J9: ='KAPAK SAYFASI'!D54 -> 05.08.2026 | X9: LİMİT | Y9: =V15 -> 1.1 | Z9: =V20 -> 0.2 | AA9: =V25 -> 1.1
X10: 30 | Y10: =H18 -> 108.108 | Z10: =H23 -> 74.646 | AA10: =H28 -> 114.444
B11: Operatör : | D11: ='OG SARGI MEVCUT KADEME'!D11 -> Hilmi GÜL | H11: Cihaz : | J11: METREL-MI3210 | M11: Cihaz S/N : | O11: 16060016 | X11: 45 | Y11: =J18 -> 119.394 | Z11: =J23 -> 87.912 | AA11: =J28 -> 125.334
X12: 60 | Y12: =L18 -> 128.106 | Z12: =L23 -> 96.624 | AA12: =L28 -> 136.224
B13: Sonuçlar | N13: Sıcaklık | P13: ='ANA SAYFA'!G27 -> 30 | Q13: °C
B15: O.G. TANK İZOLASYON | U15: OG-TANK | V15: 1.1
B16: ÖLÇÜLEN DEĞERLER | H16: HESAPLANAN DEĞERLER 20°C | V16: UYGUN
B17: 30 sn | D17: 45 sn | F17: 60 sn | H17: 30 sn | J17: 45 sn | L17: 60 sn | N17: DAR | P17: Sonuç
B18: ='ANA SAYFA'!F66 -> 54.6 | C18: GΩ | D18: ='ANA SAYFA'!I66 -> 60.3 | E18: GΩ | F18: ='ANA SAYFA'!L66 -> 64.7 | G18: GΩ | H18: =B18*V38 -> 108.108 | I18: GΩ | J18: =D18*V38 -> 119.394 | K18: GΩ | L18: =F18*V38 -> 128.106 | M18: GΩ | N18: =L18/H18 -> 1.1849817 | P18: =IF(L18<V15,V18,V16) -> UYGUN | V18: DÜŞÜK
B20: A.G. TANK İZOLASYON | U20: AG-TANK | V20: 0.2
B21: ÖLÇÜLEN DEĞERLER | H21: HESAPLANAN DEĞERLER 20°C | V21: UYGUN
B22: 30 sn | D22: 45 sn | F22: 60 sn | H22: 30 sn | J22: 45 sn | L22: 60 sn | N22: DAR | P22: Sonuç
B23: ='ANA SAYFA'!F68 -> 37.7 | C23: GΩ | D23: ='ANA SAYFA'!I68 -> 44.4 | E23: GΩ | F23: ='ANA SAYFA'!L68 -> 48.8 | G23: GΩ | H23: =B23*V38 -> 74.646 | I23: GΩ | J23: =D23*V38 -> 87.912 | K23: GΩ | L23: =F23*V38 -> 96.624 | M23: GΩ | N23: =L23/H23 -> 1.2944297 | P23: =IF(L23<V20,V23,V21) -> UYGUN | V23: DÜŞÜK
Y24: Yapılan ölçümlerde trafonun izolasyon direnç değerleri uygun bulunmuştur.
B25: O.G. A.G. İZOLASYON | U25: OG-AG | V25: 1.1
B26: ÖLÇÜLEN DEĞERLER | H26: HESAPLANAN DEĞERLER 20°C | V26: UYGUN
B27: 30 sn | D27: 45 sn | F27: 60 sn | H27: 30 sn | J27: 45 sn | L27: 60 sn | N27: DAR | P27: Sonuç
B28: ='ANA SAYFA'!F70 -> 57.8 | C28: GΩ | D28: ='ANA SAYFA'!I70 -> 63.3 | E28: GΩ | F28: ='ANA SAYFA'!L70 -> 68.8 | G28: GΩ | H28: =B28*V38 -> 114.444 | I28: GΩ | J28: =D28*V38 -> 125.334 | K28: GΩ | L28: =F28*V38 -> 136.224 | M28: GΩ | N28: =L28/H28 -> 1.1903114 | P28: =IF(L28<V25,V28,V26) -> UYGUN | V28: DÜŞÜK
Y32: Yapılan ölçümlerde trafonun izolasyon direnç değerleri düşük bulunmuştur.
U38: ÇARPAN | V38: =IF(P13>40,X43,X42) -> 1.98
B41: Sonuç : | D41: =IF(L18<V15,Y32,Y24) -> Yapılan ölçümlerde trafonun izolasyon direnç değerleri uygun bulunmuştur.
U42: Test Sıcaklığı | V42: İcra Katsayısı | X42: =IF(P13=0,V43, IF(P13=5,V44, IF(P13=10,V45, IF(P13=15,V46, IF(P13=20,V47, IF(P13=25,V48, IF(P13=30,V49, IF(P13=35,V50, IF(P13=40,V51, ))))))))) -> 1.98
U43: 0 | V43: 0.25 | X43: =IF(P13=45,V52, IF(P13=50,V53, IF(P13=55,V54, IF(P13=60,V55, IF(P13=65,V56, IF(P13=70,V57, IF(P13=75,V58, ))))))) -> 0
U44: 5 | V44: 0.36
U45: 10 | V45: 0.5
B46: Not: Polarizasyon endekslerine göre değerlendirme; hem fabrika deney sonuçları hem de daha önceki değerlerle yeni bulunan değerlerin kıyaslanması ile yapılmalıdır. Ölçülen değerler daha önceki değerlere yakın veya büyük ise normal kabul edilir. Ancak ölçüm ilk kez yapılıyorsa; PE=1,0-1,1 Zayıf / PE=1,1-1,25 Şüpheli / PE=1,25-1,40 Orta / PE=1,40-1,60 İyi / PE>1,60 Çok İyi değerlendirmesi yapılır. İzolasyon ölçümlerinde DAR endeksine bağlı kalınmaksızın, sınır değerlerin altında çıkan değerler kötü izolasyon olarak ifade edilmektedir. | U46: 15 | V46: 0.74
U47: 20 | V47: 1
U48: 25 | V48: 1.4
U49: 30 | V49: 1.98
J50: ONAYLAYAN | U50: 35 | V50: 2.8
B51: UNVAN | E51: : | F51: Elektrik Mühendisi | U51: 40 | V51: 3.95
B52: TEST TARİHİ | E52: : | F52: ='ANA SAYFA'!F79 -> 05.08.2026 | U52: 45 | V52: 5.6
U53: 50 | V53: 7.85
U54: 55 | V54: 11.2
U55: 60 | V55: 15.85
...

Sheet Ç.O 34500
G2: ŞALT SAHASI | I2: : | J2: ='ANA SAYFA'!K2 -> OK AMBALAJ
G3: LOKASYON | I3: : | J3: ='ANA SAYFA'!K5 -> TR-1
B5: ÇEVİRME ORANI TEST SONUÇLARI
B7: Üretici : | D7: ='OG SARGI MEVCUT KADEME'!D7:F7 -> ASTOR | G7: Model : | I7: ='OG SARGI MEVCUT KADEME'!I7:K7 -> 2017 | L7: Seri Numarası : | O7: ='OG SARGI MEVCUT KADEME'!O7:Q7 -> 27-07840
B9: OTURUM TARİHİ : | J9: ='KAPAK SAYFASI'!D54 -> 05.08.2026
B11: Operatör : | D11: ='OG SARGI MEVCUT KADEME'!D11 -> Hilmi GÜL | H11: Cihaz : | J11: STS 5000 | M11: Cihaz S/N : | O11: 19B20
B13: Sonuçlar
B15: PT Her Bir Kademe Oran | J15: Tap | K15: ='ANA SAYFA'!S11 -> 5 | N15: Kademe #1 | T15: ='ANA SAYFA'!R59 -> 230.9494 | U15: A | V15: =O26 -> 0.12761031
U16: B | V16: =O27 -> 0.12627147
B17: Nominal Değerler | J17: Test Değerleri | U17: C | V17: =O28 -> 0.14099868
B18: HV Kademeler | F18: ='ANA SAYFA'!O59 -> 34500 | H18: V | J18: Gerilim | N18: 500,0 V | U18: SINIR DEĞER | V18: 0.5
B19: LV Ratings | F19: 231 | H19: V | J19: Frekans | N19: 50, Hz | W19: 0.5 | X19: -0.5
B20: Çevirme Oranı | F20: =F18/T15 -> 149.38337
B22: Sonuçlar
C25: Vn HV [V] | E25: V HV[V] | G25: I HV[A] | I25: V LV[V] | K25: ᶲV LV [°] | M25: Ratio | O25: Err % | V25: ( A ) Fazına ait çevirme oranı hata yüzdesi uygundur.
B26: A | C26: 500 | E26: 500 | G26: =I26/M26 -> 0.010028481 | I26: 1.5 | K26: 26,0m | M26: ='ANA SAYFA'!AF57 -> 149.574 | O26: =(M26-F20)/F20*100 -> 0.12761031
B27: B | C27: 500 | E27: 500 | G27: =I27/M27 -> 0.010028615 | I27: 1.5 | K27: 26,0m | M27: ='ANA SAYFA'!AI57 -> 149.572 | O27: =(M27-F20)/F20*100 -> 0.12627147 | V27: ( A ) Fazına ait çevirme oranı hata yüzdesi hatalı olduğu tespit edilmiştir.
B28: C | C28: 500 | E28: 500 | G28: =I28/M28 -> 0.01002714 | I28: 1.5 | K28: 26,0m | M28: ='ANA SAYFA'!AL57 -> 149.594 | O28: =(M28-F20)/F20*100 -> 0.14099868
V29: ( B ) Fazına ait çevirme oranı hata yüzdesi uygundur.
V31: ( B ) Fazına ait çevirme oranı hata yüzdesi hatalı olduğu tespit edilmiştir.
V34: ( C ) Fazına ait çevirme oranı hata yüzdesi uygundur.
V36: ( C ) Fazına ait çevirme oranı hata yüzdesi hatalı olduğu tespit edilmiştir.
B44: Sonuç : | D44: =IF(OR(O26>W19,O26<X19),V27,V25) -> ( A ) Fazına ait çevirme oranı hata yüzdesi uygundur.
D46: =IF(OR(O27>W19,O27<X19),V31,V29) -> ( B ) Fazına ait çevirme oranı hata yüzdesi uygundur.
D48: =IF(OR(O28>W19,O28<X19),V36,V34) -> ( C ) Fazına ait çevirme oranı hata yüzdesi uygundur.
J50: ONAYLAYAN
B51: UNVAN | E51: : | F51: Elektrik Mühendisi
B52: TEST TARİHİ | E52: : | F52: ='ANA SAYFA'!F79 -> 05.08.2026

Sheet HERMETİK YAĞ DİLEKÇESİ
G2: ŞALT SAHASI | I2: : | J2: ='KAPAK SAYFASI'!D9 -> OK AMBALAJ
G3: LOKASYON | I3: : | J3: ='KAPAK SAYFASI'!D11 -> KAYAPA/BURSA
B8: FİRMA YETKİLİLERİNİN DİKKATİNE
B10: İşletmenizde bulunan trafoların testini 05.08.2026 tarihinde yapmış bulunmaktayız. Test kapsamı içerisinde istenilen trafo yağ analizi işleminin yapılabilmesi için trafodan yağ numunesi alınması gerekmektedir. İşletmenizde bulunan ASTOR marka, 1000kVA, '27-07840' seri numaralı trafonun hermetik tip olmasından dolayı yağ numunesi alınmamıştır. Hermetik tip trafolar atmosfere kapalıdır ve numune alma yerleri mühürlüdür. Mühürlerin açılıp numune alınması durumunda trafonun hermetik özelliği bozulacağından dolayı, fabrika standartlarına göre arıza durumu olmadığı sürece hiçbir şekilde hermetik trafolardan yağ numunesi alınamaz. Bilgilerinize sunarız.
T11: 30
W20: 30
J52: ONAYLAYAN
B53: UNVAN | E53: : | F53: Elektrik Mühendisi
B54: TEST TARİHİ | E54: : | F54: ='KAPAK SAYFASI'!D53 -> 05.08.2026
